Workbook
Name SegmentaçãodeDados_Ano: #N/A
Name SegmentaçãodeDados_Centro_de_Custo___Obra: #N/A
Name SegmentaçãodeDados_Conta_Pai: #N/A
Name SegmentaçãodeDados_Empresa: #N/A
Name SegmentaçãodeDados_Mês: #N/A

Sheet Painel

Sheet DRE
F2: =F6/$AH$6 -> 0 | J2: =J6/$AH$6 -> 0 | L2: =L6/$AH$6 -> 0 | N2: =N6/$AH$6 -> 0 | R2: =R6/$AH$6 -> 0 | T2: =T6/$AH$6 -> 0 | V2: =V6/$AH$6 -> 0 | Z2: =Z6/$AH$6 -> 0 | AB2: =AB6/$AH$6 -> 0 | AD2: =AD6/$AH$6 -> 0
A5: DEMONSTRATIVO DE RESULTADO GERENCIAL | B5: Jan | C5: %Jan | D5: Fev | E5: %Fev | F5: Mar | G5: %Mar | H5: 1ºTRI | I5: %1ºTRI | J5: Abr | K5: %Abr | L5: Mai | M5: %Mai | N5: Jun | O5: %Jun | P5: 2ºTRI | Q5: %2ºTRI | R5: Jul | S5: %Jul | T5: Ago | U5: %Ago | V5: Set | W5: %Set | X5: 3ºTRI | Y5: %3ºTRI | Z5: Out | AA5: %Out | AB5: Nov | AC5: %Nov | AD5: Dez | AE5: %Dez | AF5: 4ºTRI | AG5: %4ºTRI | AH5: ANO | AI5: %ANO
A6: (=)Receita Bruta | B6: =IFERROR(VLOOKUP($A6,APOIO!$B:$N,MATCH(B$5,APOIO!$B$5:$N$5,0),FALSE),0) -> 173156.44 | C6: =IFERROR(B6/B$6,0) -> 1 | D6: =IFERROR(VLOOKUP($A6,APOIO!$B:$N,MATCH(D$5,APOIO!$B$5:$N$5,0),FALSE),0) -> 420327.6 | E6: =IFERROR(D6/D$6,0) -> 1 | F6: =IFERROR(VLOOKUP($A6,APOIO!$B:$N,MATCH(F$5,APOIO!$B$5:$N$5,0),FALSE),0) -> 0 | G6: =IFERROR(F6/F$6,0) -> 0 | H6: =SUM(B6,D6,F6) -> 593484.04 | I6: =IFERROR(H6/H$6,0) -> 1 | J6: =IFERROR(VLOOKUP($A6,APOIO!$B:$N,MATCH(J$5,APOIO!$B$5:$N$5,0),FALSE),0) -> 0 | K6: =IFERROR(J6/J$6,0) -> 0 | L6: =IFERROR(VLOOKUP($A6,APOIO!$B:$N,MATCH(L$5,APOIO!$B$5:$N$5,0),FALSE),0) -> 0 | M6: =IFERROR(L6/L$6,0) -> 0 | N6: =IFERROR(VLOOKUP($A6,APOIO!$B:$N,MATCH(N$5,APOIO!$B$5:$N$5,0),FALSE),0) -> 0 | O6: =IFERROR(N6/N$6,0) -> 0 | P6: =SUM(J6,L6,N6) -> 0 | Q6: =IFERROR(P6/P$6,0) -> 0 | R6: =IFERROR(VLOOKUP($A6,APOIO!$B:$N,MATCH(R$5,APOIO!$B$5:$N$5,0),FALSE),0) -> 0 | S6: =IFERROR(R6/R$6,0) -> 0 | T6: =IFERROR(VLOOKUP($A6,APOIO!$B:$N,MATCH(T$5,APOIO!$B$5:$N$5,0),FALSE),0) -> 0 | U6: =IFERROR(T6/T$6,0) -> 0 | V6: =IFERROR(VLOOKUP($A6,APOIO!$B:$N,MATCH(V$5,APOIO!$B$5:$N$5,0),FALSE),0) -> 0 | W6: =IFERROR(V6/V$6,0) -> 0 | X6: =SUM(R6,T6,V6) -> 0 | Y6: =IFERROR(X6/X$6,0) -> 0 | Z6: =IFERROR(VLOOKUP($A6,APOIO!$B:$N,MATCH(Z$5,APOIO!$B$5:$N$5,0),FALSE),0) -> 0 | AA6: =IFERROR(Z6/Z$6,0) -> 0 | AB6: =IFERROR(VLOOKUP($A6,APOIO!$B:$N,MATCH(AB$5,APOIO!$B$5:$N$5,0),FALSE),0) -> 0 | AC6: =IFERROR(AB6/AB$6,0) -> 0 | AD6: =IFERROR(VLOOKUP($A6,APOIO!$B:$N,MATCH(AD$5,APOIO!$B$5:$N$5,0),FALSE),0) -> 0 | AE6: =IFERROR(AD6/AD$6,0) -> 0 | AF6: =SUM(Z6,AB6,AD6) -> 0 | AG6: =IFERROR(AF6/AF$6,0) -> 0 | AH6: =SUM(B6,D6,F6,J6,L6,N6,R6,T6,V6,Z6,AB6,AD6) -> 593484.04 | AI6: =IFERROR(AH6/AH$6,0) -> 1
A7: Faturamento | B7: =IFERROR(VLOOKUP($A7,APOIO!$B:$N,MATCH(B$5,APOIO!$B$5:$N$5,0),FALSE),0) -> 173156.44 | C7: =B7/B$6 -> 1 | D7: =IFERROR(VLOOKUP($A7,APOIO!$B:$N,MATCH(D$5,APOIO!$B$5:$N$5,0),FALSE),0) -> 420327.6 | E7: =D7/D$6 -> 1 | F7: =IFERROR(VLOOKUP($A7,APOIO!$B:$N,MATCH(F$5,APOIO!$B$5:$N$5,0),FALSE),0) -> 0 | G7: =F7/F$6 -> #DIV/0! | H7: =SUM(B7,D7,F7) -> 593484.04 | I7: =H7/H$6 -> 1 | J7: =IFERROR(VLOOKUP($A7,APOIO!$B:$N,MATCH(J$5,APOIO!$B$5:$N$5,0),FALSE),0) -> 0 | K7: =J7/J$6 -> #DIV/0! | L7: =IFERROR(VLOOKUP($A7,APOIO!$B:$N,MATCH(L$5,APOIO!$B$5:$N$5,0),FALSE),0) -> 0 | M7: =L7/L$6 -> #DIV/0! | N7: =IFERROR(VLOOKUP($A7,APOIO!$B:$N,MATCH(N$5,APOIO!$B$5:$N$5,0),FALSE),0) -> 0 | O7: =N7/N$6 -> #DIV/0! | P7: =SUM(J7,L7,N7) -> 0 | Q7: =P7/P$6 -> #DIV/0! | R7: =IFERROR(VLOOKUP($A7,APOIO!$B:$N,MATCH(R$5,APOIO!$B$5:$N$5,0),FALSE),0) -> 0 | S7: =R7/R$6 -> #DIV/0! | T7: =IFERROR(VLOOKUP($A7,APOIO!$B:$N,MATCH(T$5,APOIO!$B$5:$N$5,0),FALSE),0) -> 0 | U7: =T7/T$6 -> #DIV/0! | V7: =IFERROR(VLOOKUP($A7,APOIO!$B:$N,MATCH(V$5,APOIO!$B$5:$N$5,0),FALSE),0) -> 0 | W7: =V7/V$6 -> #DIV/0! | X7: =SUM(R7,T7,V7) -> 0 | Y7: =X7/X$6 -> #DIV/0! | Z7: =IFERROR(VLOOKUP($A7,APOIO!$B:$N,MATCH(Z$5,APOIO!$B$5:$N$5,0),FALSE),0) -> 0 | AA7: =Z7/Z$6 -> #DIV/0! | AB7: =IFERROR(VLOOKUP($A7,APOIO!$B:$N,MATCH(AB$5,APOIO!$B$5:$N$5,0),FALSE),0) -> 0 | AC7: =AB7/AB$6 -> #DIV/0! | AD7: =IFERROR(VLOOKUP($A7,APOIO!$B:$N,MATCH(AD$5,APOIO!$B$5:$N$5,0),FALSE),0) -> 0 | AE7: =AD7/AD$6 -> #DIV/0! | AF7: =SUM(Z7,AB7,AD7) -> 0 | AG7: =AF7/AF$6 -> #DIV/0! | AH7: =SUM(B7,D7,F7,J7,L7,N7,R7,T7,V7,Z7,AB7,AD7) -> 593484.04 | AI7: =AH7/AH$6 -> 1
A8: (-)Deduções sobre vendas | B8: =IFERROR(VLOOKUP($A8,APOIO!$B:$N,MATCH(B$5,APOIO!$B$5:$N$5,0),FALSE),0) -> -17981.98 | C8: =IFERROR(B8/B$6,0) -> -0.10384817 | D8: =IFERROR(VLOOKUP($A8,APOIO!$B:$N,MATCH(D$5,APOIO!$B$5:$N$5,0),FALSE),0) -> -55263.83 | E8: =IFERROR(D8/D$6,0) -> -0.13147799 | F8: =IFERROR(VLOOKUP($A8,APOIO!$B:$N,MATCH(F$5,APOIO!$B$5:$N$5,0),FALSE),0) -> 0 | G8: =IFERROR(F8/F$6,0) -> 0 | H8: =SUM(B8,D8,F8) -> -73245.81 | I8: =IFERROR(H8/H$6,0) -> -0.12341665 | J8: =IFERROR(VLOOKUP($A8,APOIO!$B:$N,MATCH(J$5,APOIO!$B$5:$N$5,0),FALSE),0) -> 0 | K8: =IFERROR(J8/J$6,0) -> 0 | L8: =IFERROR(VLOOKUP($A8,APOIO!$B:$N,MATCH(L$5,APOIO!$B$5:$N$5,0),FALSE),0) -> 0 | M8: =IFERROR(L8/L$6,0) -> 0 | N8: =IFERROR(VLOOKUP($A8,APOIO!$B:$N,MATCH(N$5,APOIO!$B$5:$N$5,0),FALSE),0) -> 0 | O8: =IFERROR(N8/N$6,0) -> 0 | P8: =SUM(J8,L8,N8) -> 0 | Q8: =IFERROR(P8/P$6,0) -> 0 | R8: =IFERROR(VLOOKUP($A8,APOIO!$B:$N,MATCH(R$5,APOIO!$B$5:$N$5,0),FALSE),0) -> 0 | S8: =IFERROR(R8/R$6,0) -> 0 | T8: =IFERROR(VLOOKUP($A8,APOIO!$B:$N,MATCH(T$5,APOIO!$B$5:$N$5,0),FALSE),0) -> 0 | U8: =IFERROR(T8/T$6,0) -> 0 | V8: =IFERROR(VLOOKUP($A8,APOIO!$B:$N,MATCH(V$5,APOIO!$B$5:$N$5,0),FALSE),0) -> 0 | W8: =IFERROR(V8/V$6,0) -> 0 | X8: =SUM(R8,T8,V8) -> 0 | Y8: =IFERROR(X8/X$6,0) -> 0 | Z8: =IFERROR(VLOOKUP($A8,APOIO!$B:$N,MATCH(Z$5,APOIO!$B$5:$N$5,0),FALSE),0) -> 0 | AA8: =IFERROR(Z8/Z$6,0) -> 0 | AB8: =IFERROR(VLOOKUP($A8,APOIO!$B:$N,MATCH(AB$5,APOIO!$B$5:$N$5,0),FALSE),0) -> 0 | AC8: =IFERROR(AB8/AB$6,0) -> 0 | AD8: =IFERROR(VLOOKUP($A8,APOIO!$B:$N,MATCH(AD$5,APOIO!$B$5:$N$5,0),FALSE),0) -> 0 | AE8: =IFERROR(AD8/AD$6,0) -> 0 | AF8: =SUM(Z8,AB8,AD8) -> 0 | AG8: =IFERROR(AF8/AF$6,0) -> 0 | AH8: =SUM(B8,D8,F8,J8,L8,N8,R8,T8,V8,Z8,AB8,AD8) -> -73245.81 | AI8: =IFERROR(AH8/AH$6,0) -> -0.12341665
A9: Descontos sobre vendas | B9: =IFERROR(VLOOKUP($A9,APOIO!$B:$N,MATCH(B$5,APOIO!$B$5:$N$5,0),FALSE),0) -> 0 | C9: =IFERROR(B9/B$6,0) -> 0 | D9: =IFERROR(VLOOKUP($A9,APOIO!$B:$N,MATCH(D$5,APOIO!$B$5:$N$5,0),FALSE),0) -> 0 | E9: =IFERROR(D9/D$6,0) -> 0 | F9: =IFERROR(VLOOKUP($A9,APOIO!$B:$N,MATCH(F$5,APOIO!$B$5:$N$5,0),FALSE),0) -> 0 | G9: =IFERROR(F9/F$6,0) -> 0 | H9: =SUM(B9,D9,F9) -> 0 | I9: =IFERROR(H9/H$6,0) -> 0 | J9: =IFERROR(VLOOKUP($A9,APOIO!$B:$N,MATCH(J$5,APOIO!$B$5:$N$5,0),FALSE),0) -> 0 | K9: =IFERROR(J9/J$6,0) -> 0 | L9: =IFERROR(VLOOKUP($A9,APOIO!$B:$N,MATCH(L$5,APOIO!$B$5:$N$5,0),FALSE),0) -> 0 | M9: =IFERROR(L9/L$6,0) -> 0 | N9: =IFERROR(VLOOKUP($A9,APOIO!$B:$N,MATCH(N$5,APOIO!$B$5:$N$5,0),FALSE),0) -> 0 | O9: =IFERROR(N9/N$6,0) -> 0 | P9: =SUM(J9,L9,N9) -> 0 | Q9: =IFERROR(P9/P$6,0) -> 0 | R9: =IFERROR(VLOOKUP($A9,APOIO!$B:$N,MATCH(R$5,APOIO!$B$5:$N$5,0),FALSE),0) -> 0 | S9: =IFERROR(R9/R$6,0) -> 0 | T9: =IFERROR(VLOOKUP($A9,APOIO!$B:$N,MATCH(T$5,APOIO!$B$5:$N$5,0),FALSE),0) -> 0 | U9: =IFERROR(T9/T$6,0) -> 0 | V9: =IFERROR(VLOOKUP($A9,APOIO!$B:$N,MATCH(V$5,APOIO!$B$5:$N$5,0),FALSE),0) -> 0 | W9: =IFERROR(V9/V$6,0) -> 0 | X9: =SUM(R9,T9,V9) -> 0 | Y9: =IFERROR(X9/X$6,0) -> 0 | Z9: =IFERROR(VLOOKUP($A9,APOIO!$B:$N,MATCH(Z$5,APOIO!$B$5:$N$5,0),FALSE),0) -> 0 | AA9: =IFERROR(Z9/Z$6,0) -> 0 | AB9: =IFERROR(VLOOKUP($A9,APOIO!$B:$N,MATCH(AB$5,APOIO!$B$5:$N$5,0),FALSE),0) -> 0 | AC9: =IFERROR(AB9/AB$6,0) -> 0 | AD9: =IFERROR(VLOOKUP($A9,APOIO!$B:$N,MATCH(AD$5,APOIO!$B$5:$N$5,0),FALSE),0) -> 0 | AE9: =IFERROR(AD9/AD$6,0) -> 0 | AF9: =SUM(Z9,AB9,AD9) -> 0 | AG9: =IFERROR(AF9/AF$6,0) -> 0 | AH9: =SUM(B9,D9,F9,J9,L9,N9,R9,T9,V9,Z9,AB9,AD9) -> 0 | AI9: =IFERROR(AH9/AH$6,0) -> 0
A10: Impostos sobre vendas | B10: =IFERROR(VLOOKUP($A10,APOIO!$B:$N,MATCH(B$5,APOIO!$B$5:$N$5,0),FALSE),0) -> -17981.98 | C10: =IFERROR(B10/B$6,0) -> -0.10384817 | D10: =IFERROR(VLOOKUP($A10,APOIO!$B:$N,MATCH(D$5,APOIO!$B$5:$N$5,0),FALSE),0) -> -55263.83 | E10: =IFERROR(D10/D$6,0) -> -0.13147799 | F10: =IFERROR(VLOOKUP($A10,APOIO!$B:$N,MATCH(F$5,APOIO!$B$5:$N$5,0),FALSE),0) -> 0 | G10: =IFERROR(F10/F$6,0) -> 0 | H10: =SUM(B10,D10,F10) -> -73245.81 | I10: =IFERROR(H10/H$6,0) -> -0.12341665 | J10: =IFERROR(VLOOKUP($A10,APOIO!$B:$N,MATCH(J$5,APOIO!$B$5:$N$5,0),FALSE),0) -> 0 | K10: =IFERROR(J10/J$6,0) -> 0 | L10: =IFERROR(VLOOKUP($A10,APOIO!$B:$N,MATCH(L$5,APOIO!$B$5:$N$5,0),FALSE),0) -> 0 | M10: =IFERROR(L10/L$6,0) -> 0 | N10: =IFERROR(VLOOKUP($A10,APOIO!$B:$N,MATCH(N$5,APOIO!$B$5:$N$5,0),FALSE),0) -> 0 | O10: =IFERROR(N10/N$6,0) -> 0 | P10: =SUM(J10,L10,N10) -> 0 | Q10: =IFERROR(P10/P$6,0) -> 0 | R10: =IFERROR(VLOOKUP($A10,APOIO!$B:$N,MATCH(R$5,APOIO!$B$5:$N$5,0),FALSE),0) -> 0 | S10: =IFERROR(R10/R$6,0) -> 0 | T10: =IFERROR(VLOOKUP($A10,APOIO!$B:$N,MATCH(T$5,APOIO!$B$5:$N$5,0),FALSE),0) -> 0 | U10: =IFERROR(T10/T$6,0) -> 0 | V10: =IFERROR(VLOOKUP($A10,APOIO!$B:$N,MATCH(V$5,APOIO!$B$5:$N$5,0),FALSE),0) -> 0 | W10: =IFERROR(V10/V$6,0) -> 0 | X10: =SUM(R10,T10,V10) -> 0 | Y10: =IFERROR(X10/X$6,0) -> 0 | Z10: =IFERROR(VLOOKUP($A10,APOIO!$B:$N,MATCH(Z$5,APOIO!$B$5:$N$5,0),FALSE),0) -> 0 | AA10: =IFERROR(Z10/Z$6,0) -> 0 | AB10: =IFERROR(VLOOKUP($A10,APOIO!$B:$N,MATCH(AB$5,APOIO!$B$5:$N$5,0),FALSE),0) -> 0 | AC10: =IFERROR(AB10/AB$6,0) -> 0 | AD10: =IFERROR(VLOOKUP($A10,APOIO!$B:$N,MATCH(AD$5,APOIO!$B$5:$N$5,0),FALSE),0) -> 0 | AE10: =IFERROR(AD10/AD$6,0) -> 0 | AF10: =SUM(Z10,AB10,AD10) -> 0 | AG10: =IFERROR(AF10/AF$6,0) -> 0 | AH10: =SUM(B10,D10,F10,J10,L10,N10,R10,T10,V10,Z10,AB10,AD10) -> -73245.81 | AI10: =IFERROR(AH10/AH$6,0) -> -0.12341665
A11: Simples Nacional | B11: =IFERROR(VLOOKUP($A11,APOIO!$B:$N,MATCH(B$5,APOIO!$B$5:$N$5,0),FALSE),0) -> 0 | C11: =IFERROR(B11/B$6,0) -> 0 | D11: =IFERROR(VLOOKUP($A11,APOIO!$B:$N,MATCH(D$5,APOIO!$B$5:$N$5,0),FALSE),0) -> 0 | E11: =IFERROR(D11/D$6,0) -> 0 | F11: =IFERROR(VLOOKUP($A11,APOIO!$B:$N,MATCH(F$5,APOIO!$B$5:$N$5,0),FALSE),0) -> 0 | G11: =IFERROR(F11/F$6,0) -> 0 | H11: =SUM(B11,D11,F11) -> 0 | I11: =IFERROR(H11/H$6,0) -> 0 | J11: =IFERROR(VLOOKUP($A11,APOIO!$B:$N,MATCH(J$5,APOIO!$B$5:$N$5,0),FALSE),0) -> 0 | K11: =IFERROR(J11/J$6,0) -> 0 | L11: =IFERROR(VLOOKUP($A11,APOIO!$B:$N,MATCH(L$5,APOIO!$B$5:$N$5,0),FALSE),0) -> 0 | M11: =IFERROR(L11/L$6,0) -> 0 | N11: =IFERROR(VLOOKUP($A11,APOIO!$B:$N,MATCH(N$5,APOIO!$B$5:$N$5,0),FALSE),0) -> 0 | O11: =IFERROR(N11/N$6,0) -> 0 | P11: =SUM(J11,L11,N11) -> 0 | Q11: =IFERROR(P11/P$6,0) -> 0 | R11: =IFERROR(VLOOKUP($A11,APOIO!$B:$N,MATCH(R$5,APOIO!$B$5:$N$5,0),FALSE),0) -> 0 | S11: =IFERROR(R11/R$6,0) -> 0 | T11: =IFERROR(VLOOKUP($A11,APOIO!$B:$N,MATCH(T$5,APOIO!$B$5:$N$5,0),FALSE),0) -> 0 | U11: =IFERROR(T11/T$6,0) -> 0 | V11: =IFERROR(VLOOKUP($A11,APOIO!$B:$N,MATCH(V$5,APOIO!$B$5:$N$5,0),FALSE),0) -> 0 | W11: =IFERROR(V11/V$6,0) -> 0 | X11: =SUM(R11,T11,V11) -> 0 | Y11: =IFERROR(X11/X$6,0) -> 0 | Z11: =IFERROR(VLOOKUP($A11,APOIO!$B:$N,MATCH(Z$5,APOIO!$B$5:$N$5,0),FALSE),0) -> 0 | AA11: =IFERROR(Z11/Z$6,0) -> 0 | AB11: =IFERROR(VLOOKUP($A11,APOIO!$B:$N,MATCH(AB$5,APOIO!$B$5:$N$5,0),FALSE),0) -> 0 | AC11: =IFERROR(AB11/AB$6,0) -> 0 | AD11: =IFERROR(VLOOKUP($A11,APOIO!$B:$N,MATCH(AD$5,APOIO!$B$5:$N$5,0),FALSE),0) -> 0 | AE11: =IFERROR(AD11/AD$6,0) -> 0 | AF11: =SUM(Z11,AB11,AD11) -> 0 | AG11: =IFERROR(AF11/AF$6,0) -> 0 | AH11: =SUM(B11,D11,F11,J11,L11,N11,R11,T11,V11,Z11,AB11,AD11) -> 0 | AI11: =IFERROR(AH11/AH$6,0) -> 0
A12: IR Retido | B12: =IFERROR(VLOOKUP($A12,APOIO!$B:$N,MATCH(B$5,APOIO!$B$5:$N$5,0),FALSE),0) -> -1976.04 | C12: =IFERROR(B12/B$6,0) -> -0.011411877 | D12: =IFERROR(VLOOKUP($A12,APOIO!$B:$N,MATCH(D$5,APOIO!$B$5:$N$5,0),FALSE),0) -> -6072.95 | E12: =IFERROR(D12/D$6,0) -> -0.014448135 | F12: =IFERROR(VLOOKUP($A12,APOIO!$B:$N,MATCH(F$5,APOIO!$B$5:$N$5,0),FALSE),0) -> 0 | G12: =IFERROR(F12/F$6,0) -> 0 | H12: =SUM(B12,D12,F12) -> -8048.99 | I12: =IFERROR(H12/H$6,0) -> -0.013562269 | J12: =IFERROR(VLOOKUP($A12,APOIO!$B:$N,MATCH(J$5,APOIO!$B$5:$N$5,0),FALSE),0) -> 0 | K12: =IFERROR(J12/J$6,0) -> 0 | L12: =IFERROR(VLOOKUP($A12,APOIO!$B:$N,MATCH(L$5,APOIO!$B$5:$N$5,0),FALSE),0) -> 0 | M12: =IFERROR(L12/L$6,0) -> 0 | N12: =IFERROR(VLOOKUP($A12,APOIO!$B:$N,MATCH(N$5,APOIO!$B$5:$N$5,0),FALSE),0) -> 0 | O12: =IFERROR(N12/N$6,0) -> 0 | P12: =SUM(J12,L12,N12) -> 0 | Q12: =IFERROR(P12/P$6,0) -> 0 | R12: =IFERROR(VLOOKUP($A12,APOIO!$B:$N,MATCH(R$5,APOIO!$B$5:$N$5,0),FALSE),0) -> 0 | S12: =IFERROR(R12/R$6,0) -> 0 | T12: =IFERROR(VLOOKUP($A12,APOIO!$B:$N,MATCH(T$5,APOIO!$B$5:$N$5,0),FALSE),0) -> 0 | U12: =IFERROR(T12/T$6,0) -> 0 | V12: =IFERROR(VLOOKUP($A12,APOIO!$B:$N,MATCH(V$5,APOIO!$B$5:$N$5,0),FALSE),0) -> 0 | W12: =IFERROR(V12/V$6,0) -> 0 | X12: =SUM(R12,T12,V12) -> 0 | Y12: =IFERROR(X12/X$6,0) -> 0 | Z12: =IFERROR(VLOOKUP($A12,APOIO!$B:$N,MATCH(Z$5,APOIO!$B$5:$N$5,0),FALSE),0) -> 0 | AA12: =IFERROR(Z12/Z$6,0) -> 0 | AB12: =IFERROR(VLOOKUP($A12,APOIO!$B:$N,MATCH(AB$5,APOIO!$B$5:$N$5,0),FALSE),0) -> 0 | AC12: =IFERROR(AB12/AB$6,0) -> 0 | AD12: =IFERROR(VLOOKUP($A12,APOIO!$B:$N,MATCH(AD$5,APOIO!$B$5:$N$5,0),FALSE),0) -> 0 | AE12: =IFERROR(AD12/AD$6,0) -> 0 | AF12: =SUM(Z12,AB12,AD12) -> 0 | AG12: =IFERROR(AF12/AF$6,0) -> 0 | AH12: =SUM(B12,D12,F12,J12,L12,N12,R12,T12,V12,Z12,AB12,AD12) -> -8048.99 | AI12: =IFERROR(AH12/AH$6,0) -> -0.013562269
A13: ISS Retido | B13: =IFERROR(VLOOKUP($A13,APOIO!$B:$N,MATCH(B$5,APOIO!$B$5:$N$5,0),FALSE),0) -> -6586.81 | C13: =IFERROR(B13/B$6,0) -> -0.038039648 | D13: =IFERROR(VLOOKUP($A13,APOIO!$B:$N,MATCH(D$5,APOIO!$B$5:$N$5,0),FALSE),0) -> -20243.16 | E13: =IFERROR(D13/D$6,0) -> -0.048160435 | F13: =IFERROR(VLOOKUP($A13,APOIO!$B:$N,MATCH(F$5,APOIO!$B$5:$N$5,0),FALSE),0) -> 0 | G13: =IFERROR(F13/F$6,0) -> 0 | H13: =SUM(B13,D13,F13) -> -26829.97 | I13: =IFERROR(H13/H$6,0) -> -0.045207568 | J13: =IFERROR(VLOOKUP($A13,APOIO!$B:$N,MATCH(J$5,APOIO!$B$5:$N$5,0),FALSE),0) -> 0 | K13: =IFERROR(J13/J$6,0) -> 0 | L13: =IFERROR(VLOOKUP($A13,APOIO!$B:$N,MATCH(L$5,APOIO!$B$5:$N$5,0),FALSE),0) -> 0 | M13: =IFERROR(L13/L$6,0) -> 0 | N13: =IFERROR(VLOOKUP($A13,APOIO!$B:$N,MATCH(N$5,APOIO!$B$5:$N$5,0),FALSE),0) -> 0 | O13: =IFERROR(N13/N$6,0) -> 0 | P13: =SUM(J13,L13,N13) -> 0 | Q13: =IFERROR(P13/P$6,0) -> 0 | R13: =IFERROR(VLOOKUP($A13,APOIO!$B:$N,MATCH(R$5,APOIO!$B$5:$N$5,0),FALSE),0) -> 0 | S13: =IFERROR(R13/R$6,0) -> 0 | T13: =IFERROR(VLOOKUP($A13,APOIO!$B:$N,MATCH(T$5,APOIO!$B$5:$N$5,0),FALSE),0) -> 0 | U13: =IFERROR(T13/T$6,0) -> 0 | V13: =IFERROR(VLOOKUP($A13,APOIO!$B:$N,MATCH(V$5,APOIO!$B$5:$N$5,0),FALSE),0) -> 0 | W13: =IFERROR(V13/V$6,0) -> 0 | X13: =SUM(R13,T13,V13) -> 0 | Y13: =IFERROR(X13/X$6,0) -> 0 | Z13: =IFERROR(VLOOKUP($A13,APOIO!$B:$N,MATCH(Z$5,APOIO!$B$5:$N$5,0),FALSE),0) -> 0 | AA13: =IFERROR(Z13/Z$6,0) -> 0 | AB13: =IFERROR(VLOOKUP($A13,APOIO!$B:$N,MATCH(AB$5,APOIO!$B$5:$N$5,0),FALSE),0) -> 0 | AC13: =IFERROR(AB13/AB$6,0) -> 0 | AD13: =IFERROR(VLOOKUP($A13,APOIO!$B:$N,MATCH(AD$5,APOIO!$B$5:$N$5,0),FALSE),0) -> 0 | AE13: =IFERROR(AD13/AD$6,0) -> 0 | AF13: =SUM(Z13,AB13,AD13) -> 0 | AG13: =IFERROR(AF13/AF$6,0) -> 0 | AH13: =SUM(B13,D13,F13,J13,L13,N13,R13,T13,V13,Z13,AB13,AD13) -> -26829.97 | AI13: =IFERROR(AH13/AH$6,0) -> -0.045207568
A14: INSS Retido | B14: =IFERROR(VLOOKUP($A14,APOIO!$B:$N,MATCH(B$5,APOIO!$B$5:$N$5,0),FALSE),0) -> -4610.76 | C14: =IFERROR(B14/B$6,0) -> -0.026627713 | D14: =IFERROR(VLOOKUP($A14,APOIO!$B:$N,MATCH(D$5,APOIO!$B$5:$N$5,0),FALSE),0) -> -14170.21 | E14: =IFERROR(D14/D$6,0) -> -0.0337123 | F14: =IFERROR(VLOOKUP($A14,APOIO!$B:$N,MATCH(F$5,APOIO!$B$5:$N$5,0),FALSE),0) -> 0 | G14: =IFERROR(F14/F$6,0) -> 0 | H14: =SUM(B14,D14,F14) -> -18780.97 | I14: =IFERROR(H14/H$6,0) -> -0.031645282 | J14: =IFERROR(VLOOKUP($A14,APOIO!$B:$N,MATCH(J$5,APOIO!$B$5:$N$5,0),FALSE),0) -> 0 | K14: =IFERROR(J14/J$6,0) -> 0 | L14: =IFERROR(VLOOKUP($A14,APOIO!$B:$N,MATCH(L$5,APOIO!$B$5:$N$5,0),FALSE),0) -> 0 | M14: =IFERROR(L14/L$6,0) -> 0 | N14: =IFERROR(VLOOKUP($A14,APOIO!$B:$N,MATCH(N$5,APOIO!$B$5:$N$5,0),FALSE),0) -> 0 | O14: =IFERROR(N14/N$6,0) -> 0 | P14: =SUM(J14,L14,N14) -> 0 | Q14: =IFERROR(P14/P$6,0) -> 0 | R14: =IFERROR(VLOOKUP($A14,APOIO!$B:$N,MATCH(R$5,APOIO!$B$5:$N$5,0),FALSE),0) -> 0 | S14: =IFERROR(R14/R$6,0) -> 0 | T14: =IFERROR(VLOOKUP($A14,APOIO!$B:$N,MATCH(T$5,APOIO!$B$5:$N$5,0),FALSE),0) -> 0 | U14: =IFERROR(T14/T$6,0) -> 0 | V14: =IFERROR(VLOOKUP($A14,APOIO!$B:$N,MATCH(V$5,APOIO!$B$5:$N$5,0),FALSE),0) -> 0 | W14: =IFERROR(V14/V$6,0) -> 0 | X14: =SUM(R14,T14,V14) -> 0 | Y14: =IFERROR(X14/X$6,0) -> 0 | Z14: =IFERROR(VLOOKUP($A14,APOIO!$B:$N,MATCH(Z$5,APOIO!$B$5:$N$5,0),FALSE),0) -> 0 | AA14: =IFERROR(Z14/Z$6,0) -> 0 | AB14: =IFERROR(VLOOKUP($A14,APOIO!$B:$N,MATCH(AB$5,APOIO!$B$5:$N$5,0),FALSE),0) -> 0 | AC14: =IFERROR(AB14/AB$6,0) -> 0 | AD14: =IFERROR(VLOOKUP($A14,APOIO!$B:$N,MATCH(AD$5,APOIO!$B$5:$N$5,0),FALSE),0) -> 0 | AE14: =IFERROR(AD14/AD$6,0) -> 0 | AF14: =SUM(Z14,AB14,AD14) -> 0 | AG14: =IFERROR(AF14/AF$6,0) -> 0 | AH14: =SUM(B14,D14,F14,J14,L14,N14,R14,T14,V14,Z14,AB14,AD14) -> -18780.97 | AI14: =IFERROR(AH14/AH$6,0) -> -0.031645282
A15: Tarifa de Antecipação | B15: =IFERROR(VLOOKUP($A15,APOIO!$B:$N,MATCH(B$5,APOIO!$B$5:$N$5,0),FALSE),0) -> 0 | C15: =IFERROR(B15/B$6,0) -> 0 | D15: =IFERROR(VLOOKUP($A15,APOIO!$B:$N,MATCH(D$5,APOIO!$B$5:$N$5,0),FALSE),0) -> 0 | E15: =IFERROR(D15/D$6,0) -> 0 | F15: =IFERROR(VLOOKUP($A15,APOIO!$B:$N,MATCH(F$5,APOIO!$B$5:$N$5,0),FALSE),0) -> 0 | G15: =IFERROR(F15/F$6,0) -> 0 | H15: =SUM(B15,D15,F15) -> 0 | I15: =IFERROR(H15/H$6,0) -> 0 | J15: =IFERROR(VLOOKUP($A15,APOIO!$B:$N,MATCH(J$5,APOIO!$B$5:$N$5,0),FALSE),0) -> 0 | K15: =IFERROR(J15/J$6,0) -> 0 | L15: =IFERROR(VLOOKUP($A15,APOIO!$B:$N,MATCH(L$5,APOIO!$B$5:$N$5,0),FALSE),0) -> 0 | M15: =IFERROR(L15/L$6,0) -> 0 | N15: =IFERROR(VLOOKUP($A15,APOIO!$B:$N,MATCH(N$5,APOIO!$B$5:$N$5,0),FALSE),0) -> 0 | O15: =IFERROR(N15/N$6,0) -> 0 | P15: =SUM(J15,L15,N15) -> 0 | Q15: =IFERROR(P15/P$6,0) -> 0 | R15: =IFERROR(VLOOKUP($A15,APOIO!$B:$N,MATCH(R$5,APOIO!$B$5:$N$5,0),FALSE),0) -> 0 | S15: =IFERROR(R15/R$6,0) -> 0 | T15: =IFERROR(VLOOKUP($A15,APOIO!$B:$N,MATCH(T$5,APOIO!$B$5:$N$5,0),FALSE),0) -> 0 | U15: =IFERROR(T15/T$6,0) -> 0 | V15: =IFERROR(VLOOKUP($A15,APOIO!$B:$N,MATCH(V$5,APOIO!$B$5:$N$5,0),FALSE),0) -> 0 | W15: =IFERROR(V15/V$6,0) -> 0 | X15: =SUM(R15,T15,V15) -> 0 | Y15: =IFERROR(X15/X$6,0) -> 0 | Z15: =IFERROR(VLOOKUP($A15,APOIO!$B:$N,MATCH(Z$5,APOIO!$B$5:$N$5,0),FALSE),0) -> 0 | AA15: =IFERROR(Z15/Z$6,0) -> 0 | AB15: =IFERROR(VLOOKUP($A15,APOIO!$B:$N,MATCH(AB$5,APOIO!$B$5:$N$5,0),FALSE),0) -> 0 | AC15: =IFERROR(AB15/AB$6,0) -> 0 | AD15: =IFERROR(VLOOKUP($A15,APOIO!$B:$N,MATCH(AD$5,APOIO!$B$5:$N$5,0),FALSE),0) -> 0 | AE15: =IFERROR(AD15/AD$6,0) -> 0 | AF15: =SUM(Z15,AB15,AD15) -> 0 | AG15: =IFERROR(AF15/AF$6,0) -> 0 | AH15: =SUM(B15,D15,F15,J15,L15,N15,R15,T15,V15,Z15,AB15,AD15) -> 0 | AI15: =IFERROR(AH15/AH$6,0) -> 0
A16: ISS | B16: =IFERROR(VLOOKUP($A16,APOIO!$B:$N,MATCH(B$5,APOIO!$B$5:$N$5,0),FALSE),0) -> 0 | C16: =IFERROR(B16/B$6,0) -> 0 | D16: =IFERROR(VLOOKUP($A16,APOIO!$B:$N,MATCH(D$5,APOIO!$B$5:$N$5,0),FALSE),0) -> 0 | E16: =IFERROR(D16/D$6,0) -> 0 | F16: =IFERROR(VLOOKUP($A16,APOIO!$B:$N,MATCH(F$5,APOIO!$B$5:$N$5,0),FALSE),0) -> 0 | G16: =IFERROR(F16/F$6,0) -> 0 | H16: =SUM(B16,D16,F16) -> 0 | I16: =IFERROR(H16/H$6,0) -> 0 | J16: =IFERROR(VLOOKUP($A16,APOIO!$B:$N,MATCH(J$5,APOIO!$B$5:$N$5,0),FALSE),0) -> 0 | K16: =IFERROR(J16/J$6,0) -> 0 | L16: =IFERROR(VLOOKUP($A16,APOIO!$B:$N,MATCH(L$5,APOIO!$B$5:$N$5,0),FALSE),0) -> 0 | M16: =IFERROR(L16/L$6,0) -> 0 | N16: =IFERROR(VLOOKUP($A16,APOIO!$B:$N,MATCH(N$5,APOIO!$B$5:$N$5,0),FALSE),0) -> 0 | O16: =IFERROR(N16/N$6,0) -> 0 | P16: =SUM(J16,L16,N16) -> 0 | Q16: =IFERROR(P16/P$6,0) -> 0 | R16: =IFERROR(VLOOKUP($A16,APOIO!$B:$N,MATCH(R$5,APOIO!$B$5:$N$5,0),FALSE),0) -> 0 | S16: =IFERROR(R16/R$6,0) -> 0 | T16: =IFERROR(VLOOKUP($A16,APOIO!$B:$N,MATCH(T$5,APOIO!$B$5:$N$5,0),FALSE),0) -> 0 | U16: =IFERROR(T16/T$6,0) -> 0 | V16: =IFERROR(VLOOKUP($A16,APOIO!$B:$N,MATCH(V$5,APOIO!$B$5:$N$5,0),FALSE),0) -> 0 | W16: =IFERROR(V16/V$6,0) -> 0 | X16: =SUM(R16,T16,V16) -> 0 | Y16: =IFERROR(X16/X$6,0) -> 0 | Z16: =IFERROR(VLOOKUP($A16,APOIO!$B:$N,MATCH(Z$5,APOIO!$B$5:$N$5,0),FALSE),0) -> 0 | AA16: =IFERROR(Z16/Z$6,0) -> 0 | AB16: =IFERROR(VLOOKUP($A16,APOIO!$B:$N,MATCH(AB$5,APOIO!$B$5:$N$5,0),FALSE),0) -> 0 | AC16: =IFERROR(AB16/AB$6,0) -> 0 | AD16: =IFERROR(VLOOKUP($A16,APOIO!$B:$N,MATCH(AD$5,APOIO!$B$5:$N$5,0),FALSE),0) -> 0 | AE16: =IFERROR(AD16/AD$6,0) -> 0 | AF16: =SUM(Z16,AB16,AD16) -> 0 | AG16: =IFERROR(AF16/AF$6,0) -> 0 | AH16: =SUM(B16,D16,F16,J16,L16,N16,R16,T16,V16,Z16,AB16,AD16) -> 0 | AI16: =IFERROR(AH16/AH$6,0) -> 0
A17: PIS | B17: =IFERROR(VLOOKUP($A17,APOIO!$B:$N,MATCH(B$5,APOIO!$B$5:$N$5,0),FALSE),0) -> -856.29 | C17: =IFERROR(B17/B$6,0) -> -0.0049451814 | D17: =IFERROR(VLOOKUP($A17,APOIO!$B:$N,MATCH(D$5,APOIO!$B$5:$N$5,0),FALSE),0) -> -2631.62 | E17: =IFERROR(D17/D$6,0) -> -0.0062608784 | F17: =IFERROR(VLOOKUP($A17,APOIO!$B:$N,MATCH(F$5,APOIO!$B$5:$N$5,0),FALSE),0) -> 0 | G17: =IFERROR(F17/F$6,0) -> 0 | H17: =SUM(B17,D17,F17) -> -3487.91 | I17: =IFERROR(H17/H$6,0) -> -0.0058770072 | J17: =IFERROR(VLOOKUP($A17,APOIO!$B:$N,MATCH(J$5,APOIO!$B$5:$N$5,0),FALSE),0) -> 0 | K17: =IFERROR(J17/J$6,0) -> 0 | L17: =IFERROR(VLOOKUP($A17,APOIO!$B:$N,MATCH(L$5,APOIO!$B$5:$N$5,0),FALSE),0) -> 0 | M17: =IFERROR(L17/L$6,0) -> 0 | N17: =IFERROR(VLOOKUP($A17,APOIO!$B:$N,MATCH(N$5,APOIO!$B$5:$N$5,0),FALSE),0) -> 0 | O17: =IFERROR(N17/N$6,0) -> 0 | P17: =SUM(J17,L17,N17) -> 0 | Q17: =IFERROR(P17/P$6,0) -> 0 | R17: =IFERROR(VLOOKUP($A17,APOIO!$B:$N,MATCH(R$5,APOIO!$B$5:$N$5,0),FALSE),0) -> 0 | S17: =IFERROR(R17/R$6,0) -> 0 | T17: =IFERROR(VLOOKUP($A17,APOIO!$B:$N,MATCH(T$5,APOIO!$B$5:$N$5,0),FALSE),0) -> 0 | U17: =IFERROR(T17/T$6,0) -> 0 | V17: =IFERROR(VLOOKUP($A17,APOIO!$B:$N,MATCH(V$5,APOIO!$B$5:$N$5,0),FALSE),0) -> 0 | W17: =IFERROR(V17/V$6,0) -> 0 | X17: =SUM(R17,T17,V17) -> 0 | Y17: =IFERROR(X17/X$6,0) -> 0 | Z17: =IFERROR(VLOOKUP($A17,APOIO!$B:$N,MATCH(Z$5,APOIO!$B$5:$N$5,0),FALSE),0) -> 0 | AA17: =IFERROR(Z17/Z$6,0) -> 0 | AB17: =IFERROR(VLOOKUP($A17,APOIO!$B:$N,MATCH(AB$5,APOIO!$B$5:$N$5,0),FALSE),0) -> 0 | AC17: =IFERROR(AB17/AB$6,0) -> 0 | AD17: =IFERROR(VLOOKUP($A17,APOIO!$B:$N,MATCH(AD$5,APOIO!$B$5:$N$5,0),FALSE),0) -> 0 | AE17: =IFERROR(AD17/AD$6,0) -> 0 | AF17: =SUM(Z17,AB17,AD17) -> 0 | AG17: =IFERROR(AF17/AF$6,0) -> 0 | AH17: =SUM(B17,D17,F17,J17,L17,N17,R17,T17,V17,Z17,AB17,AD17) -> -3487.91 | AI17: =IFERROR(AH17/AH$6,0) -> -0.0058770072
A18: COFINS | B18: =IFERROR(VLOOKUP($A18,APOIO!$B:$N,MATCH(B$5,APOIO!$B$5:$N$5,0),FALSE),0) -> -3952.08 | C18: =IFERROR(B18/B$6,0) -> -0.022823754 | D18: =IFERROR(VLOOKUP($A18,APOIO!$B:$N,MATCH(D$5,APOIO!$B$5:$N$5,0),FALSE),0) -> -12145.89 | E18: =IFERROR(D18/D$6,0) -> -0.028896247 | F18: =IFERROR(VLOOKUP($A18,APOIO!$B:$N,MATCH(F$5,APOIO!$B$5:$N$5,0),FALSE),0) -> 0 | G18: =IFERROR(F18/F$6,0) -> 0 | H18: =SUM(B18,D18,F18) -> -16097.97 | I18: =IFERROR(H18/H$6,0) -> -0.02712452 | J18: =IFERROR(VLOOKUP($A18,APOIO!$B:$N,MATCH(J$5,APOIO!$B$5:$N$5,0),FALSE),0) -> 0 | K18: =IFERROR(J18/J$6,0) -> 0 | L18: =IFERROR(VLOOKUP($A18,APOIO!$B:$N,MATCH(L$5,APOIO!$B$5:$N$5,0),FALSE),0) -> 0 | M18: =IFERROR(L18/L$6,0) -> 0 | N18: =IFERROR(VLOOKUP($A18,APOIO!$B:$N,MATCH(N$5,APOIO!$B$5:$N$5,0),FALSE),0) -> 0 | O18: =IFERROR(N18/N$6,0) -> 0 | P18: =SUM(J18,L18,N18) -> 0 | Q18: =IFERROR(P18/P$6,0) -> 0 | R18: =IFERROR(VLOOKUP($A18,APOIO!$B:$N,MATCH(R$5,APOIO!$B$5:$N$5,0),FALSE),0) -> 0 | S18: =IFERROR(R18/R$6,0) -> 0 | T18: =IFERROR(VLOOKUP($A18,APOIO!$B:$N,MATCH(T$5,APOIO!$B$5:$N$5,0),FALSE),0) -> 0 | U18: =IFERROR(T18/T$6,0) -> 0 | V18: =IFERROR(VLOOKUP($A18,APOIO!$B:$N,MATCH(V$5,APOIO!$B$5:$N$5,0),FALSE),0) -> 0 | W18: =IFERROR(V18/V$6,0) -> 0 | X18: =SUM(R18,T18,V18) -> 0 | Y18: =IFERROR(X18/X$6,0) -> 0 | Z18: =IFERROR(VLOOKUP($A18,APOIO!$B:$N,MATCH(Z$5,APOIO!$B$5:$N$5,0),FALSE),0) -> 0 | AA18: =IFERROR(Z18/Z$6,0) -> 0 | AB18: =IFERROR(VLOOKUP($A18,APOIO!$B:$N,MATCH(AB$5,APOIO!$B$5:$N$5,0),FALSE),0) -> 0 | AC18: =IFERROR(AB18/AB$6,0) -> 0 | AD18: =IFERROR(VLOOKUP($A18,APOIO!$B:$N,MATCH(AD$5,APOIO!$B$5:$N$5,0),FALSE),0) -> 0 | AE18: =IFERROR(AD18/AD$6,0) -> 0 | AF18: =SUM(Z18,AB18,AD18) -> 0 | AG18: =IFERROR(AF18/AF$6,0) -> 0 | AH18: =SUM(B18,D18,F18,J18,L18,N18,R18,T18,V18,Z18,AB18,AD18) -> -16097.97 | AI18: =IFERROR(AH18/AH$6,0) -> -0.02712452
A19: (=)Receita Líquida | B19: =SUM(B8,B6) -> 155174.46 | C19: =IFERROR(B19/B$6,0) -> 0.89615183 | D19: =SUM(D8,D6) -> 365063.77 | E19: =IFERROR(D19/D$6,0) -> 0.86852201 | F19: =SUM(F8,F6) -> 0 | G19: =IFERROR(F19/F$6,0) -> 0 | H19: =SUM(B19,D19,F19) -> 520238.23 | I19: =IFERROR(H19/H$6,0) -> 0.87658335 | J19: =SUM(J8,J6) -> 0 | K19: =IFERROR(J19/J$6,0) -> 0 | L19: =SUM(L8,L6) -> 0 | M19: =IFERROR(L19/L$6,0) -> 0 | N19: =SUM(N8,N6) -> 0 | O19: =IFERROR(N19/N$6,0) -> 0 | P19: =SUM(J19,L19,N19) -> 0 | Q19: =IFERROR(P19/P$6,0) -> 0 | R19: =SUM(R8,R6) -> 0 | S19: =IFERROR(R19/R$6,0) -> 0 | T19: =SUM(T8,T6) -> 0 | U19: =IFERROR(T19/T$6,0) -> 0 | V19: =SUM(V8,V6) -> 0 | W19: =IFERROR(V19/V$6,0) -> 0 | X19: =SUM(R19,T19,V19) -> 0 | Y19: =IFERROR(X19/X$6,0) -> 0 | Z19: =SUM(Z8,Z6) -> 0 | AA19: =IFERROR(Z19/Z$6,0) -> 0 | AB19: =SUM(AB8,AB6) -> 0 | AC19: =IFERROR(AB19/AB$6,0) -> 0 | AD19: =SUM(AD8,AD6) -> 0 | AE19: =IFERROR(AD19/AD$6,0) -> 0 | AF19: =SUM(Z19,AB19,AD19) -> 0 | AG19: =IFERROR(AF19/AF$6,0) -> 0 | AH19: =SUM(B19,D19,F19,J19,L19,N19,R19,T19,V19,Z19,AB19,AD19) -> 520238.23 | AI19: =IFERROR(AH19/AH$6,0) -> 0.87658335
A20: (-)Custos Variavéis | B20: =IFERROR(VLOOKUP($A20,APOIO!$B:$N,MATCH(B$5,APOIO!$B$5:$N$5,0),FALSE),0) -> -1314.12 | C20: =IFERROR(B20/B$19,0) -> -0.0084686617 | D20: =IFERROR(VLOOKUP($A20,APOIO!$B:$N,MATCH(D$5,APOIO!$B$5:$N$5,0),FALSE),0) -> -20346.43 | E20: =IFERROR(D20/D$19,0) -> -0.055733906 | F20: =IFERROR(VLOOKUP($A20,APOIO!$B:$N,MATCH(F$5,APOIO!$B$5:$N$5,0),FALSE),0) -> -1333.2045 | G20: =IFERROR(F20/F$19,0) -> 0 | H20: =SUM(B20,D20,F20) -> -22993.755 | I20: =IFERROR(H20/H$19,0) -> -0.04419851 | J20: =IFERROR(VLOOKUP($A20,APOIO!$B:$N,MATCH(J$5,APOIO!$B$5:$N$5,0),FALSE),0) -> 0 | K20: =IFERROR(J20/J$19,0) -> 0 | L20: =IFERROR(VLOOKUP($A20,APOIO!$B:$N,MATCH(L$5,APOIO!$B$5:$N$5,0),FALSE),0) -> -312.58 | M20: =IFERROR(L20/L$19,0) -> 0 | N20: =IFERROR(VLOOKUP($A20,APOIO!$B:$N,MATCH(N$5,APOIO!$B$5:$N$5,0),FALSE),0) -> 0 | O20: =IFERROR(N20/N$19,0) -> 0 | P20: =SUM(J20,L20,N20) -> -312.58 | Q20: =IFERROR(P20/P$19,0) -> 0 | R20: =IFERROR(VLOOKUP($A20,APOIO!$B:$N,MATCH(R$5,APOIO!$B$5:$N$5,0),FALSE),0) -> 0 | S20: =IFERROR(R20/R$19,0) -> 0 | T20: =IFERROR(VLOOKUP($A20,APOIO!$B:$N,MATCH(T$5,APOIO!$B$5:$N$5,0),FALSE),0) -> 0 | U20: =IFERROR(T20/T$19,0) -> 0 | V20: =IFERROR(VLOOKUP($A20,APOIO!$B:$N,MATCH(V$5,APOIO!$B$5:$N$5,0),FALSE),0) -> 0 | W20: =IFERROR(V20/V$19,0) -> 0 | X20: =SUM(R20,T20,V20) -> 0 | Y20: =IFERROR(X20/X$19,0) -> 0 | Z20: =IFERROR(VLOOKUP($A20,APOIO!$B:$N,MATCH(Z$5,APOIO!$B$5:$N$5,0),FALSE),0) -> 0 | AA20: =IFERROR(Z20/Z$19,0) -> 0 | AB20: =IFERROR(VLOOKUP($A20,APOIO!$B:$N,MATCH(AB$5,APOIO!$B$5:$N$5,0),FALSE),0) -> 0 | AC20: =IFERROR(AB20/AB$19,0) -> 0 | AD20: =IFERROR(VLOOKUP($A20,APOIO!$B:$N,MATCH(AD$5,APOIO!$B$5:$N$5,0),FALSE),0) -> 0 | AE20: =IFERROR(AD20/AD$19,0) -> 0 | AF20: =SUM(Z20,AB20,AD20) -> 0 | AG20: =IFERROR(AF20/AF$19,0) -> 0 | AH20: =SUM(B20,D20,F20,J20,L20,N20,R20,T20,V20,Z20,AB20,AD20) -> -23306.335 | AI20: =IFERROR(AH20/AH$19,0) -> -0.04479935
A21: Fornecedores | B21: =IFERROR(VLOOKUP($A21,APOIO!$B:$N,MATCH(B$5,APOIO!$B$5:$N$5,0),FALSE),0) -> -1314.12 | C21: =IFERROR(B21/B$19,0) -> -0.0084686617 | D21: =IFERROR(VLOOKUP($A21,APOIO!$B:$N,MATCH(D$5,APOIO!$B$5:$N$5,0),FALSE),0) -> -20346.43 | E21: =IFERROR(D21/D$19,0) -> -0.055733906 | F21: =IFERROR(VLOOKUP($A21,APOIO!$B:$N,MATCH(F$5,APOIO!$B$5:$N$5,0),FALSE),0) -> -1333.2045 | G21: =IFERROR(F21/F$19,0) -> 0 | H21: =SUM(B21,D21,F21) -> -22993.755 | I21: =IFERROR(H21/H$19,0) -> -0.04419851 | J21: =IFERROR(VLOOKUP($A21,APOIO!$B:$N,MATCH(J$5,APOIO!$B$5:$N$5,0),FALSE),0) -> 0 | K21: =IFERROR(J21/J$19,0) -> 0 | L21: =IFERROR(VLOOKUP($A21,APOIO!$B:$N,MATCH(L$5,APOIO!$B$5:$N$5,0),FALSE),0) -> -312.58 | M21: =IFERROR(L21/L$19,0) -> 0 | N21: =IFERROR(VLOOKUP($A21,APOIO!$B:$N,MATCH(N$5,APOIO!$B$5:$N$5,0),FALSE),0) -> 0 | O21: =IFERROR(N21/N$19,0) -> 0 | P21: =SUM(J21,L21,N21) -> -312.58 | Q21: =IFERROR(P21/P$19,0) -> 0 | R21: =IFERROR(VLOOKUP($A21,APOIO!$B:$N,MATCH(R$5,APOIO!$B$5:$N$5,0),FALSE),0) -> 0 | S21: =IFERROR(R21/R$19,0) -> 0 | T21: =IFERROR(VLOOKUP($A21,APOIO!$B:$N,MATCH(T$5,APOIO!$B$5:$N$5,0),FALSE),0) -> 0 | U21: =IFERROR(T21/T$19,0) -> 0 | V21: =IFERROR(VLOOKUP($A21,APOIO!$B:$N,MATCH(V$5,APOIO!$B$5:$N$5,0),FALSE),0) -> 0 | W21: =IFERROR(V21/V$19,0) -> 0 | X21: =SUM(R21,T21,V21) -> 0 | Y21: =IFERROR(X21/X$19,0) -> 0 | Z21: =IFERROR(VLOOKUP($A21,APOIO!$B:$N,MATCH(Z$5,APOIO!$B$5:$N$5,0),FALSE),0) -> 0 | AA21: =IFERROR(Z21/Z$19,0) -> 0 | AB21: =IFERROR(VLOOKUP($A21,APOIO!$B:$N,MATCH(AB$5,APOIO!$B$5:$N$5,0),FALSE),0) -> 0 | AC21: =IFERROR(AB21/AB$19,0) -> 0 | AD21: =IFERROR(VLOOKUP($A21,APOIO!$B:$N,MATCH(AD$5,APOIO!$B$5:$N$5,0),FALSE),0) -> 0 | AE21: =IFERROR(AD21/AD$19,0) -> 0 | AF21: =SUM(Z21,AB21,AD21) -> 0 | AG21: =IFERROR(AF21/AF$19,0) -> 0 | AH21: =SUM(B21,D21,F21,J21,L21,N21,R21,T21,V21,Z21,AB21,AD21) -> -23306.335 | AI21: =IFERROR(AH21/AH$19,0) -> -0.04479935
A22: FRETE MATERIAIS E EQUIPAMENTOS | B22: =IFERROR(VLOOKUP($A22,APOIO!$B:$N,MATCH(B$5,APOIO!$B$5:$N$5,0),FALSE),0) -> 0 | C22: =IFERROR(B22/B$19,0) -> 0 | D22: =IFERROR(VLOOKUP($A22,APOIO!$B:$N,MATCH(D$5,APOIO!$B$5:$N$5,0),FALSE),0) -> -2345.47 | E22: =IFERROR(D22/D$19,0) -> -0.0064248227 | F22: =IFERROR(VLOOKUP($A22,APOIO!$B:$N,MATCH(F$5,APOIO!$B$5:$N$5,0),FALSE),0) -> 0 | G22: =IFERROR(F22/F$19,0) -> 0 | H22: =SUM(B22,D22,F22) -> -2345.47 | I22: =IFERROR(H22/H$19,0) -> -0.0045084538 | J22: =IFERROR(VLOOKUP($A22,APOIO!$B:$N,MATCH(J$5,APOIO!$B$5:$N$5,0),FALSE),0) -> 0 | K22: =IFERROR(J22/J$19,0) -> 0 | L22: =IFERROR(VLOOKUP($A22,APOIO!$B:$N,MATCH(L$5,APOIO!$B$5:$N$5,0),FALSE),0) -> 0 | M22: =IFERROR(L22/L$19,0) -> 0 | N22: =IFERROR(VLOOKUP($A22,APOIO!$B:$N,MATCH(N$5,APOIO!$B$5:$N$5,0),FALSE),0) -> 0 | O22: =IFERROR(N22/N$19,0) -> 0 | P22: =SUM(J22,L22,N22) -> 0 | Q22: =IFERROR(P22/P$19,0) -> 0 | R22: =IFERROR(VLOOKUP($A22,APOIO!$B:$N,MATCH(R$5,APOIO!$B$5:$N$5,0),FALSE),0) -> 0 | S22: =IFERROR(R22/R$19,0) -> 0 | T22: =IFERROR(VLOOKUP($A22,APOIO!$B:$N,MATCH(T$5,APOIO!$B$5:$N$5,0),FALSE),0) -> 0 | U22: =IFERROR(T22/T$19,0) -> 0 | V22: =IFERROR(VLOOKUP($A22,APOIO!$B:$N,MATCH(V$5,APOIO!$B$5:$N$5,0),FALSE),0) -> 0 | W22: =IFERROR(V22/V$19,0) -> 0 | X22: =SUM(R22,T22,V22) -> 0 | Y22: =IFERROR(X22/X$19,0) -> 0 | Z22: =IFERROR(VLOOKUP($A22,APOIO!$B:$N,MATCH(Z$5,APOIO!$B$5:$N$5,0),FALSE),0) -> 0 | AA22: =IFERROR(Z22/Z$19,0) -> 0 | AB22: =IFERROR(VLOOKUP($A22,APOIO!$B:$N,MATCH(AB$5,APOIO!$B$5:$N$5,0),FALSE),0) -> 0 | AC22: =IFERROR(AB22/AB$19,0) -> 0 | AD22: =IFERROR(VLOOKUP($A22,APOIO!$B:$N,MATCH(AD$5,APOIO!$B$5:$N$5,0),FALSE),0) -> 0 | AE22: =IFERROR(AD22/AD$19,0) -> 0 | AF22: =SUM(Z22,AB22,AD22) -> 0 | AG22: =IFERROR(AF22/AF$19,0) -> 0 | AH22: =SUM(B22,D22,F22,J22,L22,N22,R22,T22,V22,Z22,AB22,AD22) -> -2345.47 | AI22: =IFERROR(AH22/AH$19,0) -> -0.0045084538
A23: FRETE ABRASIVOS | B23: =IFERROR(VLOOKUP($A23,APOIO!$B:$N,MATCH(B$5,APOIO!$B$5:$N$5,0),FALSE),0) -> 0 | C23: =IFERROR(B23/B$19,0) -> 0 | D23: =IFERROR(VLOOKUP($A23,APOIO!$B:$N,MATCH(D$5,APOIO!$B$5:$N$5,0),FALSE),0) -> 0 | E23: =IFERROR(D23/D$19,0) -> 0 | F23: =IFERROR(VLOOKUP($A23,APOIO!$B:$N,MATCH(F$5,APOIO!$B$5:$N$5,0),FALSE),0) -> 0 | G23: =IFERROR(F23/F$19,0) -> 0 | H23: =SUM(B23,D23,F23) -> 0 | I23: =IFERROR(H23/H$19,0) -> 0 | J23: =IFERROR(VLOOKUP($A23,APOIO!$B:$N,MATCH(J$5,APOIO!$B$5:$N$5,0),FALSE),0) -> 0 | K23: =IFERROR(J23/J$19,0) -> 0 | L23: =IFERROR(VLOOKUP($A23,APOIO!$B:$N,MATCH(L$5,APOIO!$B$5:$N$5,0),FALSE),0) -> 0 | M23: =IFERROR(L23/L$19,0) -> 0 | N23: =IFERROR(VLOOKUP($A23,APOIO!$B:$N,MATCH(N$5,APOIO!$B$5:$N$5,0),FALSE),0) -> 0 | O23: =IFERROR(N23/N$19,0) -> 0 | P23: =SUM(J23,L23,N23) -> 0 | Q23: =IFERROR(P23/P$19,0) -> 0 | R23: =IFERROR(VLOOKUP($A23,APOIO!$B:$N,MATCH(R$5,APOIO!$B$5:$N$5,0),FALSE),0) -> 0 | S23: =IFERROR(R23/R$19,0) -> 0 | T23: =IFERROR(VLOOKUP($A23,APOIO!$B:$N,MATCH(T$5,APOIO!$B$5:$N$5,0),FALSE),0) -> 0 | U23: =IFERROR(T23/T$19,0) -> 0 | V23: =IFERROR(VLOOKUP($A23,APOIO!$B:$N,MATCH(V$5,APOIO!$B$5:$N$5,0),FALSE),0) -> 0 | W23: =IFERROR(V23/V$19,0) -> 0 | X23: =SUM(R23,T23,V23) -> 0 | Y23: =IFERROR(X23/X$19,0) -> 0 | Z23: =IFERROR(VLOOKUP($A23,APOIO!$B:$N,MATCH(Z$5,APOIO!$B$5:$N$5,0),FALSE),0) -> 0 | AA23: =IFERROR(Z23/Z$19,0) -> 0 | AB23: =IFERROR(VLOOKUP($A23,APOIO!$B:$N,MATCH(AB$5,APOIO!$B$5:$N$5,0),FALSE),0) -> 0 | AC23: =IFERROR(AB23/AB$19,0) -> 0 | AD23: =IFERROR(VLOOKUP($A23,APOIO!$B:$N,MATCH(AD$5,APOIO!$B$5:$N$5,0),FALSE),0) -> 0 | AE23: =IFERROR(AD23/AD$19,0) -> 0 | AF23: =SUM(Z23,AB23,AD23) -> 0 | AG23: =IFERROR(AF23/AF$19,0) -> 0 | AH23: =SUM(B23,D23,F23,J23,L23,N23,R23,T23,V23,Z23,AB23,AD23) -> 0 | AI23: =IFERROR(AH23/AH$19,0) -> 0
A24: FRETE TINTAS E SOLVENTE | B24: =IFERROR(VLOOKUP($A24,APOIO!$B:$N,MATCH(B$5,APOIO!$B$5:$N$5,0),FALSE),0) -> 0 | C24: =IFERROR(B24/B$19,0) -> 0 | D24: =IFERROR(VLOOKUP($A24,APOIO!$B:$N,MATCH(D$5,APOIO!$B$5:$N$5,0),FALSE),0) -> -953 | E24: =IFERROR(D24/D$19,0) -> -0.0026105028 | F24: =IFERROR(VLOOKUP($A24,APOIO!$B:$N,MATCH(F$5,APOIO!$B$5:$N$5,0),FALSE),0) -> 0 | G24: =IFERROR(F24/F$19,0) -> 0 | H24: =SUM(B24,D24,F24) -> -953 | I24: =IFERROR(H24/H$19,0) -> -0.0018318531 | J24: =IFERROR(VLOOKUP($A24,APOIO!$B:$N,MATCH(J$5,APOIO!$B$5:$N$5,0),FALSE),0) -> 0 | K24: =IFERROR(J24/J$19,0) -> 0 | L24: =IFERROR(VLOOKUP($A24,APOIO!$B:$N,MATCH(L$5,APOIO!$B$5:$N$5,0),FALSE),0) -> 0 | M24: =IFERROR(L24/L$19,0) -> 0 | N24: =IFERROR(VLOOKUP($A24,APOIO!$B:$N,MATCH(N$5,APOIO!$B$5:$N$5,0),FALSE),0) -> 0 | O24: =IFERROR(N24/N$19,0) -> 0 | P24: =SUM(J24,L24,N24) -> 0 | Q24: =IFERROR(P24/P$19,0) -> 0 | R24: =IFERROR(VLOOKUP($A24,APOIO!$B:$N,MATCH(R$5,APOIO!$B$5:$N$5,0),FALSE),0) -> 0 | S24: =IFERROR(R24/R$19,0) -> 0 | T24: =IFERROR(VLOOKUP($A24,APOIO!$B:$N,MATCH(T$5,APOIO!$B$5:$N$5,0),FALSE),0) -> 0 | U24: =IFERROR(T24/T$19,0) -> 0 | V24: =IFERROR(VLOOKUP($A24,APOIO!$B:$N,MATCH(V$5,APOIO!$B$5:$N$5,0),FALSE),0) -> 0 | W24: =IFERROR(V24/V$19,0) -> 0 | X24: =SUM(R24,T24,V24) -> 0 | Y24: =IFERROR(X24/X$19,0) -> 0 | Z24: =IFERROR(VLOOKUP($A24,APOIO!$B:$N,MATCH(Z$5,APOIO!$B$5:$N$5,0),FALSE),0) -> 0 | AA24: =IFERROR(Z24/Z$19,0) -> 0 | AB24: =IFERROR(VLOOKUP($A24,APOIO!$B:$N,MATCH(AB$5,APOIO!$B$5:$N$5,0),FALSE),0) -> 0 | AC24: =IFERROR(AB24/AB$19,0) -> 0 | AD24: =IFERROR(VLOOKUP($A24,APOIO!$B:$N,MATCH(AD$5,APOIO!$B$5:$N$5,0),FALSE),0) -> 0 | AE24: =IFERROR(AD24/AD$19,0) -> 0 | AF24: =SUM(Z24,AB24,AD24) -> 0 | AG24: =IFERROR(AF24/AF$19,0) -> 0 | AH24: =SUM(B24,D24,F24,J24,L24,N24,R24,T24,V24,Z24,AB24,AD24) -> -953 | AI24: =IFERROR(AH24/AH$19,0) -> -0.0018318531
A25: FRETE TRANSPORTADORA | B25: =IFERROR(VLOOKUP($A25,APOIO!$B:$N,MATCH(B$5,APOIO!$B$5:$N$5,0),FALSE),0) -> -1314.12 | C25: =IFERROR(B25/B$19,0) -> -0.0084686617 | D25: =IFERROR(VLOOKUP($A25,APOIO!$B:$N,MATCH(D$5,APOIO!$B$5:$N$5,0),FALSE),0) -> 0 | E25: =IFERROR(D25/D$19,0) -> 0 | F25: =IFERROR(VLOOKUP($A25,APOIO!$B:$N,MATCH(F$5,APOIO!$B$5:$N$5,0),FALSE),0) -> -1333.2045 | G25: =IFERROR(F25/F$19,0) -> 0 | H25: =SUM(B25,D25,F25) -> -2647.3245 | I25: =IFERROR(H25/H$19,0) -> -0.0050886774 | J25: =IFERROR(VLOOKUP($A25,APOIO!$B:$N,MATCH(J$5,APOIO!$B$5:$N$5,0),FALSE),0) -> 0 | K25: =IFERROR(J25/J$19,0) -> 0 | L25: =IFERROR(VLOOKUP($A25,APOIO!$B:$N,MATCH(L$5,APOIO!$B$5:$N$5,0),FALSE),0) -> -312.58 | M25: =IFERROR(L25/L$19,0) -> 0 | N25: =IFERROR(VLOOKUP($A25,APOIO!$B:$N,MATCH(N$5,APOIO!$B$5:$N$5,0),FALSE),0) -> 0 | O25: =IFERROR(N25/N$19,0) -> 0 | P25: =SUM(J25,L25,N25) -> -312.58 | Q25: =IFERROR(P25/P$19,0) -> 0 | R25: =IFERROR(VLOOKUP($A25,APOIO!$B:$N,MATCH(R$5,APOIO!$B$5:$N$5,0),FALSE),0) -> 0 | S25: =IFERROR(R25/R$19,0) -> 0 | T25: =IFERROR(VLOOKUP($A25,APOIO!$B:$N,MATCH(T$5,APOIO!$B$5:$N$5,0),FALSE),0) -> 0 | U25: =IFERROR(T25/T$19,0) -> 0 | V25: =IFERROR(VLOOKUP($A25,APOIO!$B:$N,MATCH(V$5,APOIO!$B$5:$N$5,0),FALSE),0) -> 0 | W25: =IFERROR(V25/V$19,0) -> 0 | X25: =SUM(R25,T25,V25) -> 0 | Y25: =IFERROR(X25/X$19,0) -> 0 | Z25: =IFERROR(VLOOKUP($A25,APOIO!$B:$N,MATCH(Z$5,APOIO!$B$5:$N$5,0),FALSE),0) -> 0 | AA25: =IFERROR(Z25/Z$19,0) -> 0 | AB25: =IFERROR(VLOOKUP($A25,APOIO!$B:$N,MATCH(AB$5,APOIO!$B$5:$N$5,0),FALSE),0) -> 0 | AC25: =IFERROR(AB25/AB$19,0) -> 0 | AD25: =IFERROR(VLOOKUP($A25,APOIO!$B:$N,MATCH(AD$5,APOIO!$B$5:$N$5,0),FALSE),0) -> 0 | AE25: =IFERROR(AD25/AD$19,0) -> 0 | AF25: =SUM(Z25,AB25,AD25) -> 0 | AG25: =IFERROR(AF25/AF$19,0) -> 0 | AH25: =SUM(B25,D25,F25,J25,L25,N25,R25,T25,V25,Z25,AB25,AD25) -> -2959.9045 | AI25: =IFERROR(AH25/AH$19,0) -> -0.0056895176
A26: TINTAS E SOLVENTES | B26: =IFERROR(VLOOKUP($A26,APOIO!$B:$N,MATCH(B$5,APOIO!$B$5:$N$5,0),FALSE),0) -> 0 | C26: =IFERROR(B26/B$19,0) -> 0 | D26: =IFERROR(VLOOKUP($A26,APOIO!$B:$N,MATCH(D$5,APOIO!$B$5:$N$5,0),FALSE),0) -> -17047.96 | E26: =IFERROR(D26/D$19,0) -> -0.046698581 | F26: =IFERROR(VLOOKUP($A26,APOIO!$B:$N,MATCH(F$5,APOIO!$B$5:$N$5,0),FALSE),0) -> 0 | G26: =IFERROR(F26/F$19,0) -> 0 | H26: =SUM(B26,D26,F26) -> -17047.96 | I26: =IFERROR(H26/H$19,0) -> -0.032769526 | J26: =IFERROR(VLOOKUP($A26,APOIO!$B:$N,MATCH(J$5,APOIO!$B$5:$N$5,0),FALSE),0) -> 0 | K26: =IFERROR(J26/J$19,0) -> 0 | L26: =IFERROR(VLOOKUP($A26,APOIO!$B:$N,MATCH(L$5,APOIO!$B$5:$N$5,0),FALSE),0) -> 0 | M26: =IFERROR(L26/L$19,0) -> 0 | N26: =IFERROR(VLOOKUP($A26,APOIO!$B:$N,MATCH(N$5,APOIO!$B$5:$N$5,0),FALSE),0) -> 0 | O26: =IFERROR(N26/N$19,0) -> 0 | P26: =SUM(J26,L26,N26) -> 0 | Q26: =IFERROR(P26/P$19,0) -> 0 | R26: =IFERROR(VLOOKUP($A26,APOIO!$B:$N,MATCH(R$5,APOIO!$B$5:$N$5,0),FALSE),0) -> 0 | S26: =IFERROR(R26/R$19,0) -> 0 | T26: =IFERROR(VLOOKUP($A26,APOIO!$B:$N,MATCH(T$5,APOIO!$B$5:$N$5,0),FALSE),0) -> 0 | U26: =IFERROR(T26/T$19,0) -> 0 | V26: =IFERROR(VLOOKUP($A26,APOIO!$B:$N,MATCH(V$5,APOIO!$B$5:$N$5,0),FALSE),0) -> 0 | W26: =IFERROR(V26/V$19,0) -> 0 | X26: =SUM(R26,T26,V26) -> 0 | Y26: =IFERROR(X26/X$19,0) -> 0 | Z26: =IFERROR(VLOOKUP($A26,APOIO!$B:$N,MATCH(Z$5,APOIO!$B$5:$N$5,0),FALSE),0) -> 0 | AA26: =IFERROR(Z26/Z$19,0) -> 0 | AB26: =IFERROR(VLOOKUP($A26,APOIO!$B:$N,MATCH(AB$5,APOIO!$B$5:$N$5,0),FALSE),0) -> 0 | AC26: =IFERROR(AB26/AB$19,0) -> 0 | AD26: =IFERROR(VLOOKUP($A26,APOIO!$B:$N,MATCH(AD$5,APOIO!$B$5:$N$5,0),FALSE),0) -> 0 | AE26: =IFERROR(AD26/AD$19,0) -> 0 | AF26: =SUM(Z26,AB26,AD26) -> 0 | AG26: =IFERROR(AF26/AF$19,0) -> 0 | AH26: =SUM(B26,D26,F26,J26,L26,N26,R26,T26,V26,Z26,AB26,AD26) -> -17047.96 | AI26: =IFERROR(AH26/AH$19,0) -> -0.032769526
A27: ABRASIVOS | B27: =IFERROR(VLOOKUP($A27,APOIO!$B:$N,MATCH(B$5,APOIO!$B$5:$N$5,0),FALSE),0) -> 0 | C27: =IFERROR(B27/B$19,0) -> 0 | D27: =IFERROR(VLOOKUP($A27,APOIO!$B:$N,MATCH(D$5,APOIO!$B$5:$N$5,0),FALSE),0) -> 0 | E27: =IFERROR(D27/D$19,0) -> 0 | F27: =IFERROR(VLOOKUP($A27,APOIO!$B:$N,MATCH(F$5,APOIO!$B$5:$N$5,0),FALSE),0) -> 0 | G27: =IFERROR(F27/F$19,0) -> 0 | H27: =SUM(B27,D27,F27) -> 0 | I27: =IFERROR(H27/H$19,0) -> 0 | J27: =IFERROR(VLOOKUP($A27,APOIO!$B:$N,MATCH(J$5,APOIO!$B$5:$N$5,0),FALSE),0) -> 0 | K27: =IFERROR(J27/J$19,0) -> 0 | L27: =IFERROR(VLOOKUP($A27,APOIO!$B:$N,MATCH(L$5,APOIO!$B$5:$N$5,0),FALSE),0) -> 0 | M27: =IFERROR(L27/L$19,0) -> 0 | N27: =IFERROR(VLOOKUP($A27,APOIO!$B:$N,MATCH(N$5,APOIO!$B$5:$N$5,0),FALSE),0) -> 0 | O27: =IFERROR(N27/N$19,0) -> 0 | P27: =SUM(J27,L27,N27) -> 0 | Q27: =IFERROR(P27/P$19,0) -> 0 | R27: =IFERROR(VLOOKUP($A27,APOIO!$B:$N,MATCH(R$5,APOIO!$B$5:$N$5,0),FALSE),0) -> 0 | S27: =IFERROR(R27/R$19,0) -> 0 | T27: =IFERROR(VLOOKUP($A27,APOIO!$B:$N,MATCH(T$5,APOIO!$B$5:$N$5,0),FALSE),0) -> 0 | U27: =IFERROR(T27/T$19,0) -> 0 | V27: =IFERROR(VLOOKUP($A27,APOIO!$B:$N,MATCH(V$5,APOIO!$B$5:$N$5,0),FALSE),0) -> 0 | W27: =IFERROR(V27/V$19,0) -> 0 | X27: =SUM(R27,T27,V27) -> 0 | Y27: =IFERROR(X27/X$19,0) -> 0 | Z27: =IFERROR(VLOOKUP($A27,APOIO!$B:$N,MATCH(Z$5,APOIO!$B$5:$N$5,0),FALSE),0) -> 0 | AA27: =IFERROR(Z27/Z$19,0) -> 0 | AB27: =IFERROR(VLOOKUP($A27,APOIO!$B:$N,MATCH(AB$5,APOIO!$B$5:$N$5,0),FALSE),0) -> 0 | AC27: =IFERROR(AB27/AB$19,0) -> 0 | AD27: =IFERROR(VLOOKUP($A27,APOIO!$B:$N,MATCH(AD$5,APOIO!$B$5:$N$5,0),FALSE),0) -> 0 | AE27: =IFERROR(AD27/AD$19,0) -> 0 | AF27: =SUM(Z27,AB27,AD27) -> 0 | AG27: =IFERROR(AF27/AF$19,0) -> 0 | AH27: =SUM(B27,D27,F27,J27,L27,N27,R27,T27,V27,Z27,AB27,AD27) -> 0 | AI27: =IFERROR(AH27/AH$19,0) -> 0
A28: OUTROS MATERIAIS DE APLICAÇÃO | B28: =IFERROR(VLOOKUP($A28,APOIO!$B:$N,MATCH(B$5,APOIO!$B$5:$N$5,0),FALSE),0) -> 0 | C28: =IFERROR(B28/B$19,0) -> 0 | D28: =IFERROR(VLOOKUP($A28,APOIO!$B:$N,MATCH(D$5,APOIO!$B$5:$N$5,0),FALSE),0) -> 0 | E28: =IFERROR(D28/D$19,0) -> 0 | F28: =IFERROR(VLOOKUP($A28,APOIO!$B:$N,MATCH(F$5,APOIO!$B$5:$N$5,0),FALSE),0) -> 0 | G28: =IFERROR(F28/F$19,0) -> 0 | H28: =SUM(B28,D28,F28) -> 0 | I28: =IFERROR(H28/H$19,0) -> 0 | J28: =IFERROR(VLOOKUP($A28,APOIO!$B:$N,MATCH(J$5,APOIO!$B$5:$N$5,0),FALSE),0) -> 0 | K28: =IFERROR(J28/J$19,0) -> 0 | L28: =IFERROR(VLOOKUP($A28,APOIO!$B:$N,MATCH(L$5,APOIO!$B$5:$N$5,0),FALSE),0) -> 0 | M28: =IFERROR(L28/L$19,0) -> 0 | N28: =IFERROR(VLOOKUP($A28,APOIO!$B:$N,MATCH(N$5,APOIO!$B$5:$N$5,0),FALSE),0) -> 0 | O28: =IFERROR(N28/N$19,0) -> 0 | P28: =SUM(J28,L28,N28) -> 0 | Q28: =IFERROR(P28/P$19,0) -> 0 | R28: =IFERROR(VLOOKUP($A28,APOIO!$B:$N,MATCH(R$5,APOIO!$B$5:$N$5,0),FALSE),0) -> 0 | S28: =IFERROR(R28/R$19,0) -> 0 | T28: =IFERROR(VLOOKUP($A28,APOIO!$B:$N,MATCH(T$5,APOIO!$B$5:$N$5,0),FALSE),0) -> 0 | U28: =IFERROR(T28/T$19,0) -> 0 | V28: =IFERROR(VLOOKUP($A28,APOIO!$B:$N,MATCH(V$5,APOIO!$B$5:$N$5,0),FALSE),0) -> 0 | W28: =IFERROR(V28/V$19,0) -> 0 | X28: =SUM(R28,T28,V28) -> 0 | Y28: =IFERROR(X28/X$19,0) -> 0 | Z28: =IFERROR(VLOOKUP($A28,APOIO!$B:$N,MATCH(Z$5,APOIO!$B$5:$N$5,0),FALSE),0) -> 0 | AA28: =IFERROR(Z28/Z$19,0) -> 0 | AB28: =IFERROR(VLOOKUP($A28,APOIO!$B:$N,MATCH(AB$5,APOIO!$B$5:$N$5,0),FALSE),0) -> 0 | AC28: =IFERROR(AB28/AB$19,0) -> 0 | AD28: =IFERROR(VLOOKUP($A28,APOIO!$B:$N,MATCH(AD$5,APOIO!$B$5:$N$5,0),FALSE),0) -> 0 | AE28: =IFERROR(AD28/AD$19,0) -> 0 | AF28: =SUM(Z28,AB28,AD28) -> 0 | AG28: =IFERROR(AF28/AF$19,0) -> 0 | AH28: =SUM(B28,D28,F28,J28,L28,N28,R28,T28,V28,Z28,AB28,AD28) -> 0 | AI28: =IFERROR(AH28/AH$19,0) -> 0
B29: =IFERROR(VLOOKUP($A29,APOIO!$B:$N,MATCH(B$5,APOIO!$B$5:$N$5,0),FALSE),0) -> 0 | C29: =IFERROR(B29/B$19,0) -> 0 | D29: =IFERROR(VLOOKUP($A29,APOIO!$B:$N,MATCH(D$5,APOIO!$B$5:$N$5,0),FALSE),0) -> 0 | E29: =IFERROR(D29/D$19,0) -> 0 | F29: =IFERROR(VLOOKUP($A29,APOIO!$B:$N,MATCH(F$5,APOIO!$B$5:$N$5,0),FALSE),0) -> 0 | G29: =IFERROR(F29/F$19,0) -> 0 | H29: =SUM(B29,D29,F29) -> 0 | I29: =IFERROR(H29/H$19,0) -> 0 | J29: =IFERROR(VLOOKUP($A29,APOIO!$B:$N,MATCH(J$5,APOIO!$B$5:$N$5,0),FALSE),0) -> 0 | K29: =IFERROR(J29/J$19,0) -> 0 | L29: =IFERROR(VLOOKUP($A29,APOIO!$B:$N,MATCH(L$5,APOIO!$B$5:$N$5,0),FALSE),0) -> 0 | M29: =IFERROR(L29/L$19,0) -> 0 | N29: =IFERROR(VLOOKUP($A29,APOIO!$B:$N,MATCH(N$5,APOIO!$B$5:$N$5,0),FALSE),0) -> 0 | O29: =IFERROR(N29/N$19,0) -> 0 | P29: =SUM(J29,L29,N29) -> 0 | Q29: =IFERROR(P29/P$19,0) -> 0 | R29: =IFERROR(VLOOKUP($A29,APOIO!$B:$N,MATCH(R$5,APOIO!$B$5:$N$5,0),FALSE),0) -> 0 | S29: =IFERROR(R29/R$19,0) -> 0 | T29: =IFERROR(VLOOKUP($A29,APOIO!$B:$N,MATCH(T$5,APOIO!$B$5:$N$5,0),FALSE),0) -> 0 | U29: =IFERROR(T29/T$19,0) -> 0 | V29: =IFERROR(VLOOKUP($A29,APOIO!$B:$N,MATCH(V$5,APOIO!$B$5:$N$5,0),FALSE),0) -> 0 | W29: =IFERROR(V29/V$19,0) -> 0 | X29: =SUM(R29,T29,V29) -> 0 | Y29: =IFERROR(X29/X$19,0) -> 0 | Z29: =IFERROR(VLOOKUP($A29,APOIO!$B:$N,MATCH(Z$5,APOIO!$B$5:$N$5,0),FALSE),0) -> 0 | AA29: =IFERROR(Z29/Z$19,0) -> 0 | AB29: =IFERROR(VLOOKUP($A29,APOIO!$B:$N,MATCH(AB$5,APOIO!$B$5:$N$5,0),FALSE),0) -> 0 | AC29: =IFERROR(AB29/AB$19,0) -> 0 | AD29: =IFERROR(VLOOKUP($A29,APOIO!$B:$N,MATCH(AD$5,APOIO!$B$5:$N$5,0),FALSE),0) -> 0 | AE29: =IFERROR(AD29/AD$19,0) -> 0 | AF29: =SUM(Z29,AB29,AD29) -> 0 | AG29: =IFERROR(AF29/AF$19,0) -> 0 | AH29: =SUM(B29,D29,F29,J29,L29,N29,R29,T29,V29,Z29,AB29,AD29) -> 0 | AI29: =IFERROR(AH29/AH$19,0) -> 0
A30: Gastos Comerciais | B30: =IFERROR(VLOOKUP($A30,APOIO!$B:$N,MATCH(B$5,APOIO!$B$5:$N$5,0),FALSE),0) -> 0 | C30: =IFERROR(B30/B$19,0) -> 0 | D30: =IFERROR(VLOOKUP($A30,APOIO!$B:$N,MATCH(D$5,APOIO!$B$5:$N$5,0),FALSE),0) -> 0 | E30: =IFERROR(D30/D$19,0) -> 0 | F30: =IFERROR(VLOOKUP($A30,APOIO!$B:$N,MATCH(F$5,APOIO!$B$5:$N$5,0),FALSE),0) -> 0 | G30: =IFERROR(F30/F$19,0) -> 0 | H30: =SUM(B30,D30,F30) -> 0 | I30: =IFERROR(H30/H$19,0) -> 0 | J30: =IFERROR(VLOOKUP($A30,APOIO!$B:$N,MATCH(J$5,APOIO!$B$5:$N$5,0),FALSE),0) -> 0 | K30: =IFERROR(J30/J$19,0) -> 0 | L30: =IFERROR(VLOOKUP($A30,APOIO!$B:$N,MATCH(L$5,APOIO!$B$5:$N$5,0),FALSE),0) -> 0 | M30: =IFERROR(L30/L$19,0) -> 0 | N30: =IFERROR(VLOOKUP($A30,APOIO!$B:$N,MATCH(N$5,APOIO!$B$5:$N$5,0),FALSE),0) -> 0 | O30: =IFERROR(N30/N$19,0) -> 0 | P30: =SUM(J30,L30,N30) -> 0 | Q30: =IFERROR(P30/P$19,0) -> 0 | R30: =IFERROR(VLOOKUP($A30,APOIO!$B:$N,MATCH(R$5,APOIO!$B$5:$N$5,0),FALSE),0) -> 0 | S30: =IFERROR(R30/R$19,0) -> 0 | T30: =IFERROR(VLOOKUP($A30,APOIO!$B:$N,MATCH(T$5,APOIO!$B$5:$N$5,0),FALSE),0) -> 0 | U30: =IFERROR(T30/T$19,0) -> 0 | V30: =IFERROR(VLOOKUP($A30,APOIO!$B:$N,MATCH(V$5,APOIO!$B$5:$N$5,0),FALSE),0) -> 0 | W30: =IFERROR(V30/V$19,0) -> 0 | X30: =SUM(R30,T30,V30) -> 0 | Y30: =IFERROR(X30/X$19,0) -> 0 | Z30: =IFERROR(VLOOKUP($A30,APOIO!$B:$N,MATCH(Z$5,APOIO!$B$5:$N$5,0),FALSE),0) -> 0 | AA30: =IFERROR(Z30/Z$19,0) -> 0 | AB30: =IFERROR(VLOOKUP($A30,APOIO!$B:$N,MATCH(AB$5,APOIO!$B$5:$N$5,0),FALSE),0) -> 0 | AC30: =IFERROR(AB30/AB$19,0) -> 0 | AD30: =IFERROR(VLOOKUP($A30,APOIO!$B:$N,MATCH(AD$5,APOIO!$B$5:$N$5,0),FALSE),0) -> 0 | AE30: =IFERROR(AD30/AD$19,0) -> 0 | AF30: =SUM(Z30,AB30,AD30) -> 0 | AG30: =IFERROR(AF30/AF$19,0) -> 0 | AH30: =SUM(B30,D30,F30,J30,L30,N30,R30,T30,V30,Z30,AB30,AD30) -> 0 | AI30: =IFERROR(AH30/AH$19,0) -> 0
A31: COMISSÃO | B31: =IFERROR(VLOOKUP($A31,APOIO!$B:$N,MATCH(B$5,APOIO!$B$5:$N$5,0),FALSE),0) -> 0 | C31: =IFERROR(B31/B$19,0) -> 0 | D31: =IFERROR(VLOOKUP($A31,APOIO!$B:$N,MATCH(D$5,APOIO!$B$5:$N$5,0),FALSE),0) -> 0 | E31: =IFERROR(D31/D$19,0) -> 0 | F31: =IFERROR(VLOOKUP($A31,APOIO!$B:$N,MATCH(F$5,APOIO!$B$5:$N$5,0),FALSE),0) -> 0 | G31: =IFERROR(F31/F$19,0) -> 0 | H31: =SUM(B31,D31,F31) -> 0 | I31: =IFERROR(H31/H$19,0) -> 0 | J31: =IFERROR(VLOOKUP($A31,APOIO!$B:$N,MATCH(J$5,APOIO!$B$5:$N$5,0),FALSE),0) -> 0 | K31: =IFERROR(J31/J$19,0) -> 0 | L31: =IFERROR(VLOOKUP($A31,APOIO!$B:$N,MATCH(L$5,APOIO!$B$5:$N$5,0),FALSE),0) -> 0 | M31: =IFERROR(L31/L$19,0) -> 0 | N31: =IFERROR(VLOOKUP($A31,APOIO!$B:$N,MATCH(N$5,APOIO!$B$5:$N$5,0),FALSE),0) -> 0 | O31: =IFERROR(N31/N$19,0) -> 0 | P31: =SUM(J31,L31,N31) -> 0 | Q31: =IFERROR(P31/P$19,0) -> 0 | R31: =IFERROR(VLOOKUP($A31,APOIO!$B:$N,MATCH(R$5,APOIO!$B$5:$N$5,0),FALSE),0) -> 0 | S31: =IFERROR(R31/R$19,0) -> 0 | T31: =IFERROR(VLOOKUP($A31,APOIO!$B:$N,MATCH(T$5,APOIO!$B$5:$N$5,0),FALSE),0) -> 0 | U31: =IFERROR(T31/T$19,0) -> 0 | V31: =IFERROR(VLOOKUP($A31,APOIO!$B:$N,MATCH(V$5,APOIO!$B$5:$N$5,0),FALSE),0) -> 0 | W31: =IFERROR(V31/V$19,0) -> 0 | X31: =SUM(R31,T31,V31) -> 0 | Y31: =IFERROR(X31/X$19,0) -> 0 | Z31: =IFERROR(VLOOKUP($A31,APOIO!$B:$N,MATCH(Z$5,APOIO!$B$5:$N$5,0),FALSE),0) -> 0 | AA31: =IFERROR(Z31/Z$19,0) -> 0 | AB31: =IFERROR(VLOOKUP($A31,APOIO!$B:$N,MATCH(AB$5,APOIO!$B$5:$N$5,0),FALSE),0) -> 0 | AC31: =IFERROR(AB31/AB$19,0) -> 0 | AD31: =IFERROR(VLOOKUP($A31,APOIO!$B:$N,MATCH(AD$5,APOIO!$B$5:$N$5,0),FALSE),0) -> 0 | AE31: =IFERROR(AD31/AD$19,0) -> 0 | AF31: =SUM(Z31,AB31,AD31) -> 0 | AG31: =IFERROR(AF31/AF$19,0) -> 0 | AH31: =SUM(B31,D31,F31,J31,L31,N31,R31,T31,V31,Z31,AB31,AD31) -> 0 | AI31: =IFERROR(AH31/AH$19,0) -> 0
B32: =IFERROR(VLOOKUP($A32,APOIO!$B:$N,MATCH(B$5,APOIO!$B$5:$N$5,0),FALSE),0) -> 0 | C32: =IFERROR(B32/B$19,0) -> 0 | D32: =IFERROR(VLOOKUP($A32,APOIO!$B:$N,MATCH(D$5,APOIO!$B$5:$N$5,0),FALSE),0) -> 0 | E32: =IFERROR(D32/D$19,0) -> 0 | F32: =IFERROR(VLOOKUP($A32,APOIO!$B:$N,MATCH(F$5,APOIO!$B$5:$N$5,0),FALSE),0) -> 0 | G32: =IFERROR(F32/F$19,0) -> 0 | H32: =SUM(B32,D32,F32) -> 0 | I32: =IFERROR(H32/H$19,0) -> 0 | J32: =IFERROR(VLOOKUP($A32,APOIO!$B:$N,MATCH(J$5,APOIO!$B$5:$N$5,0),FALSE),0) -> 0 | K32: =IFERROR(J32/J$19,0) -> 0 | L32: =IFERROR(VLOOKUP($A32,APOIO!$B:$N,MATCH(L$5,APOIO!$B$5:$N$5,0),FALSE),0) -> 0 | M32: =IFERROR(L32/L$19,0) -> 0 | N32: =IFERROR(VLOOKUP($A32,APOIO!$B:$N,MATCH(N$5,APOIO!$B$5:$N$5,0),FALSE),0) -> 0 | O32: =IFERROR(N32/N$19,0) -> 0 | P32: =SUM(J32,L32,N32) -> 0 | Q32: =IFERROR(P32/P$19,0) -> 0 | R32: =IFERROR(VLOOKUP($A32,APOIO!$B:$N,MATCH(R$5,APOIO!$B$5:$N$5,0),FALSE),0) -> 0 | S32: =IFERROR(R32/R$19,0) -> 0 | T32: =IFERROR(VLOOKUP($A32,APOIO!$B:$N,MATCH(T$5,APOIO!$B$5:$N$5,0),FALSE),0) -> 0 | U32: =IFERROR(T32/T$19,0) -> 0 | V32: =IFERROR(VLOOKUP($A32,APOIO!$B:$N,MATCH(V$5,APOIO!$B$5:$N$5,0),FALSE),0) -> 0 | W32: =IFERROR(V32/V$19,0) -> 0 | X32: =SUM(R32,T32,V32) -> 0 | Y32: =IFERROR(X32/X$19,0) -> 0 | Z32: =IFERROR(VLOOKUP($A32,APOIO!$B:$N,MATCH(Z$5,APOIO!$B$5:$N$5,0),FALSE),0) -> 0 | AA32: =IFERROR(Z32/Z$19,0) -> 0 | AB32: =IFERROR(VLOOKUP($A32,APOIO!$B:$N,MATCH(AB$5,APOIO!$B$5:$N$5,0),FALSE),0) -> 0 | AC32: =IFERROR(AB32/AB$19,0) -> 0 | AD32: =IFERROR(VLOOKUP($A32,APOIO!$B:$N,MATCH(AD$5,APOIO!$B$5:$N$5,0),FALSE),0) -> 0 | AE32: =IFERROR(AD32/AD$19,0) -> 0 | AF32: =SUM(Z32,AB32,AD32) -> 0 | AG32: =IFERROR(AF32/AF$19,0) -> 0 | AH32: =SUM(B32,D32,F32,J32,L32,N32,R32,T32,V32,Z32,AB32,AD32) -> 0 | AI32: =IFERROR(AH32/AH$19,0) -> 0
B33: =IFERROR(VLOOKUP($A33,APOIO!$B:$N,MATCH(B$5,APOIO!$B$5:$N$5,0),FALSE),0) -> 0 | C33: =IFERROR(B33/B$19,0) -> 0 | D33: =IFERROR(VLOOKUP($A33,APOIO!$B:$N,MATCH(D$5,APOIO!$B$5:$N$5,0),FALSE),0) -> 0 | E33: =IFERROR(D33/D$19,0) -> 0 | F33: =IFERROR(VLOOKUP($A33,APOIO!$B:$N,MATCH(F$5,APOIO!$B$5:$N$5,0),FALSE),0) -> 0 | G33: =IFERROR(F33/F$19,0) -> 0 | H33: =SUM(B33,D33,F33) -> 0 | I33: =IFERROR(H33/H$19,0) -> 0 | J33: =IFERROR(VLOOKUP($A33,APOIO!$B:$N,MATCH(J$5,APOIO!$B$5:$N$5,0),FALSE),0) -> 0 | K33: =IFERROR(J33/J$19,0) -> 0 | L33: =IFERROR(VLOOKUP($A33,APOIO!$B:$N,MATCH(L$5,APOIO!$B$5:$N$5,0),FALSE),0) -> 0 | M33: =IFERROR(L33/L$19,0) -> 0 | N33: =IFERROR(VLOOKUP($A33,APOIO!$B:$N,MATCH(N$5,APOIO!$B$5:$N$5,0),FALSE),0) -> 0 | O33: =IFERROR(N33/N$19,0) -> 0 | P33: =SUM(J33,L33,N33) -> 0 | Q33: =IFERROR(P33/P$19,0) -> 0 | R33: =IFERROR(VLOOKUP($A33,APOIO!$B:$N,MATCH(R$5,APOIO!$B$5:$N$5,0),FALSE),0) -> 0 | S33: =IFERROR(R33/R$19,0) -> 0 | T33: =IFERROR(VLOOKUP($A33,APOIO!$B:$N,MATCH(T$5,APOIO!$B$5:$N$5,0),FALSE),0) -> 0 | U33: =IFERROR(T33/T$19,0) -> 0 | V33: =IFERROR(VLOOKUP($A33,APOIO!$B:$N,MATCH(V$5,APOIO!$B$5:$N$5,0),FALSE),0) -> 0 | W33: =IFERROR(V33/V$19,0) -> 0 | X33: =SUM(R33,T33,V33) -> 0 | Y33: =IFERROR(X33/X$19,0) -> 0 | Z33: =IFERROR(VLOOKUP($A33,APOIO!$B:$N,MATCH(Z$5,APOIO!$B$5:$N$5,0),FALSE),0) -> 0 | AA33: =IFERROR(Z33/Z$19,0) -> 0 | AB33: =IFERROR(VLOOKUP($A33,APOIO!$B:$N,MATCH(AB$5,APOIO!$B$5:$N$5,0),FALSE),0) -> 0 | AC33: =IFERROR(AB33/AB$19,0) -> 0 | AD33: =IFERROR(VLOOKUP($A33,APOIO!$B:$N,MATCH(AD$5,APOIO!$B$5:$N$5,0),FALSE),0) -> 0 | AE33: =IFERROR(AD33/AD$19,0) -> 0 | AF33: =SUM(Z33,AB33,AD33) -> 0 | AG33: =IFERROR(AF33/AF$19,0) -> 0 | AH33: =SUM(B33,D33,F33,J33,L33,N33,R33,T33,V33,Z33,AB33,AD33) -> 0 | AI33: =IFERROR(AH33/AH$19,0) -> 0
A34: (=)Margem de Contribuição | B34: =SUM(B19:B20) -> 153860.34 | C34: =IFERROR(B34/B$19,0) -> 0.99153134 | D34: =SUM(D19:D20) -> 344717.34 | E34: =IFERROR(D34/D$19,0) -> 0.94426609 | F34: =SUM(F19:F20) -> -1333.2045 | G34: =IFERROR(F34/F$19,0) -> 0 | H34: =SUM(B34,D34,F34) -> 497244.48 | I34: =IFERROR(H34/H$19,0) -> 0.95580149 | J34: =SUM(J19:J20) -> 0 | K34: =IFERROR(J34/J$19,0) -> 0 | L34: =SUM(L19:L20) -> -312.58 | M34: =IFERROR(L34/L$19,0) -> 0 | N34: =SUM(N19:N20) -> 0 | O34: =IFERROR(N34/N$19,0) -> 0 | P34: =SUM(J34,L34,N34) -> -312.58 | Q34: =IFERROR(P34/P$19,0) -> 0 | R34: =SUM(R19:R20) -> 0 | S34: =IFERROR(R34/R$19,0) -> 0 | T34: =SUM(T19:T20) -> 0 | U34: =IFERROR(T34/T$19,0) -> 0 | V34: =SUM(V19:V20) -> 0 | W34: =IFERROR(V34/V$19,0) -> 0 | X34: =SUM(R34,T34,V34) -> 0 | Y34: =IFERROR(X34/X$19,0) -> 0 | Z34: =SUM(Z19:Z20) -> 0 | AA34: =IFERROR(Z34/Z$19,0) -> 0 | AB34: =SUM(AB19:AB20) -> 0 | AC34: =IFERROR(AB34/AB$19,0) -> 0 | AD34: =SUM(AD19:AD20) -> 0 | AE34: =IFERROR(AD34/AD$19,0) -> 0 | AF34: =SUM(Z34,AB34,AD34) -> 0 | AG34: =IFERROR(AF34/AF$19,0) -> 0 | AH34: =SUM(B34,D34,F34,J34,L34,N34,R34,T34,V34,Z34,AB34,AD34) -> 496931.9 | AI34: =IFERROR(AH34/AH$19,0) -> 0.95520065
A35: (-)Gastos Fixos | B35: =IFERROR(VLOOKUP($A35,APOIO!$B:$N,MATCH(B$5,APOIO!$B$5:$N$5,0),FALSE),0) -> -264326.31 | C35: =IFERROR(B35/B$19,0) -> -1.7034138 | D35: =IFERROR(VLOOKUP($A35,APOIO!$B:$N,MATCH(D$5,APOIO!$B$5:$N$5,0),FALSE),0) -> -192424.63 | E35: =IFERROR(D35/D$19,0) -> -0.52709867 | F35: =IFERROR(VLOOKUP($A35,APOIO!$B:$N,MATCH(F$5,APOIO!$B$5:$N$5,0),FALSE),0) -> -85532.052 | G35: =IFERROR(F35/F$19,0) -> 0 | H35: =SUM(B35,D35,F35) -> -542282.99 | I35: =IFERROR(H35/H$19,0) -> -1.0423744 | J35: =IFERROR(VLOOKUP($A35,APOIO!$B:$N,MATCH(J$5,APOIO!$B$5:$N$5,0),FALSE),0) -> -65470.009 | K35: =IFERROR(J35/J$19,0) -> 0 | L35: =IFERROR(VLOOKUP($A35,APOIO!$B:$N,MATCH(L$5,APOIO!$B$5:$N$5,0),FALSE),0) -> -74641.516 | M35: =IFERROR(L35/L$19,0) -> 0 | N35: =IFERROR(VLOOKUP($A35,APOIO!$B:$N,MATCH(N$5,APOIO!$B$5:$N$5,0),FALSE),0) -> 0 | O35: =IFERROR(N35/N$19,0) -> 0 | P35: =SUM(J35,L35,N35) -> -140111.53 | Q35: =IFERROR(P35/P$19,0) -> 0 | R35: =IFERROR(VLOOKUP($A35,APOIO!$B:$N,MATCH(R$5,APOIO!$B$5:$N$5,0),FALSE),0) -> 0 | S35: =IFERROR(R35/R$19,0) -> 0 | T35: =IFERROR(VLOOKUP($A35,APOIO!$B:$N,MATCH(T$5,APOIO!$B$5:$N$5,0),FALSE),0) -> 0 | U35: =IFERROR(T35/T$19,0) -> 0 | V35: =IFERROR(VLOOKUP($A35,APOIO!$B:$N,MATCH(V$5,APOIO!$B$5:$N$5,0),FALSE),0) -> 0 | W35: =IFERROR(V35/V$19,0) -> 0 | X35: =SUM(R35,T35,V35) -> 0 | Y35: =IFERROR(X35/X$19,0) -> 0 | Z35: =IFERROR(VLOOKUP($A35,APOIO!$B:$N,MATCH(Z$5,APOIO!$B$5:$N$5,0),FALSE),0) -> 0 | AA35: =IFERROR(Z35/Z$19,0) -> 0 | AB35: =IFERROR(VLOOKUP($A35,APOIO!$B:$N,MATCH(AB$5,APOIO!$B$5:$N$5,0),FALSE),0) -> 0 | AC35: =IFERROR(AB35/AB$19,0) -> 0 | AD35: =IFERROR(VLOOKUP($A35,APOIO!$B:$N,MATCH(AD$5,APOIO!$B$5:$N$5,0),FALSE),0) -> 0 | AE35: =IFERROR(AD35/AD$19,0) -> 0 | AF35: =SUM(Z35,AB35,AD35) -> 0 | AG35: =IFERROR(AF35/AF$19,0) -> 0 | AH35: =SUM(B35,D35,F35,J35,L35,N35,R35,T35,V35,Z35,AB35,AD35) -> -682394.52 | AI35: =IFERROR(AH35/AH$19,0) -> -1.3116962
A36: Despesas com Pessoal | B36: =IFERROR(VLOOKUP($A36,APOIO!$B:$N,MATCH(B$5,APOIO!$B$5:$N$5,0),FALSE),0) -> -243857.98 | C36: =IFERROR(B36/B$19,0) -> -1.5715085 | D36: =IFERROR(VLOOKUP($A36,APOIO!$B:$N,MATCH(D$5,APOIO!$B$5:$N$5,0),FALSE),0) -> -175790.23 | E36: =IFERROR(D36/D$19,0) -> -0.48153294 | F36: =IFERROR(VLOOKUP($A36,APOIO!$B:$N,MATCH(F$5,APOIO!$B$5:$N$5,0),FALSE),0) -> -74082.832 | G36: =IFERROR(F36/F$19,0) -> 0 | H36: =SUM(B36,D36,F36) -> -493731.04 | I36: =IFERROR(H36/H$19,0) -> -0.94904798 | J36: =IFERROR(VLOOKUP($A36,APOIO!$B:$N,MATCH(J$5,APOIO!$B$5:$N$5,0),FALSE),0) -> -58484.918 | K36: =IFERROR(J36/J$19,0) -> 0 | L36: =IFERROR(VLOOKUP($A36,APOIO!$B:$N,MATCH(L$5,APOIO!$B$5:$N$5,0),FALSE),0) -> -63680.216 | M36: =IFERROR(L36/L$19,0) -> 0 | N36: =IFERROR(VLOOKUP($A36,APOIO!$B:$N,MATCH(N$5,APOIO!$B$5:$N$5,0),FALSE),0) -> 0 | O36: =IFERROR(N36/N$19,0) -> 0 | P36: =SUM(J36,L36,N36) -> -122165.13 | Q36: =IFERROR(P36/P$19,0) -> 0 | R36: =IFERROR(VLOOKUP($A36,APOIO!$B:$N,MATCH(R$5,APOIO!$B$5:$N$5,0),FALSE),0) -> 0 | S36: =IFERROR(R36/R$19,0) -> 0 | T36: =IFERROR(VLOOKUP($A36,APOIO!$B:$N,MATCH(T$5,APOIO!$B$5:$N$5,0),FALSE),0) -> 0 | U36: =IFERROR(T36/T$19,0) -> 0 | V36: =IFERROR(VLOOKUP($A36,APOIO!$B:$N,MATCH(V$5,APOIO!$B$5:$N$5,0),FALSE),0) -> 0 | W36: =IFERROR(V36/V$19,0) -> 0 | X36: =SUM(R36,T36,V36) -> 0 | Y36: =IFERROR(X36/X$19,0) -> 0 | Z36: =IFERROR(VLOOKUP($A36,APOIO!$B:$N,MATCH(Z$5,APOIO!$B$5:$N$5,0),FALSE),0) -> 0 | AA36: =IFERROR(Z36/Z$19,0) -> 0 | AB36: =IFERROR(VLOOKUP($A36,APOIO!$B:$N,MATCH(AB$5,APOIO!$B$5:$N$5,0),FALSE),0) -> 0 | AC36: =IFERROR(AB36/AB$19,0) -> 0 | AD36: =IFERROR(VLOOKUP($A36,APOIO!$B:$N,MATCH(AD$5,APOIO!$B$5:$N$5,0),FALSE),0) -> 0 | AE36: =IFERROR(AD36/AD$19,0) -> 0 | AF36: =SUM(Z36,AB36,AD36) -> 0 | AG36: =IFERROR(AF36/AF$19,0) -> 0 | AH36: =SUM(B36,D36,F36,J36,L36,N36,R36,T36,V36,Z36,AB36,AD36) -> -615896.17 | AI36: =IFERROR(AH36/AH$19,0) -> -1.1838733
A37: SALARIO | B37: =IFERROR(VLOOKUP($A37,APOIO!$B:$N,MATCH(B$5,APOIO!$B$5:$N$5,0),FALSE),0) -> -89957.13 | C37: =IFERROR(B37/B$19,0) -> -0.57971608 | D37: =IFERROR(VLOOKUP($A37,APOIO!$B:$N,MATCH(D$5,APOIO!$B$5:$N$5,0),FALSE),0) -> -78180.87 | E37: =IFERROR(D37/D$19,0) -> -0.21415675 | F37: =IFERROR(VLOOKUP($A37,APOIO!$B:$N,MATCH(F$5,APOIO!$B$5:$N$5,0),FALSE),0) -> -32628.441 | G37: =IFERROR(F37/F$19,0) -> 0 | H37: =SUM(B37,D37,F37) -> -200766.44 | I37: =IFERROR(H37/H$19,0) -> -0.38591251 | J37: =IFERROR(VLOOKUP($A37,APOIO!$B:$N,MATCH(J$5,APOIO!$B$5:$N$5,0),FALSE),0) -> -30150.883 | K37: =IFERROR(J37/J$19,0) -> 0 | L37: =IFERROR(VLOOKUP($A37,APOIO!$B:$N,MATCH(L$5,APOIO!$B$5:$N$5,0),FALSE),0) -> -29306.024 | M37: =IFERROR(L37/L$19,0) -> 0 | N37: =IFERROR(VLOOKUP($A37,APOIO!$B:$N,MATCH(N$5,APOIO!$B$5:$N$5,0),FALSE),0) -> 0 | O37: =IFERROR(N37/N$19,0) -> 0 | P37: =SUM(J37,L37,N37) -> -59456.907 | Q37: =IFERROR(P37/P$19,0) -> 0 | R37: =IFERROR(VLOOKUP($A37,APOIO!$B:$N,MATCH(R$5,APOIO!$B$5:$N$5,0),FALSE),0) -> 0 | S37: =IFERROR(R37/R$19,0) -> 0 | T37: =IFERROR(VLOOKUP($A37,APOIO!$B:$N,MATCH(T$5,APOIO!$B$5:$N$5,0),FALSE),0) -> 0 | U37: =IFERROR(T37/T$19,0) -> 0 | V37: =IFERROR(VLOOKUP($A37,APOIO!$B:$N,MATCH(V$5,APOIO!$B$5:$N$5,0),FALSE),0) -> 0 | W37: =IFERROR(V37/V$19,0) -> 0 | X37: =SUM(R37,T37,V37) -> 0 | Y37: =IFERROR(X37/X$19,0) -> 0 | Z37: =IFERROR(VLOOKUP($A37,APOIO!$B:$N,MATCH(Z$5,APOIO!$B$5:$N$5,0),FALSE),0) -> 0 | AA37: =IFERROR(Z37/Z$19,0) -> 0 | AB37: =IFERROR(VLOOKUP($A37,APOIO!$B:$N,MATCH(AB$5,APOIO!$B$5:$N$5,0),FALSE),0) -> 0 | AC37: =IFERROR(AB37/AB$19,0) -> 0 | AD37: =IFERROR(VLOOKUP($A37,APOIO!$B:$N,MATCH(AD$5,APOIO!$B$5:$N$5,0),FALSE),0) -> 0 | AE37: =IFERROR(AD37/AD$19,0) -> 0 | AF37: =SUM(Z37,AB37,AD37) -> 0 | AG37: =IFERROR(AF37/AF$19,0) -> 0 | AH37: =SUM(B37,D37,F37,J37,L37,N37,R37,T37,V37,Z37,AB37,AD37) -> -260223.35 | AI37: =IFERROR(AH37/AH$19,0) -> -0.50020036
A38: 13° SALARIO | B38: =IFERROR(VLOOKUP($A38,APOIO!$B:$N,MATCH(B$5,APOIO!$B$5:$N$5,0),FALSE),0) -> 0 | C38: =IFERROR(B38/B$19,0) -> 0 | D38: =IFERROR(VLOOKUP($A38,APOIO!$B:$N,MATCH(D$5,APOIO!$B$5:$N$5,0),FALSE),0) -> 0 | E38: =IFERROR(D38/D$19,0) -> 0 | F38: =IFERROR(VLOOKUP($A38,APOIO!$B:$N,MATCH(F$5,APOIO!$B$5:$N$5,0),FALSE),0) -> 0 | G38: =IFERROR(F38/F$19,0) -> 0 | H38: =SUM(B38,D38,F38) -> 0 | I38: =IFERROR(H38/H$19,0) -> 0 | J38: =IFERROR(VLOOKUP($A38,APOIO!$B:$N,MATCH(J$5,APOIO!$B$5:$N$5,0),FALSE),0) -> 0 | K38: =IFERROR(J38/J$19,0) -> 0 | L38: =IFERROR(VLOOKUP($A38,APOIO!$B:$N,MATCH(L$5,APOIO!$B$5:$N$5,0),FALSE),0) -> 0 | M38: =IFERROR(L38/L$19,0) -> 0 | N38: =IFERROR(VLOOKUP($A38,APOIO!$B:$N,MATCH(N$5,APOIO!$B$5:$N$5,0),FALSE),0) -> 0 | O38: =IFERROR(N38/N$19,0) -> 0 | P38: =SUM(J38,L38,N38) -> 0 | Q38: =IFERROR(P38/P$19,0) -> 0 | R38: =IFERROR(VLOOKUP($A38,APOIO!$B:$N,MATCH(R$5,APOIO!$B$5:$N$5,0),FALSE),0) -> 0 | S38: =IFERROR(R38/R$19,0) -> 0 | T38: =IFERROR(VLOOKUP($A38,APOIO!$B:$N,MATCH(T$5,APOIO!$B$5:$N$5,0),FALSE),0) -> 0 | U38: =IFERROR(T38/T$19,0) -> 0 | V38: =IFERROR(VLOOKUP($A38,APOIO!$B:$N,MATCH(V$5,APOIO!$B$5:$N$5,0),FALSE),0) -> 0 | W38: =IFERROR(V38/V$19,0) -> 0 | X38: =SUM(R38,T38,V38) -> 0 | Y38: =IFERROR(X38/X$19,0) -> 0 | Z38: =IFERROR(VLOOKUP($A38,APOIO!$B:$N,MATCH(Z$5,APOIO!$B$5:$N$5,0),FALSE),0) -> 0 | AA38: =IFERROR(Z38/Z$19,0) -> 0 | AB38: =IFERROR(VLOOKUP($A38,APOIO!$B:$N,MATCH(AB$5,APOIO!$B$5:$N$5,0),FALSE),0) -> 0 | AC38: =IFERROR(AB38/AB$19,0) -> 0 | AD38: =IFERROR(VLOOKUP($A38,APOIO!$B:$N,MATCH(AD$5,APOIO!$B$5:$N$5,0),FALSE),0) -> 0 | AE38: =IFERROR(AD38/AD$19,0) -> 0 | AF38: =SUM(Z38,AB38,AD38) -> 0 | AG38: =IFERROR(AF38/AF$19,0) -> 0 | AH38: =SUM(B38,D38,F38,J38,L38,N38,R38,T38,V38,Z38,AB38,AD38) -> 0 | AI38: =IFERROR(AH38/AH$19,0) -> 0
