Workbook
Name SegmentaçãodeDados_Ano: #N/A
Name SegmentaçãodeDados_Banco: #N/A
Name SegmentaçãodeDados_Empresa: #N/A

Sheet Painel

Sheet Fluxo de Caixa 
B5: FLUXO DE CAIXA DIRETO | D5: JANEIRO | E5: FEVEREIRO | F5: MARÇO | G5: ABRIL | H5: MAIO | I5: JUNHO | J5: JULHO | K5: AGOSTO | L5: SETEMBRO | M5: OUTUBRO | N5: NOVEMBRO | O5: DEZEMBRO | Q5: ACUMULADO
B7: (+) SALDO INICIAL | D7: =SUM(D9:D18) | E7: =D227 | F7: =E227 | G7: =F227 | H7: =G227 | I7: =H227 | J7: =I227 | K7: =J227 | L7: =K227 | ... O7: =N227 | Q7: =D7
C8: Saldo Inicial Aplicações | D8: =IFERROR(INDEX(Apoio!$B:$AB,MATCH($C8,Apoio!$B$1:$B$176,0),MATCH('Fluxo de Caixa '!D$5,Apoio!$B$4:$AB$4,0)),0) | E8: =D228 | F8: =E228 | G8: =F228 | H8: =G228 | I8: =H228 | J8: =I228 | K8: =J228 | L8: =K228 | ... O8: =N228 | Q8: =D8
C9: Saldo Inicial BB | D9: =IFERROR(INDEX(Apoio!$B:$AB,MATCH($C9,Apoio!$B$1:$B$176,0),MATCH('Fluxo de Caixa '!D$5,Apoio!$B$4:$AB$4,0)),0) | E9: =D229 | F9: =E229 | G9: =F229 | H9: =G229 | I9: =H229 | J9: =I229 | K9: =J229 | L9: =K229 | ... O9: =N229 | Q9: =D9
C10: Saldo Inicial CEF | D10: =IFERROR(INDEX(Apoio!$B:$AB,MATCH($C10,Apoio!$B$1:$B$176,0),MATCH('Fluxo de Caixa '!D$5,Apoio!$B$4:$AB$4,0)),0) | E10: =D230 | F10: =E230 | G10: =F230 | H10: =G230 | I10: =H230 | J10: =I230 | K10: =J230 | L10: =K230 | ... O10: =N230 | Q10: =D10
C11: Saldo Inicial Mercantil | D11: =IFERROR(INDEX(Apoio!$B:$AB,MATCH($C11,Apoio!$B$1:$B$176,0),MATCH('Fluxo de Caixa '!D$5,Apoio!$B$4:$AB$4,0)),0) | E11: =IFERROR(INDEX(Apoio!$B:$AB,MATCH($C11,Apoio!$B$1:$B$176,0),MATCH('Fluxo de Caixa '!E$5,Apoio!$B$4:$AB$4,0)),0) | F11: =IFERROR(INDEX(Apoio!$B:$AB,MATCH($C11,Apoio!$B$1:$B$176,0),MATCH('Fluxo de Caixa '!F$5,Apoio!$B$4:$AB$4,0)),0) | G11: =IFERROR(INDEX(Apoio!$B:$AB,MATCH($C11,Apoio!$B$1:$B$176,0),MATCH('Fluxo de Caixa '!G$5,Apoio!$B$4:$AB$4,0)),0) | H11: =IFERROR(INDEX(Apoio!$B:$AB,MATCH($C11,Apoio!$B$1:$B$176,0),MATCH('Fluxo de Caixa '!H$5,Apoio!$B$4:$AB$4,0)),0) | I11: =IFERROR(INDEX(Apoio!$B:$AB,MATCH($C11,Apoio!$B$1:$B$176,0),MATCH('Fluxo de Caixa '!I$5,Apoio!$B$4:$AB$4,0)),0) | J11: =IFERROR(INDEX(Apoio!$B:$AB,MATCH($C11,Apoio!$B$1:$B$176,0),MATCH('Fluxo de Caixa '!J$5,Apoio!$B$4:$AB$4,0)),0) | K11: =IFERROR(INDEX(Apoio!$B:$AB,MATCH($C11,Apoio!$B$1:$B$176,0),MATCH('Fluxo de Caixa '!K$5,Apoio!$B$4:$AB$4,0)),0) | ... P11: =IFERROR(INDEX(Apoio!$B:$AB,MATCH($C11,Apoio!$B$1:$B$176,0),MATCH('Fluxo de Caixa '!P$5,Apoio!$B$4:$AB$4,0)),0) | Q11: =D11
C12: Saldo inicial GC Pay | D12: =IFERROR(INDEX(Apoio!$B:$AB,MATCH($C12,Apoio!$B$1:$B$176,0),MATCH('Fluxo de Caixa '!D$5,Apoio!$B$4:$AB$4,0)),0) | E12: =IFERROR(INDEX(Apoio!$B:$AB,MATCH($C12,Apoio!$B$1:$B$176,0),MATCH('Fluxo de Caixa '!E$5,Apoio!$B$4:$AB$4,0)),0) | F12: =IFERROR(INDEX(Apoio!$B:$AB,MATCH($C12,Apoio!$B$1:$B$176,0),MATCH('Fluxo de Caixa '!F$5,Apoio!$B$4:$AB$4,0)),0) | G12: =IFERROR(INDEX(Apoio!$B:$AB,MATCH($C12,Apoio!$B$1:$B$176,0),MATCH('Fluxo de Caixa '!G$5,Apoio!$B$4:$AB$4,0)),0) | H12: =IFERROR(INDEX(Apoio!$B:$AB,MATCH($C12,Apoio!$B$1:$B$176,0),MATCH('Fluxo de Caixa '!H$5,Apoio!$B$4:$AB$4,0)),0) | I12: =IFERROR(INDEX(Apoio!$B:$AB,MATCH($C12,Apoio!$B$1:$B$176,0),MATCH('Fluxo de Caixa '!I$5,Apoio!$B$4:$AB$4,0)),0) | J12: =IFERROR(INDEX(Apoio!$B:$AB,MATCH($C12,Apoio!$B$1:$B$176,0),MATCH('Fluxo de Caixa '!J$5,Apoio!$B$4:$AB$4,0)),0) | K12: =IFERROR(INDEX(Apoio!$B:$AB,MATCH($C12,Apoio!$B$1:$B$176,0),MATCH('Fluxo de Caixa '!K$5,Apoio!$B$4:$AB$4,0)),0) | ... O12: =IFERROR(INDEX(Apoio!$B:$AB,MATCH($C12,Apoio!$B$1:$B$176,0),MATCH('Fluxo de Caixa '!O$5,Apoio!$B$4:$AB$4,0)),0) | Q12: =D12
C13: Saldo inicial Itau Isolamento | D13: =IFERROR(INDEX(Apoio!$B:$AB,MATCH($C13,Apoio!$B$1:$B$176,0),MATCH('Fluxo de Caixa '!D$5,Apoio!$B$4:$AB$4,0)),0) | E13: =IFERROR(INDEX(Apoio!$B:$AB,MATCH($C13,Apoio!$B$1:$B$176,0),MATCH('Fluxo de Caixa '!E$5,Apoio!$B$4:$AB$4,0)),0) | F13: =IFERROR(INDEX(Apoio!$B:$AB,MATCH($C13,Apoio!$B$1:$B$176,0),MATCH('Fluxo de Caixa '!F$5,Apoio!$B$4:$AB$4,0)),0) | G13: =IFERROR(INDEX(Apoio!$B:$AB,MATCH($C13,Apoio!$B$1:$B$176,0),MATCH('Fluxo de Caixa '!G$5,Apoio!$B$4:$AB$4,0)),0) | H13: =IFERROR(INDEX(Apoio!$B:$AB,MATCH($C13,Apoio!$B$1:$B$176,0),MATCH('Fluxo de Caixa '!H$5,Apoio!$B$4:$AB$4,0)),0) | I13: =IFERROR(INDEX(Apoio!$B:$AB,MATCH($C13,Apoio!$B$1:$B$176,0),MATCH('Fluxo de Caixa '!I$5,Apoio!$B$4:$AB$4,0)),0) | J13: =IFERROR(INDEX(Apoio!$B:$AB,MATCH($C13,Apoio!$B$1:$B$176,0),MATCH('Fluxo de Caixa '!J$5,Apoio!$B$4:$AB$4,0)),0) | K13: =IFERROR(INDEX(Apoio!$B:$AB,MATCH($C13,Apoio!$B$1:$B$176,0),MATCH('Fluxo de Caixa '!K$5,Apoio!$B$4:$AB$4,0)),0) | ... O13: =IFERROR(INDEX(Apoio!$B:$AB,MATCH($C13,Apoio!$B$1:$B$176,0),MATCH('Fluxo de Caixa '!O$5,Apoio!$B$4:$AB$4,0)),0) | Q13: =D13
C14: Saldo inicial permuta | D14: =IFERROR(INDEX(Apoio!$B:$AB,MATCH($C14,Apoio!$B$1:$B$176,0),MATCH('Fluxo de Caixa '!D$5,Apoio!$B$4:$AB$4,0)),0) | E14: =IFERROR(INDEX(Apoio!$B:$AB,MATCH($C14,Apoio!$B$1:$B$176,0),MATCH('Fluxo de Caixa '!E$5,Apoio!$B$4:$AB$4,0)),0) | F14: =IFERROR(INDEX(Apoio!$B:$AB,MATCH($C14,Apoio!$B$1:$B$176,0),MATCH('Fluxo de Caixa '!F$5,Apoio!$B$4:$AB$4,0)),0) | G14: =IFERROR(INDEX(Apoio!$B:$AB,MATCH($C14,Apoio!$B$1:$B$176,0),MATCH('Fluxo de Caixa '!G$5,Apoio!$B$4:$AB$4,0)),0) | H14: =IFERROR(INDEX(Apoio!$B:$AB,MATCH($C14,Apoio!$B$1:$B$176,0),MATCH('Fluxo de Caixa '!H$5,Apoio!$B$4:$AB$4,0)),0) | I14: =IFERROR(INDEX(Apoio!$B:$AB,MATCH($C14,Apoio!$B$1:$B$176,0),MATCH('Fluxo de Caixa '!I$5,Apoio!$B$4:$AB$4,0)),0) | J14: =IFERROR(INDEX(Apoio!$B:$AB,MATCH($C14,Apoio!$B$1:$B$176,0),MATCH('Fluxo de Caixa '!J$5,Apoio!$B$4:$AB$4,0)),0) | K14: =IFERROR(INDEX(Apoio!$B:$AB,MATCH($C14,Apoio!$B$1:$B$176,0),MATCH('Fluxo de Caixa '!K$5,Apoio!$B$4:$AB$4,0)),0) | ... O14: =IFERROR(INDEX(Apoio!$B:$AB,MATCH($C14,Apoio!$B$1:$B$176,0),MATCH('Fluxo de Caixa '!O$5,Apoio!$B$4:$AB$4,0)),0) | Q14: =D14
C15: Saldo Inicial Safra | D15: =IFERROR(INDEX(Apoio!$B:$AB,MATCH($C15,Apoio!$B$1:$B$176,0),MATCH('Fluxo de Caixa '!D$5,Apoio!$B$4:$AB$4,0)),0) | E15: =D235 | F15: =E235 | G15: =F235 | H15: =G235 | I15: =H235 | J15: =I235 | K15: =J235 | L15: =K235 | ... O15: =N235 | Q15: =D15
C16: Saldo Inicial Itau | D16: =IFERROR(INDEX(Apoio!$B:$AB,MATCH($C16,Apoio!$B$1:$B$176,0),MATCH('Fluxo de Caixa '!D$5,Apoio!$B$4:$AB$4,0)),0) | E16: =D236 | F16: =E236 | G16: =F236 | H16: =G236 | I16: =H236 | J16: =I236 | K16: =J236 | L16: =K236 | ... O16: =N236 | Q16: =D16
C17: Saldo Inicial SICOOB | D17: =IFERROR(INDEX(Apoio!$B:$AB,MATCH($C17,Apoio!$B$1:$B$176,0),MATCH('Fluxo de Caixa '!D$5,Apoio!$B$4:$AB$4,0)),0) | E17: =D237 | F17: =E237 | G17: =F237 | H17: =G237 | I17: =H237 | J17: =I237 | K17: =J237 | L17: =K237 | ... O17: =N237
C18: Saldo Inicial Dinheiro | D18: =IFERROR(INDEX(Apoio!$B:$AB,MATCH($C18,Apoio!$B$1:$B$176,0),MATCH('Fluxo de Caixa '!D$5,Apoio!$B$4:$AB$4,0)),0) | E18: =D238 | F18: =E238 | G18: =F238 | H18: =G238 | I18: =H238 | J18: =I238 | K18: =J238 | L18: =K238 | ... O18: =N238 | Q18: =D18
B20: (+) Recebimentos Operacionais | D20: =SUM(D21:D26) | E20: =SUM(E21:E26) | F20: =SUM(F21:F26) | G20: =SUM(G21:G26) | H20: =SUM(H21:H26) | I20: =SUM(I21:I26) | J20: =SUM(J21:J26) | K20: =SUM(K21:K26) | ... O20: =SUM(O21:O26) | Q20: =SUM(Q21:Q26)
C21: Recebimento de Clientes | D21: =IFERROR(INDEX(Apoio!$B:$AB,MATCH($C21,Apoio!$B$1:$B$176,0),MATCH('Fluxo de Caixa '!D$5,Apoio!$B$4:$AB$4,0)),0) | E21: =IFERROR(INDEX(Apoio!$B:$AB,MATCH($C21,Apoio!$B$1:$B$176,0),MATCH('Fluxo de Caixa '!E$5,Apoio!$B$4:$AB$4,0)),0) | F21: =IFERROR(INDEX(Apoio!$B:$AB,MATCH($C21,Apoio!$B$1:$B$176,0),MATCH('Fluxo de Caixa '!F$5,Apoio!$B$4:$AB$4,0)),0) | G21: =IFERROR(INDEX(Apoio!$B:$AB,MATCH($C21,Apoio!$B$1:$B$176,0),MATCH('Fluxo de Caixa '!G$5,Apoio!$B$4:$AB$4,0)),0) | H21: =IFERROR(INDEX(Apoio!$B:$AB,MATCH($C21,Apoio!$B$1:$B$176,0),MATCH('Fluxo de Caixa '!H$5,Apoio!$B$4:$AB$4,0)),0) | I21: =IFERROR(INDEX(Apoio!$B:$AB,MATCH($C21,Apoio!$B$1:$B$176,0),MATCH('Fluxo de Caixa '!I$5,Apoio!$B$4:$AB$4,0)),0) | J21: =IFERROR(INDEX(Apoio!$B:$AB,MATCH($C21,Apoio!$B$1:$B$176,0),MATCH('Fluxo de Caixa '!J$5,Apoio!$B$4:$AB$4,0)),0) | K21: =IFERROR(INDEX(Apoio!$B:$AB,MATCH($C21,Apoio!$B$1:$B$176,0),MATCH('Fluxo de Caixa '!K$5,Apoio!$B$4:$AB$4,0)),0) | ... O21: =IFERROR(INDEX(Apoio!$B:$AB,MATCH($C21,Apoio!$B$1:$B$176,0),MATCH('Fluxo de Caixa '!O$5,Apoio!$B$4:$AB$4,0)),0) | Q21: =SUM(D21:P21)
C22: Serviços Prestados | D22: =IFERROR(INDEX(Apoio!$B:$AB,MATCH($C22,Apoio!$B$1:$B$176,0),MATCH('Fluxo de Caixa '!D$5,Apoio!$B$4:$AB$4,0)),0) | E22: =IFERROR(INDEX(Apoio!$B:$AB,MATCH($C22,Apoio!$B$1:$B$176,0),MATCH('Fluxo de Caixa '!E$5,Apoio!$B$4:$AB$4,0)),0) | F22: =IFERROR(INDEX(Apoio!$B:$AB,MATCH($C22,Apoio!$B$1:$B$176,0),MATCH('Fluxo de Caixa '!F$5,Apoio!$B$4:$AB$4,0)),0) | G22: =IFERROR(INDEX(Apoio!$B:$AB,MATCH($C22,Apoio!$B$1:$B$176,0),MATCH('Fluxo de Caixa '!G$5,Apoio!$B$4:$AB$4,0)),0) | H22: =IFERROR(INDEX(Apoio!$B:$AB,MATCH($C22,Apoio!$B$1:$B$176,0),MATCH('Fluxo de Caixa '!H$5,Apoio!$B$4:$AB$4,0)),0) | I22: =IFERROR(INDEX(Apoio!$B:$AB,MATCH($C22,Apoio!$B$1:$B$176,0),MATCH('Fluxo de Caixa '!I$5,Apoio!$B$4:$AB$4,0)),0) | J22: =IFERROR(INDEX(Apoio!$B:$AB,MATCH($C22,Apoio!$B$1:$B$176,0),MATCH('Fluxo de Caixa '!J$5,Apoio!$B$4:$AB$4,0)),0) | K22: =IFERROR(INDEX(Apoio!$B:$AB,MATCH($C22,Apoio!$B$1:$B$176,0),MATCH('Fluxo de Caixa '!K$5,Apoio!$B$4:$AB$4,0)),0) | ... O22: =IFERROR(INDEX(Apoio!$B:$AB,MATCH($C22,Apoio!$B$1:$B$176,0),MATCH('Fluxo de Caixa '!O$5,Apoio!$B$4:$AB$4,0)),0) | Q22: =SUM(D22:P22)
C23: Dinheiro | D23: =IFERROR(INDEX(Apoio!$B:$AB,MATCH($C23,Apoio!$B$1:$B$176,0),MATCH('Fluxo de Caixa '!D$5,Apoio!$B$4:$AB$4,0)),0) | E23: =IFERROR(INDEX(Apoio!$B:$AB,MATCH($C23,Apoio!$B$1:$B$176,0),MATCH('Fluxo de Caixa '!E$5,Apoio!$B$4:$AB$4,0)),0) | F23: =IFERROR(INDEX(Apoio!$B:$AB,MATCH($C23,Apoio!$B$1:$B$176,0),MATCH('Fluxo de Caixa '!F$5,Apoio!$B$4:$AB$4,0)),0) | G23: =IFERROR(INDEX(Apoio!$B:$AB,MATCH($C23,Apoio!$B$1:$B$176,0),MATCH('Fluxo de Caixa '!G$5,Apoio!$B$4:$AB$4,0)),0) | H23: =IFERROR(INDEX(Apoio!$B:$AB,MATCH($C23,Apoio!$B$1:$B$176,0),MATCH('Fluxo de Caixa '!H$5,Apoio!$B$4:$AB$4,0)),0) | I23: =IFERROR(INDEX(Apoio!$B:$AB,MATCH($C23,Apoio!$B$1:$B$176,0),MATCH('Fluxo de Caixa '!I$5,Apoio!$B$4:$AB$4,0)),0) | J23: =IFERROR(INDEX(Apoio!$B:$AB,MATCH($C23,Apoio!$B$1:$B$176,0),MATCH('Fluxo de Caixa '!J$5,Apoio!$B$4:$AB$4,0)),0) | K23: =IFERROR(INDEX(Apoio!$B:$AB,MATCH($C23,Apoio!$B$1:$B$176,0),MATCH('Fluxo de Caixa '!K$5,Apoio!$B$4:$AB$4,0)),0) | ... O23: =IFERROR(INDEX(Apoio!$B:$AB,MATCH($C23,Apoio!$B$1:$B$176,0),MATCH('Fluxo de Caixa '!O$5,Apoio!$B$4:$AB$4,0)),0) | Q23: =SUM(D23:P23)
C24: Antecipação de Recebíveis | D24: =IFERROR(INDEX(Apoio!$B:$AB,MATCH($C24,Apoio!$B$1:$B$176,0),MATCH('Fluxo de Caixa '!D$5,Apoio!$B$4:$AB$4,0)),0) | E24: =IFERROR(INDEX(Apoio!$B:$AB,MATCH($C24,Apoio!$B$1:$B$176,0),MATCH('Fluxo de Caixa '!E$5,Apoio!$B$4:$AB$4,0)),0) | F24: =IFERROR(INDEX(Apoio!$B:$AB,MATCH($C24,Apoio!$B$1:$B$176,0),MATCH('Fluxo de Caixa '!F$5,Apoio!$B$4:$AB$4,0)),0) | G24: =IFERROR(INDEX(Apoio!$B:$AB,MATCH($C24,Apoio!$B$1:$B$176,0),MATCH('Fluxo de Caixa '!G$5,Apoio!$B$4:$AB$4,0)),0) | H24: =IFERROR(INDEX(Apoio!$B:$AB,MATCH($C24,Apoio!$B$1:$B$176,0),MATCH('Fluxo de Caixa '!H$5,Apoio!$B$4:$AB$4,0)),0) | I24: =IFERROR(INDEX(Apoio!$B:$AB,MATCH($C24,Apoio!$B$1:$B$176,0),MATCH('Fluxo de Caixa '!I$5,Apoio!$B$4:$AB$4,0)),0) | J24: =IFERROR(INDEX(Apoio!$B:$AB,MATCH($C24,Apoio!$B$1:$B$176,0),MATCH('Fluxo de Caixa '!J$5,Apoio!$B$4:$AB$4,0)),0) | K24: =IFERROR(INDEX(Apoio!$B:$AB,MATCH($C24,Apoio!$B$1:$B$176,0),MATCH('Fluxo de Caixa '!K$5,Apoio!$B$4:$AB$4,0)),0) | ... O24: =IFERROR(INDEX(Apoio!$B:$AB,MATCH($C24,Apoio!$B$1:$B$176,0),MATCH('Fluxo de Caixa '!O$5,Apoio!$B$4:$AB$4,0)),0) | Q24: =SUM(D24:P24)
C25: Outras Entradas Operacionais | D25: =IFERROR(INDEX(Apoio!$B:$AB,MATCH($C25,Apoio!$B$1:$B$176,0),MATCH('Fluxo de Caixa '!D$5,Apoio!$B$4:$AB$4,0)),0) | E25: =IFERROR(INDEX(Apoio!$B:$AB,MATCH($C25,Apoio!$B$1:$B$176,0),MATCH('Fluxo de Caixa '!E$5,Apoio!$B$4:$AB$4,0)),0) | F25: =IFERROR(INDEX(Apoio!$B:$AB,MATCH($C25,Apoio!$B$1:$B$176,0),MATCH('Fluxo de Caixa '!F$5,Apoio!$B$4:$AB$4,0)),0) | G25: =IFERROR(INDEX(Apoio!$B:$AB,MATCH($C25,Apoio!$B$1:$B$176,0),MATCH('Fluxo de Caixa '!G$5,Apoio!$B$4:$AB$4,0)),0) | H25: =IFERROR(INDEX(Apoio!$B:$AB,MATCH($C25,Apoio!$B$1:$B$176,0),MATCH('Fluxo de Caixa '!H$5,Apoio!$B$4:$AB$4,0)),0) | I25: =IFERROR(INDEX(Apoio!$B:$AB,MATCH($C25,Apoio!$B$1:$B$176,0),MATCH('Fluxo de Caixa '!I$5,Apoio!$B$4:$AB$4,0)),0) | J25: =IFERROR(INDEX(Apoio!$B:$AB,MATCH($C25,Apoio!$B$1:$B$176,0),MATCH('Fluxo de Caixa '!J$5,Apoio!$B$4:$AB$4,0)),0) | K25: =IFERROR(INDEX(Apoio!$B:$AB,MATCH($C25,Apoio!$B$1:$B$176,0),MATCH('Fluxo de Caixa '!K$5,Apoio!$B$4:$AB$4,0)),0) | ... O25: =IFERROR(INDEX(Apoio!$B:$AB,MATCH($C25,Apoio!$B$1:$B$176,0),MATCH('Fluxo de Caixa '!O$5,Apoio!$B$4:$AB$4,0)),0) | Q25: =SUM(D25:P25)
C26: Ajustes | D26: =IFERROR(INDEX(Apoio!$B:$AB,MATCH($C26,Apoio!$B$1:$B$176,0),MATCH('Fluxo de Caixa '!D$5,Apoio!$B$4:$AB$4,0)),0) | E26: =IFERROR(INDEX(Apoio!$B:$AB,MATCH($C26,Apoio!$B$1:$B$176,0),MATCH('Fluxo de Caixa '!E$5,Apoio!$B$4:$AB$4,0)),0) | F26: =IFERROR(INDEX(Apoio!$B:$AB,MATCH($C26,Apoio!$B$1:$B$176,0),MATCH('Fluxo de Caixa '!F$5,Apoio!$B$4:$AB$4,0)),0) | G26: =IFERROR(INDEX(Apoio!$B:$AB,MATCH($C26,Apoio!$B$1:$B$176,0),MATCH('Fluxo de Caixa '!G$5,Apoio!$B$4:$AB$4,0)),0) | H26: =IFERROR(INDEX(Apoio!$B:$AB,MATCH($C26,Apoio!$B$1:$B$176,0),MATCH('Fluxo de Caixa '!H$5,Apoio!$B$4:$AB$4,0)),0) | I26: =IFERROR(INDEX(Apoio!$B:$AB,MATCH($C26,Apoio!$B$1:$B$176,0),MATCH('Fluxo de Caixa '!I$5,Apoio!$B$4:$AB$4,0)),0) | J26: =IFERROR(INDEX(Apoio!$B:$AB,MATCH($C26,Apoio!$B$1:$B$176,0),MATCH('Fluxo de Caixa '!J$5,Apoio!$B$4:$AB$4,0)),0) | K26: =IFERROR(INDEX(Apoio!$B:$AB,MATCH($C26,Apoio!$B$1:$B$176,0),MATCH('Fluxo de Caixa '!K$5,Apoio!$B$4:$AB$4,0)),0) | ... O26: =IFERROR(INDEX(Apoio!$B:$AB,MATCH($C26,Apoio!$B$1:$B$176,0),MATCH('Fluxo de Caixa '!O$5,Apoio!$B$4:$AB$4,0)),0) | Q26: =SUM(D26:P26)
D27: 0 | Q27: =SUM(D27:P27)
B28: (-) Pagamentos Operacionais | D28: =SUM(D29,D55,D68,D74,D83,D95,D126,D132,D137,D140,D144,D110) | E28: =SUM(E29,E55,E68,E74,E83,E95,E126,E132,E137,E140,E144,E110) | F28: =SUM(F29,F55,F68,F74,F83,F95,F126,F132,F137,F140,F144,F110) | G28: =SUM(G29,G55,G68,G74,G83,G95,G126,G132,G137,G140,G144,G110) | H28: =SUM(H29,H55,H68,H74,H83,H95,H126,H132,H137,H140,H144,H110) | I28: =SUM(I29,I55,I68,I74,I83,I95,I126,I132,I137,I140,I144,I110) | J28: =SUM(J29,J55,J68,J74,J83,J95,J126,J132,J137,J140,J144,J110) | K28: =SUM(K29,K55,K68,K74,K83,K95,K126,K132,K137,K140,K144,K110) | ... O28: =SUM(O29,O55,O68,O74,O83,O95,O126,O132,O137,O140,O144,O110) | Q28: =SUM(Q29,Q55,Q68,Q74,Q83,Q95,Q126,Q132,Q137,Q140,Q144,Q110)
C29: Gastos com Pessoal | D29: =SUM(D30:D53) | E29: =SUM(E30:E53) | F29: =SUM(F30:F53) | G29: =SUM(G30:G53) | H29: =SUM(H30:H53) | I29: =SUM(I30:I53) | J29: =SUM(J30:J53) | K29: =SUM(K30:K53) | ... O29: =SUM(O30:O53) | Q29: =SUM(Q30:Q53)
C30: SALARIO | D30: =IFERROR(INDEX(Apoio!$B:$AB,MATCH($C30,Apoio!$B$1:$B$176,0),MATCH('Fluxo de Caixa '!D$5,Apoio!$B$4:$AB$4,0)+1),0) | E30: =IFERROR(INDEX(Apoio!$B:$AB,MATCH($C30,Apoio!$B$1:$B$176,0),MATCH('Fluxo de Caixa '!E$5,Apoio!$B$4:$AB$4,0)+1),0) | F30: =IFERROR(INDEX(Apoio!$B:$AB,MATCH($C30,Apoio!$B$1:$B$176,0),MATCH('Fluxo de Caixa '!F$5,Apoio!$B$4:$AB$4,0)+1),0) | G30: =IFERROR(INDEX(Apoio!$B:$AB,MATCH($C30,Apoio!$B$1:$B$176,0),MATCH('Fluxo de Caixa '!G$5,Apoio!$B$4:$AB$4,0)+1),0) | H30: =IFERROR(INDEX(Apoio!$B:$AB,MATCH($C30,Apoio!$B$1:$B$176,0),MATCH('Fluxo de Caixa '!H$5,Apoio!$B$4:$AB$4,0)+1),0) | I30: =IFERROR(INDEX(Apoio!$B:$AB,MATCH($C30,Apoio!$B$1:$B$176,0),MATCH('Fluxo de Caixa '!I$5,Apoio!$B$4:$AB$4,0)+1),0) | J30: =IFERROR(INDEX(Apoio!$B:$AB,MATCH($C30,Apoio!$B$1:$B$176,0),MATCH('Fluxo de Caixa '!J$5,Apoio!$B$4:$AB$4,0)+1),0) | K30: =IFERROR(INDEX(Apoio!$B:$AB,MATCH($C30,Apoio!$B$1:$B$176,0),MATCH('Fluxo de Caixa '!K$5,Apoio!$B$4:$AB$4,0)+1),0) | ... O30: =IFERROR(INDEX(Apoio!$B:$AB,MATCH($C30,Apoio!$B$1:$B$176,0),MATCH('Fluxo de Caixa '!O$5,Apoio!$B$4:$AB$4,0)+1),0) | Q30: =SUM(D30:P30)
C31: 13° SALARIO | D31: =IFERROR(INDEX(Apoio!$B:$AB,MATCH($C31,Apoio!$B$1:$B$176,0),MATCH('Fluxo de Caixa '!D$5,Apoio!$B$4:$AB$4,0)+1),0) | E31: =IFERROR(INDEX(Apoio!$B:$AB,MATCH($C31,Apoio!$B$1:$B$176,0),MATCH('Fluxo de Caixa '!E$5,Apoio!$B$4:$AB$4,0)+1),0) | F31: =IFERROR(INDEX(Apoio!$B:$AB,MATCH($C31,Apoio!$B$1:$B$176,0),MATCH('Fluxo de Caixa '!F$5,Apoio!$B$4:$AB$4,0)+1),0) | G31: =IFERROR(INDEX(Apoio!$B:$AB,MATCH($C31,Apoio!$B$1:$B$176,0),MATCH('Fluxo de Caixa '!G$5,Apoio!$B$4:$AB$4,0)+1),0) | H31: =IFERROR(INDEX(Apoio!$B:$AB,MATCH($C31,Apoio!$B$1:$B$176,0),MATCH('Fluxo de Caixa '!H$5,Apoio!$B$4:$AB$4,0)+1),0) | I31: =IFERROR(INDEX(Apoio!$B:$AB,MATCH($C31,Apoio!$B$1:$B$176,0),MATCH('Fluxo de Caixa '!I$5,Apoio!$B$4:$AB$4,0)+1),0) | J31: =IFERROR(INDEX(Apoio!$B:$AB,MATCH($C31,Apoio!$B$1:$B$176,0),MATCH('Fluxo de Caixa '!J$5,Apoio!$B$4:$AB$4,0)+1),0) | K31: =IFERROR(INDEX(Apoio!$B:$AB,MATCH($C31,Apoio!$B$1:$B$176,0),MATCH('Fluxo de Caixa '!K$5,Apoio!$B$4:$AB$4,0)+1),0) | ... O31: =IFERROR(INDEX(Apoio!$B:$AB,MATCH($C31,Apoio!$B$1:$B$176,0),MATCH('Fluxo de Caixa '!O$5,Apoio!$B$4:$AB$4,0)+1),0) | Q31: =SUM(D31:P31)
C32: FERIAS | D32: =IFERROR(INDEX(Apoio!$B:$AB,MATCH($C32,Apoio!$B$1:$B$176,0),MATCH('Fluxo de Caixa '!D$5,Apoio!$B$4:$AB$4,0)+1),0) | E32: =IFERROR(INDEX(Apoio!$B:$AB,MATCH($C32,Apoio!$B$1:$B$176,0),MATCH('Fluxo de Caixa '!E$5,Apoio!$B$4:$AB$4,0)+1),0) | F32: =IFERROR(INDEX(Apoio!$B:$AB,MATCH($C32,Apoio!$B$1:$B$176,0),MATCH('Fluxo de Caixa '!F$5,Apoio!$B$4:$AB$4,0)+1),0) | G32: =IFERROR(INDEX(Apoio!$B:$AB,MATCH($C32,Apoio!$B$1:$B$176,0),MATCH('Fluxo de Caixa '!G$5,Apoio!$B$4:$AB$4,0)+1),0) | H32: =IFERROR(INDEX(Apoio!$B:$AB,MATCH($C32,Apoio!$B$1:$B$176,0),MATCH('Fluxo de Caixa '!H$5,Apoio!$B$4:$AB$4,0)+1),0) | I32: =IFERROR(INDEX(Apoio!$B:$AB,MATCH($C32,Apoio!$B$1:$B$176,0),MATCH('Fluxo de Caixa '!I$5,Apoio!$B$4:$AB$4,0)+1),0) | J32: =IFERROR(INDEX(Apoio!$B:$AB,MATCH($C32,Apoio!$B$1:$B$176,0),MATCH('Fluxo de Caixa '!J$5,Apoio!$B$4:$AB$4,0)+1),0) | K32: =IFERROR(INDEX(Apoio!$B:$AB,MATCH($C32,Apoio!$B$1:$B$176,0),MATCH('Fluxo de Caixa '!K$5,Apoio!$B$4:$AB$4,0)+1),0) | ... O32: =IFERROR(INDEX(Apoio!$B:$AB,MATCH($C32,Apoio!$B$1:$B$176,0),MATCH('Fluxo de Caixa '!O$5,Apoio!$B$4:$AB$4,0)+1),0) | Q32: =SUM(D32:P32)
C33: MULTA RESCISORIAS FGTS | D33: =IFERROR(INDEX(Apoio!$B:$AB,MATCH($C33,Apoio!$B$1:$B$176,0),MATCH('Fluxo de Caixa '!D$5,Apoio!$B$4:$AB$4,0)+1),0) | E33: =IFERROR(INDEX(Apoio!$B:$AB,MATCH($C33,Apoio!$B$1:$B$176,0),MATCH('Fluxo de Caixa '!E$5,Apoio!$B$4:$AB$4,0)+1),0) | F33: =IFERROR(INDEX(Apoio!$B:$AB,MATCH($C33,Apoio!$B$1:$B$176,0),MATCH('Fluxo de Caixa '!F$5,Apoio!$B$4:$AB$4,0)+1),0) | G33: =IFERROR(INDEX(Apoio!$B:$AB,MATCH($C33,Apoio!$B$1:$B$176,0),MATCH('Fluxo de Caixa '!G$5,Apoio!$B$4:$AB$4,0)+1),0) | H33: =IFERROR(INDEX(Apoio!$B:$AB,MATCH($C33,Apoio!$B$1:$B$176,0),MATCH('Fluxo de Caixa '!H$5,Apoio!$B$4:$AB$4,0)+1),0) | I33: =IFERROR(INDEX(Apoio!$B:$AB,MATCH($C33,Apoio!$B$1:$B$176,0),MATCH('Fluxo de Caixa '!I$5,Apoio!$B$4:$AB$4,0)+1),0) | J33: =IFERROR(INDEX(Apoio!$B:$AB,MATCH($C33,Apoio!$B$1:$B$176,0),MATCH('Fluxo de Caixa '!J$5,Apoio!$B$4:$AB$4,0)+1),0) | K33: =IFERROR(INDEX(Apoio!$B:$AB,MATCH($C33,Apoio!$B$1:$B$176,0),MATCH('Fluxo de Caixa '!K$5,Apoio!$B$4:$AB$4,0)+1),0) | ... O33: =IFERROR(INDEX(Apoio!$B:$AB,MATCH($C33,Apoio!$B$1:$B$176,0),MATCH('Fluxo de Caixa '!O$5,Apoio!$B$4:$AB$4,0)+1),0) | Q33: =SUM(D33:P33)
C34: REFEIÇÕES COLABORADORES | D34: =IFERROR(INDEX(Apoio!$B:$AB,MATCH($C34,Apoio!$B$1:$B$176,0),MATCH('Fluxo de Caixa '!D$5,Apoio!$B$4:$AB$4,0)+1),0) | E34: =IFERROR(INDEX(Apoio!$B:$AB,MATCH($C34,Apoio!$B$1:$B$176,0),MATCH('Fluxo de Caixa '!E$5,Apoio!$B$4:$AB$4,0)+1),0) | F34: =IFERROR(INDEX(Apoio!$B:$AB,MATCH($C34,Apoio!$B$1:$B$176,0),MATCH('Fluxo de Caixa '!F$5,Apoio!$B$4:$AB$4,0)+1),0) | G34: =IFERROR(INDEX(Apoio!$B:$AB,MATCH($C34,Apoio!$B$1:$B$176,0),MATCH('Fluxo de Caixa '!G$5,Apoio!$B$4:$AB$4,0)+1),0) | H34: =IFERROR(INDEX(Apoio!$B:$AB,MATCH($C34,Apoio!$B$1:$B$176,0),MATCH('Fluxo de Caixa '!H$5,Apoio!$B$4:$AB$4,0)+1),0) | I34: =IFERROR(INDEX(Apoio!$B:$AB,MATCH($C34,Apoio!$B$1:$B$176,0),MATCH('Fluxo de Caixa '!I$5,Apoio!$B$4:$AB$4,0)+1),0) | J34: =IFERROR(INDEX(Apoio!$B:$AB,MATCH($C34,Apoio!$B$1:$B$176,0),MATCH('Fluxo de Caixa '!J$5,Apoio!$B$4:$AB$4,0)+1),0) | K34: =IFERROR(INDEX(Apoio!$B:$AB,MATCH($C34,Apoio!$B$1:$B$176,0),MATCH('Fluxo de Caixa '!K$5,Apoio!$B$4:$AB$4,0)+1),0) | ... O34: =IFERROR(INDEX(Apoio!$B:$AB,MATCH($C34,Apoio!$B$1:$B$176,0),MATCH('Fluxo de Caixa '!O$5,Apoio!$B$4:$AB$4,0)+1),0) | Q34: =SUM(D34:P34)
C35: ALIMENTAÇÃO ADM | D35: =IFERROR(INDEX(Apoio!$B:$AB,MATCH($C35,Apoio!$B$1:$B$176,0),MATCH('Fluxo de Caixa '!D$5,Apoio!$B$4:$AB$4,0)+1),0) | E35: =IFERROR(INDEX(Apoio!$B:$AB,MATCH($C35,Apoio!$B$1:$B$176,0),MATCH('Fluxo de Caixa '!E$5,Apoio!$B$4:$AB$4,0)+1),0) | F35: =IFERROR(INDEX(Apoio!$B:$AB,MATCH($C35,Apoio!$B$1:$B$176,0),MATCH('Fluxo de Caixa '!F$5,Apoio!$B$4:$AB$4,0)+1),0) | G35: =IFERROR(INDEX(Apoio!$B:$AB,MATCH($C35,Apoio!$B$1:$B$176,0),MATCH('Fluxo de Caixa '!G$5,Apoio!$B$4:$AB$4,0)+1),0) | H35: =IFERROR(INDEX(Apoio!$B:$AB,MATCH($C35,Apoio!$B$1:$B$176,0),MATCH('Fluxo de Caixa '!H$5,Apoio!$B$4:$AB$4,0)+1),0) | I35: =IFERROR(INDEX(Apoio!$B:$AB,MATCH($C35,Apoio!$B$1:$B$176,0),MATCH('Fluxo de Caixa '!I$5,Apoio!$B$4:$AB$4,0)+1),0) | J35: =IFERROR(INDEX(Apoio!$B:$AB,MATCH($C35,Apoio!$B$1:$B$176,0),MATCH('Fluxo de Caixa '!J$5,Apoio!$B$4:$AB$4,0)+1),0) | K35: =IFERROR(INDEX(Apoio!$B:$AB,MATCH($C35,Apoio!$B$1:$B$176,0),MATCH('Fluxo de Caixa '!K$5,Apoio!$B$4:$AB$4,0)+1),0) | ... O35: =IFERROR(INDEX(Apoio!$B:$AB,MATCH($C35,Apoio!$B$1:$B$176,0),MATCH('Fluxo de Caixa '!O$5,Apoio!$B$4:$AB$4,0)+1),0) | Q35: =SUM(D35:P35)
C36: ACERTO RESCISORIOS | D36: =IFERROR(INDEX(Apoio!$B:$AB,MATCH($C36,Apoio!$B$1:$B$176,0),MATCH('Fluxo de Caixa '!D$5,Apoio!$B$4:$AB$4,0)+1),0) | E36: =IFERROR(INDEX(Apoio!$B:$AB,MATCH($C36,Apoio!$B$1:$B$176,0),MATCH('Fluxo de Caixa '!E$5,Apoio!$B$4:$AB$4,0)+1),0) | F36: =IFERROR(INDEX(Apoio!$B:$AB,MATCH($C36,Apoio!$B$1:$B$176,0),MATCH('Fluxo de Caixa '!F$5,Apoio!$B$4:$AB$4,0)+1),0) | G36: =IFERROR(INDEX(Apoio!$B:$AB,MATCH($C36,Apoio!$B$1:$B$176,0),MATCH('Fluxo de Caixa '!G$5,Apoio!$B$4:$AB$4,0)+1),0) | H36: =IFERROR(INDEX(Apoio!$B:$AB,MATCH($C36,Apoio!$B$1:$B$176,0),MATCH('Fluxo de Caixa '!H$5,Apoio!$B$4:$AB$4,0)+1),0) | I36: =IFERROR(INDEX(Apoio!$B:$AB,MATCH($C36,Apoio!$B$1:$B$176,0),MATCH('Fluxo de Caixa '!I$5,Apoio!$B$4:$AB$4,0)+1),0) | J36: =IFERROR(INDEX(Apoio!$B:$AB,MATCH($C36,Apoio!$B$1:$B$176,0),MATCH('Fluxo de Caixa '!J$5,Apoio!$B$4:$AB$4,0)+1),0) | K36: =IFERROR(INDEX(Apoio!$B:$AB,MATCH($C36,Apoio!$B$1:$B$176,0),MATCH('Fluxo de Caixa '!K$5,Apoio!$B$4:$AB$4,0)+1),0) | ... O36: =IFERROR(INDEX(Apoio!$B:$AB,MATCH($C36,Apoio!$B$1:$B$176,0),MATCH('Fluxo de Caixa '!O$5,Apoio!$B$4:$AB$4,0)+1),0) | Q36: =SUM(D36:P36)
C37: TRANSPORTE DE COLABORADORES | D37: =IFERROR(INDEX(Apoio!$B:$AB,MATCH($C37,Apoio!$B$1:$B$176,0),MATCH('Fluxo de Caixa '!D$5,Apoio!$B$4:$AB$4,0)+1),0) | E37: =IFERROR(INDEX(Apoio!$B:$AB,MATCH($C37,Apoio!$B$1:$B$176,0),MATCH('Fluxo de Caixa '!E$5,Apoio!$B$4:$AB$4,0)+1),0) | F37: =IFERROR(INDEX(Apoio!$B:$AB,MATCH($C37,Apoio!$B$1:$B$176,0),MATCH('Fluxo de Caixa '!F$5,Apoio!$B$4:$AB$4,0)+1),0) | G37: =IFERROR(INDEX(Apoio!$B:$AB,MATCH($C37,Apoio!$B$1:$B$176,0),MATCH('Fluxo de Caixa '!G$5,Apoio!$B$4:$AB$4,0)+1),0) | H37: =IFERROR(INDEX(Apoio!$B:$AB,MATCH($C37,Apoio!$B$1:$B$176,0),MATCH('Fluxo de Caixa '!H$5,Apoio!$B$4:$AB$4,0)+1),0) | I37: =IFERROR(INDEX(Apoio!$B:$AB,MATCH($C37,Apoio!$B$1:$B$176,0),MATCH('Fluxo de Caixa '!I$5,Apoio!$B$4:$AB$4,0)+1),0) | J37: =IFERROR(INDEX(Apoio!$B:$AB,MATCH($C37,Apoio!$B$1:$B$176,0),MATCH('Fluxo de Caixa '!J$5,Apoio!$B$4:$AB$4,0)+1),0) | K37: =IFERROR(INDEX(Apoio!$B:$AB,MATCH($C37,Apoio!$B$1:$B$176,0),MATCH('Fluxo de Caixa '!K$5,Apoio!$B$4:$AB$4,0)+1),0) | ... O37: =IFERROR(INDEX(Apoio!$B:$AB,MATCH($C37,Apoio!$B$1:$B$176,0),MATCH('Fluxo de Caixa '!O$5,Apoio!$B$4:$AB$4,0)+1),0) | Q37: =SUM(D37:P37)
C38: SINDICATO | D38: =IFERROR(INDEX(Apoio!$B:$AB,MATCH($C38,Apoio!$B$1:$B$176,0),MATCH('Fluxo de Caixa '!D$5,Apoio!$B$4:$AB$4,0)+1),0) | E38: =IFERROR(INDEX(Apoio!$B:$AB,MATCH($C38,Apoio!$B$1:$B$176,0),MATCH('Fluxo de Caixa '!E$5,Apoio!$B$4:$AB$4,0)+1),0) | F38: =IFERROR(INDEX(Apoio!$B:$AB,MATCH($C38,Apoio!$B$1:$B$176,0),MATCH('Fluxo de Caixa '!F$5,Apoio!$B$4:$AB$4,0)+1),0) | G38: =IFERROR(INDEX(Apoio!$B:$AB,MATCH($C38,Apoio!$B$1:$B$176,0),MATCH('Fluxo de Caixa '!G$5,Apoio!$B$4:$AB$4,0)+1),0) | H38: =IFERROR(INDEX(Apoio!$B:$AB,MATCH($C38,Apoio!$B$1:$B$176,0),MATCH('Fluxo de Caixa '!H$5,Apoio!$B$4:$AB$4,0)+1),0) | I38: =IFERROR(INDEX(Apoio!$B:$AB,MATCH($C38,Apoio!$B$1:$B$176,0),MATCH('Fluxo de Caixa '!I$5,Apoio!$B$4:$AB$4,0)+1),0) | J38: =IFERROR(INDEX(Apoio!$B:$AB,MATCH($C38,Apoio!$B$1:$B$176,0),MATCH('Fluxo de Caixa '!J$5,Apoio!$B$4:$AB$4,0)+1),0) | K38: =IFERROR(INDEX(Apoio!$B:$AB,MATCH($C38,Apoio!$B$1:$B$176,0),MATCH('Fluxo de Caixa '!K$5,Apoio!$B$4:$AB$4,0)+1),0) | ... O38: =IFERROR(INDEX(Apoio!$B:$AB,MATCH($C38,Apoio!$B$1:$B$176,0),MATCH('Fluxo de Caixa '!O$5,Apoio!$B$4:$AB$4,0)+1),0) | Q38: =SUM(D38:P38)
C39: PASSAGENS COLABORADORES | D39: =IFERROR(INDEX(Apoio!$B:$AB,MATCH($C39,Apoio!$B$1:$B$176,0),MATCH('Fluxo de Caixa '!D$5,Apoio!$B$4:$AB$4,0)+1),0) | E39: =IFERROR(INDEX(Apoio!$B:$AB,MATCH($C39,Apoio!$B$1:$B$176,0),MATCH('Fluxo de Caixa '!E$5,Apoio!$B$4:$AB$4,0)+1),0) | F39: =IFERROR(INDEX(Apoio!$B:$AB,MATCH($C39,Apoio!$B$1:$B$176,0),MATCH('Fluxo de Caixa '!F$5,Apoio!$B$4:$AB$4,0)+1),0) | G39: =IFERROR(INDEX(Apoio!$B:$AB,MATCH($C39,Apoio!$B$1:$B$176,0),MATCH('Fluxo de Caixa '!G$5,Apoio!$B$4:$AB$4,0)+1),0) | H39: =IFERROR(INDEX(Apoio!$B:$AB,MATCH($C39,Apoio!$B$1:$B$176,0),MATCH('Fluxo de Caixa '!H$5,Apoio!$B$4:$AB$4,0)+1),0) | I39: =IFERROR(INDEX(Apoio!$B:$AB,MATCH($C39,Apoio!$B$1:$B$176,0),MATCH('Fluxo de Caixa '!I$5,Apoio!$B$4:$AB$4,0)+1),0) | J39: =IFERROR(INDEX(Apoio!$B:$AB,MATCH($C39,Apoio!$B$1:$B$176,0),MATCH('Fluxo de Caixa '!J$5,Apoio!$B$4:$AB$4,0)+1),0) | K39: =IFERROR(INDEX(Apoio!$B:$AB,MATCH($C39,Apoio!$B$1:$B$176,0),MATCH('Fluxo de Caixa '!K$5,Apoio!$B$4:$AB$4,0)+1),0) | ... O39: =IFERROR(INDEX(Apoio!$B:$AB,MATCH($C39,Apoio!$B$1:$B$176,0),MATCH('Fluxo de Caixa '!O$5,Apoio!$B$4:$AB$4,0)+1),0) | Q39: =SUM(D39:P39)
C40: PLANO DE SAUDE | D40: =IFERROR(INDEX(Apoio!$B:$AB,MATCH($C40,Apoio!$B$1:$B$176,0),MATCH('Fluxo de Caixa '!D$5,Apoio!$B$4:$AB$4,0)+1),0) | E40: =IFERROR(INDEX(Apoio!$B:$AB,MATCH($C40,Apoio!$B$1:$B$176,0),MATCH('Fluxo de Caixa '!E$5,Apoio!$B$4:$AB$4,0)+1),0) | F40: =IFERROR(INDEX(Apoio!$B:$AB,MATCH($C40,Apoio!$B$1:$B$176,0),MATCH('Fluxo de Caixa '!F$5,Apoio!$B$4:$AB$4,0)+1),0) | G40: =IFERROR(INDEX(Apoio!$B:$AB,MATCH($C40,Apoio!$B$1:$B$176,0),MATCH('Fluxo de Caixa '!G$5,Apoio!$B$4:$AB$4,0)+1),0) | H40: =IFERROR(INDEX(Apoio!$B:$AB,MATCH($C40,Apoio!$B$1:$B$176,0),MATCH('Fluxo de Caixa '!H$5,Apoio!$B$4:$AB$4,0)+1),0) | I40: =IFERROR(INDEX(Apoio!$B:$AB,MATCH($C40,Apoio!$B$1:$B$176,0),MATCH('Fluxo de Caixa '!I$5,Apoio!$B$4:$AB$4,0)+1),0) | J40: =IFERROR(INDEX(Apoio!$B:$AB,MATCH($C40,Apoio!$B$1:$B$176,0),MATCH('Fluxo de Caixa '!J$5,Apoio!$B$4:$AB$4,0)+1),0) | K40: =IFERROR(INDEX(Apoio!$B:$AB,MATCH($C40,Apoio!$B$1:$B$176,0),MATCH('Fluxo de Caixa '!K$5,Apoio!$B$4:$AB$4,0)+1),0) | ... O40: =IFERROR(INDEX(Apoio!$B:$AB,MATCH($C40,Apoio!$B$1:$B$176,0),MATCH('Fluxo de Caixa '!O$5,Apoio!$B$4:$AB$4,0)+1),0) | Q40: =SUM(D40:P40)
C41: ASSISTENCIA MEDICA ADM | D41: =IFERROR(INDEX(Apoio!$B:$AB,MATCH($C41,Apoio!$B$1:$B$176,0),MATCH('Fluxo de Caixa '!D$5,Apoio!$B$4:$AB$4,0)+1),0) | E41: =IFERROR(INDEX(Apoio!$B:$AB,MATCH($C41,Apoio!$B$1:$B$176,0),MATCH('Fluxo de Caixa '!E$5,Apoio!$B$4:$AB$4,0)+1),0) | F41: =IFERROR(INDEX(Apoio!$B:$AB,MATCH($C41,Apoio!$B$1:$B$176,0),MATCH('Fluxo de Caixa '!F$5,Apoio!$B$4:$AB$4,0)+1),0) | G41: =IFERROR(INDEX(Apoio!$B:$AB,MATCH($C41,Apoio!$B$1:$B$176,0),MATCH('Fluxo de Caixa '!G$5,Apoio!$B$4:$AB$4,0)+1),0) | H41: =IFERROR(INDEX(Apoio!$B:$AB,MATCH($C41,Apoio!$B$1:$B$176,0),MATCH('Fluxo de Caixa '!H$5,Apoio!$B$4:$AB$4,0)+1),0) | I41: =IFERROR(INDEX(Apoio!$B:$AB,MATCH($C41,Apoio!$B$1:$B$176,0),MATCH('Fluxo de Caixa '!I$5,Apoio!$B$4:$AB$4,0)+1),0) | J41: =IFERROR(INDEX(Apoio!$B:$AB,MATCH($C41,Apoio!$B$1:$B$176,0),MATCH('Fluxo de Caixa '!J$5,Apoio!$B$4:$AB$4,0)+1),0) | K41: =IFERROR(INDEX(Apoio!$B:$AB,MATCH($C41,Apoio!$B$1:$B$176,0),MATCH('Fluxo de Caixa '!K$5,Apoio!$B$4:$AB$4,0)+1),0) | ... O41: =IFERROR(INDEX(Apoio!$B:$AB,MATCH($C41,Apoio!$B$1:$B$176,0),MATCH('Fluxo de Caixa '!O$5,Apoio!$B$4:$AB$4,0)+1),0) | Q41: =SUM(D41:P41)
... C53: PROGRAMA DE SEGURANÇA DO TRABALHO | D53: =IFERROR(INDEX(Apoio!$B:$AB,MATCH($C53,Apoio!$B$1:$B$176,0),MATCH('Fluxo de Caixa '!D$5,Apoio!$B$4:$AB$4,0)+1),0) | E53: =IFERROR(INDEX(Apoio!$B:$AB,MATCH($C53,Apoio!$B$1:$B$176,0),MATCH('Fluxo de Caixa '!E$5,Apoio!$B$4:$AB$4,0)+1),0) | F53: =IFERROR(INDEX(Apoio!$B:$AB,MATCH($C53,Apoio!$B$1:$B$176,0),MATCH('Fluxo de Caixa '!F$5,Apoio!$B$4:$AB$4,0)+1),0) | G53: =IFERROR(INDEX(Apoio!$B:$AB,MATCH($C53,Apoio!$B$1:$B$176,0),MATCH('Fluxo de Caixa '!G$5,Apoio!$B$4:$AB$4,0)+1),0) | H53: =IFERROR(INDEX(Apoio!$B:$AB,MATCH($C53,Apoio!$B$1:$B$176,0),MATCH('Fluxo de Caixa '!H$5,Apoio!$B$4:$AB$4,0)+1),0) | I53: =IFERROR(INDEX(Apoio!$B:$AB,MATCH($C53,Apoio!$B$1:$B$176,0),MATCH('Fluxo de Caixa '!I$5,Apoio!$B$4:$AB$4,0)+1),0) | J53: =IFERROR(INDEX(Apoio!$B:$AB,MATCH($C53,Apoio!$B$1:$B$176,0),MATCH('Fluxo de Caixa '!J$5,Apoio!$B$4:$AB$4,0)+1),0) | K53: =IFERROR(INDEX(Apoio!$B:$AB,MATCH($C53,Apoio!$B$1:$B$176,0),MATCH('Fluxo de Caixa '!K$5,Apoio!$B$4:$AB$4,0)+1),0) | ... O53: =IFERROR(INDEX(Apoio!$B:$AB,MATCH($C53,Apoio!$B$1:$B$176,0),MATCH('Fluxo de Caixa '!O$5,Apoio!$B$4:$AB$4,0)+1),0) | Q53: =SUM(D53:P53)
C55: Gastos com Instalações | D55: =SUM(D56:D66) | E55: =SUM(E56:E66) | F55: =SUM(F56:F66) | G55: =SUM(G56:G66) | H55: =SUM(H56:H66) | I55: =SUM(I56:I66) | J55: =SUM(J56:J66) | K55: =SUM(K56:K66) | ... O55: =SUM(O56:O66) | Q55: =SUM(Q56:Q66)
C56: ALUGUEL ALOJAMENTO | D56: =IFERROR(INDEX(Apoio!$B:$AB,MATCH($C56,Apoio!$B$1:$B$176,0),MATCH('Fluxo de Caixa '!D$5,Apoio!$B$4:$AB$4,0)+1),0) | E56: =IFERROR(INDEX(Apoio!$B:$AB,MATCH($C56,Apoio!$B$1:$B$176,0),MATCH('Fluxo de Caixa '!E$5,Apoio!$B$4:$AB$4,0)+1),0) | F56: =IFERROR(INDEX(Apoio!$B:$AB,MATCH($C56,Apoio!$B$1:$B$176,0),MATCH('Fluxo de Caixa '!F$5,Apoio!$B$4:$AB$4,0)+1),0) | G56: =IFERROR(INDEX(Apoio!$B:$AB,MATCH($C56,Apoio!$B$1:$B$176,0),MATCH('Fluxo de Caixa '!G$5,Apoio!$B$4:$AB$4,0)+1),0) | H56: =IFERROR(INDEX(Apoio!$B:$AB,MATCH($C56,Apoio!$B$1:$B$176,0),MATCH('Fluxo de Caixa '!H$5,Apoio!$B$4:$AB$4,0)+1),0) | I56: =IFERROR(INDEX(Apoio!$B:$AB,MATCH($C56,Apoio!$B$1:$B$176,0),MATCH('Fluxo de Caixa '!I$5,Apoio!$B$4:$AB$4,0)+1),0) | J56: =IFERROR(INDEX(Apoio!$B:$AB,MATCH($C56,Apoio!$B$1:$B$176,0),MATCH('Fluxo de Caixa '!J$5,Apoio!$B$4:$AB$4,0)+1),0) | K56: =IFERROR(INDEX(Apoio!$B:$AB,MATCH($C56,Apoio!$B$1:$B$176,0),MATCH('Fluxo de Caixa '!K$5,Apoio!$B$4:$AB$4,0)+1),0) | ... O56: =IFERROR(INDEX(Apoio!$B:$AB,MATCH($C56,Apoio!$B$1:$B$176,0),MATCH('Fluxo de Caixa '!O$5,Apoio!$B$4:$AB$4,0)+1),0) | Q56: =SUM(D56:P56)
C57: AGUA ALOJAMENTO | D57: =IFERROR(INDEX(Apoio!$B:$AB,MATCH($C57,Apoio!$B$1:$B$176,0),MATCH('Fluxo de Caixa '!D$5,Apoio!$B$4:$AB$4,0)+1),0) | E57: =IFERROR(INDEX(Apoio!$B:$AB,MATCH($C57,Apoio!$B$1:$B$176,0),MATCH('Fluxo de Caixa '!E$5,Apoio!$B$4:$AB$4,0)+1),0) | F57: =IFERROR(INDEX(Apoio!$B:$AB,MATCH($C57,Apoio!$B$1:$B$176,0),MATCH('Fluxo de Caixa '!F$5,Apoio!$B$4:$AB$4,0)+1),0) | G57: =IFERROR(INDEX(Apoio!$B:$AB,MATCH($C57,Apoio!$B$1:$B$176,0),MATCH('Fluxo de Caixa '!G$5,Apoio!$B$4:$AB$4,0)+1),0) | H57: =IFERROR(INDEX(Apoio!$B:$AB,MATCH($C57,Apoio!$B$1:$B$176,0),MATCH('Fluxo de Caixa '!H$5,Apoio!$B$4:$AB$4,0)+1),0) | I57: =IFERROR(INDEX(Apoio!$B:$AB,MATCH($C57,Apoio!$B$1:$B$176,0),MATCH('Fluxo de Caixa '!I$5,Apoio!$B$4:$AB$4,0)+1),0) | J57: =IFERROR(INDEX(Apoio!$B:$AB,MATCH($C57,Apoio!$B$1:$B$176,0),MATCH('Fluxo de Caixa '!J$5,Apoio!$B$4:$AB$4,0)+1),0) | K57: =IFERROR(INDEX(Apoio!$B:$AB,MATCH($C57,Apoio!$B$1:$B$176,0),MATCH('Fluxo de Caixa '!K$5,Apoio!$B$4:$AB$4,0)+1),0) | ... O57: =IFERROR(INDEX(Apoio!$B:$AB,MATCH($C57,Apoio!$B$1:$B$176,0),MATCH('Fluxo de Caixa '!O$5,Apoio!$B$4:$AB$4,0)+1),0) | Q57: =SUM(D57:P57)
C58: ENERGIA ALOJAMENTO | D58: =IFERROR(INDEX(Apoio!$B:$AB,MATCH($C58,Apoio!$B$1:$B$176,0),MATCH('Fluxo de Caixa '!D$5,Apoio!$B$4:$AB$4,0)+1),0) | E58: =IFERROR(INDEX(Apoio!$B:$AB,MATCH($C58,Apoio!$B$1:$B$176,0),MATCH('Fluxo de Caixa '!E$5,Apoio!$B$4:$AB$4,0)+1),0) | F58: =IFERROR(INDEX(Apoio!$B:$AB,MATCH($C58,Apoio!$B$1:$B$176,0),MATCH('Fluxo de Caixa '!F$5,Apoio!$B$4:$AB$4,0)+1),0) | G58: =IFERROR(INDEX(Apoio!$B:$AB,MATCH($C58,Apoio!$B$1:$B$176,0),MATCH('Fluxo de Caixa '!G$5,Apoio!$B$4:$AB$4,0)+1),0) | H58: =IFERROR(INDEX(Apoio!$B:$AB,MATCH($C58,Apoio!$B$1:$B$176,0),MATCH('Fluxo de Caixa '!H$5,Apoio!$B$4:$AB$4,0)+1),0) | I58: =IFERROR(INDEX(Apoio!$B:$AB,MATCH($C58,Apoio!$B$1:$B$176,0),MATCH('Fluxo de Caixa '!I$5,Apoio!$B$4:$AB$4,0)+1),0) | J58: =IFERROR(INDEX(Apoio!$B:$AB,MATCH($C58,Apoio!$B$1:$B$176,0),MATCH('Fluxo de Caixa '!J$5,Apoio!$B$4:$AB$4,0)+1),0) | K58: =IFERROR(INDEX(Apoio!$B:$AB,MATCH($C58,Apoio!$B$1:$B$176,0),MATCH('Fluxo de Caixa '!K$5,Apoio!$B$4:$AB$4,0)+1),0) | ... O58: =IFERROR(INDEX(Apoio!$B:$AB,MATCH($C58,Apoio!$B$1:$B$176,0),MATCH('Fluxo de Caixa '!O$5,Apoio!$B$4:$AB$4,0)+1),0) | Q58: =SUM(D58:P58)
...

Sheet Consolidado
A1: Data | B1: Fornecedor | C1: Crédito | D1: Débito | E1: Saldo | F1: Classificação | G1: Ano | H1: C.M. | I1: Mês | J1: Banco | K1: Empresa
A2: 45658 | B2: Saldo Inicial CEF | C2: 435332.04 | E2: 435332.04 | F2: Saldo Inicial CEF | G2: =YEAR(A2) | H2: =MONTH(A2) | I2: =INDEX(mês[],Consolidado!H2,2) | J2: CEF | K2: A IDEAL
A3: 45659 | B3: TRANSFERÊNCIA ENTRE BANCOS CEF X ITAÚ - Transferência entre Bancos (100,00%); | D3: 400000 | E3: 35332.04 | F3: Transferência Emitida | G3: =YEAR(A3) | H3: =MONTH(A3) | I3: =INDEX(mês[],Consolidado!H3,2) | J3: CEF | K3: A IDEAL
A4: 45659 | B4: DEB IOF - JUROS BANCARIOS (100,00%); | D4: 22.79 | E4: 35309.25 | F4: Juros Bancários | G4: =YEAR(A4) | H4: =MONTH(A4) | I4: =INDEX(mês[],Consolidado!H4,2) | J4: CEF | K4: A IDEAL
A5: 45659 | B5: DEB JUROS - JUROS BANCARIOS (100,00%); | D5: 363.04 | E5: 34946.21 | F5: Juros Bancários | G5: =YEAR(A5) | H5: =MONTH(A5) | I5: =INDEX(mês[],Consolidado!H5,2) | J5: CEF | K5: A IDEAL
A6: 45660 | B6: BM 07 Hh - Recebimento de Clientes (100,00%); | C6: 112098.45 | E6: 147044.66 | F6: Recebimento de Clientes | G6: =YEAR(A6) | H6: =MONTH(A6) | I6: =INDEX(mês[],Consolidado!H6,2) | J6: CEF | K6: A IDEAL
A7: 45660 | B7: BM 07 MATERIAIS - Recebimento de Clientes (100,00%); | C7: 70313.58 | E7: 217358.24 | F7: Recebimento de Clientes | G7: =YEAR(A7) | H7: =MONTH(A7) | I7: =INDEX(mês[],Consolidado!H7,2) | J7: CEF | K7: A IDEAL
A8: 45660 | B8: BM 08 MATERIAIS - Recebimento de Clientes (100,00%); | C8: 7781.98 | E8: 225140.22 | F8: Recebimento de Clientes | G8: =YEAR(A8) | H8: =MONTH(A8) | I8: =INDEX(mês[],Consolidado!H8,2) | J8: CEF | K8: A IDEAL
A9: 45660 | B9: RECIBO - Recebimento de Clientes (100,00%); | C9: 63350.67 | E9: 288490.89 | F9: Recebimento de Clientes | G9: =YEAR(A9) | H9: =MONTH(A9) | I9: =INDEX(mês[],Consolidado!H9,2) | J9: CEF | K9: A IDEAL
A10: 45660 | B10: TRANSFERENCIA ENTRE BANCOS CEF X ITAÚ - Transferência entre Bancos (100,00%); | D10: 268576.19 | E10: 19914.7 | F10: Transferência Emitida | G10: =YEAR(A10) | H10: =MONTH(A10) | I10: =INDEX(mês[],Consolidado!H10,2) | J10: CEF | K10: A IDEAL
A11: 45663 | B11: EMPRESTIMO BANCO CAIXA / PEGO PARA PAGAR MERCANTIL - PAGAMENTOS EMPRESTIMOS (100,00%); | D11: 19891.97 | E11: 22.73 | F11: Pagamento de Empréstimos Bancários | G11: =YEAR(A11) | H11: =MONTH(A11) | I11: =INDEX(mês[],Consolidado!H11,2) | J11: CEF | K11: A IDEAL
A12: 45663 | B12: RENDIMENTO APLICAÇÃO - Origens Financeiras (100,00%); | C12: 94.87 | E12: 117.6 | F12: Juros Recebidos | G12: =YEAR(A12) | H12: =MONTH(A12) | I12: =INDEX(mês[],Consolidado!H12,2) | J12: CEF | K12: A IDEAL
A13: 45664 | B13: TRANSFERÊNCIA ENTRE BANCOS ITAÚ X CEF - Transferência entre Bancos (100,00%); | C13: 337744.57 | E13: 337862.17 | F13: Transferência Recebida | G13: =YEAR(A13) | H13: =MONTH(A13) | I13: =INDEX(mês[],Consolidado!H13,2) | J13: CEF | K13: A IDEAL
A14: 45664 | B14: RENDIMENTO APLICAÇÃO - Origens Financeiras (100,00%); | C14: 0.04 | E14: 337862.21 | F14: Juros Recebidos | G14: =YEAR(A14) | H14: =MONTH(A14) | I14: =INDEX(mês[],Consolidado!H14,2) | J14: CEF | K14: A IDEAL
A15: 45664 | B15: FOLHA PGTO REF. 12/2024 - SALARIO (100,00%); | D15: 337862.17 | E15: 0.04 | F15: SALARIO | G15: =YEAR(A15) | H15: =MONTH(A15) | I15: =INDEX(mês[],Consolidado!H15,2) | J15: CEF | K15: A IDEAL
A16: 45666 | B16: TARIFAS BANCÁRIAS - TARIFAS BANCARIAS (100,00%); | D16: 205.8 | E16: -205.76 | F16: TARIFAS BANCARIAS | G16: =YEAR(A16) | H16: =MONTH(A16) | I16: =INDEX(mês[],Consolidado!H16,2) | J16: CEF | K16: A IDEAL
A17: 45667 | B17: VALOR DEPOSITADO PELA MOSAIC - Recebimento de Clientes (100,00%); | C17: 1791.49 | E17: 1585.73 | F17: Recebimento de Clientes | G17: =YEAR(A17) | H17: =MONTH(A17) | I17: =INDEX(mês[],Consolidado!H17,2) | J17: CEF | K17: A IDEAL
A18: 45667 | B18: IMOBILIARIO LOTE PARQUE OESTE - FINANCIAMENTO (100,00%); | D18: 4302.43 | E18: -2716.7 | F18: Financiamentos | G18: =YEAR(A18) | H18: =MONTH(A18) | I18: =INDEX(mês[],Consolidado!H18,2) | J18: CEF | K18: A IDEAL
A19: 45667 | B19: TARIFAS BANCÁRIAS CEF - TARIFAS BANCARIAS (100,00%); | D19: 564.98 | E19: -3281.68 | F19: TARIFAS BANCARIAS | G19: =YEAR(A19) | H19: =MONTH(A19) | I19: =INDEX(mês[],Consolidado!H19,2) | J19: CEF | K19: A IDEAL
A20: 45677 | B20: ADIANTAMENTO 40% - SALARIO (100,00%); | D20: 34885.28 | E20: -38166.96 | F20: SALARIO | G20: =YEAR(A20) | H20: =MONTH(A20) | I20: =INDEX(mês[],Consolidado!H20,2) | J20: CEF | K20: A IDEAL
A21: 45677 | B21: TRANSFERENCIA ENTRE BANCOS ITAÚ X CEF - Transferência entre Bancos (100,00%); | C21: 50000 | E21: 11833.04 | F21: Transferência Recebida | G21: =YEAR(A21) | H21: =MONTH(A21) | I21: =INDEX(mês[],Consolidado!H21,2) | J21: CEF | K21: A IDEAL
A22: 45677 | B22: EMPRESTIMO BANCO CAIXA / CAPITAL DE GIRO R$ 300.000,00 - PAGAMENTOS EMPRESTIMOS (100,00%); | D22: 15804.58 | E22: -3971.54 | F22: Pagamento de Empréstimos Bancários | G22: =YEAR(A22) | H22: =MONTH(A22) | I22: =INDEX(mês[],Consolidado!H22,2) | J22: CEF | K22: A IDEAL
A23: 45678 | B23: TRANSFERÊNCIA ENTRE BANCOS ITÁU X CEF - Transferência entre Bancos (100,00%); | C23: 4000 | E23: 28.46 | F23: Transferência Recebida | G23: =YEAR(A23) | H23: =MONTH(A23) | I23: =INDEX(mês[],Consolidado!H23,2) | J23: CEF | K23: A IDEAL
A24: 45679 | B24: TARIFAS BANCÁRIAS - TARIFAS BANCARIAS (100,00%); | D24: 44.8 | E24: -16.34 | F24: TARIFAS BANCARIAS | G24: =YEAR(A24) | H24: =MONTH(A24) | I24: =INDEX(mês[],Consolidado!H24,2) | J24: CEF | K24: A IDEAL
A25: 45688 | B25: TRANSFERENCIA ENTRE BANCOS ITAÚ X CEF - Transferência entre Bancos (100,00%); | C25: 10000 | E25: 9983.66 | F25: Transferência Recebida | G25: =YEAR(A25) | H25: =MONTH(A25) | I25: =INDEX(mês[],Consolidado!H25,2) | J25: CEF | K25: A IDEAL
A26: 45688 | B26: IMPOSTOS DEBITADOS EM CONTA CAIXA ECONOMICA - PARCELAMENTO (100,00%); | D26: 19946.33 | E26: -9962.67 | F26: Parcelamento de Impostos Exercicio Anterior | G26: =YEAR(A26) | H26: =MONTH(A26) | I26: =INDEX(mês[],Consolidado!H26,2) | J26: CEF | K26: A IDEAL
A27: 45688 | B27: Saldo Final CEF | D27: -9962.67 | E27: -9962.67 | F27: Saldo Final CEF | G27: =YEAR(A27) | H27: =MONTH(A27) | I27: =INDEX(mês[],Consolidado!H27,2) | J27: CEF | K27: A IDEAL
A28: 45691 | B28: BM 08 Hh - Recebimento de Clientes (100,00%); | C28: 83747.86 | E28: 73785.19 | F28: Recebimento de Clientes | G28: =YEAR(A28) | H28: =MONTH(A28) | I28: =INDEX(mês[],Consolidado!H28,2) | J28: CEF | K28: A IDEAL
A29: 45691 | B29: RECIBO LOCAÇÃO - Recebimento de Clientes (100,00%); | C29: 61307.1 | E29: 135092.29 | F29: Recebimento de Clientes | G29: =YEAR(A29) | H29: =MONTH(A29) | I29: =INDEX(mês[],Consolidado!H29,2) | J29: CEF | K29: A IDEAL
A30: 45691 | B30: BM 09 TINTAS - Recebimento de Clientes (100,00%); | C30: 11353.45 | E30: 146445.74 | F30: Recebimento de Clientes | G30: =YEAR(A30) | H30: =MONTH(A30) | I30: =INDEX(mês[],Consolidado!H30,2) | J30: CEF | K30: A IDEAL
A31: 45691 | B31: BM 10 TINTAS - Recebimento de Clientes (100,00%); | C31: 18002.42 | E31: 164448.16 | F31: Recebimento de Clientes | G31: =YEAR(A31) | H31: =MONTH(A31) | I31: =INDEX(mês[],Consolidado!H31,2) | J31: CEF | K31: A IDEAL
A32: 45691 | B32: DEB IOF E DEB JUROS CEF - JUROS BANCARIOS (100,00%); | D32: 289.39 | E32: 164158.77 | F32: Juros Bancários | G32: =YEAR(A32) | H32: =MONTH(A32) | I32: =INDEX(mês[],Consolidado!H32,2) | J32: CEF | K32: A IDEAL
A33: 45692 | B33: TRANSFERÊNCIA ENTRE BANCOS CEF X ITAÚ - Transferência entre Bancos (100,00%); | D33: 164158.77 | E33: 0 | F33: Transferência Emitida | G33: =YEAR(A33) | H33: =MONTH(A33) | I33: =INDEX(mês[],Consolidado!H33,2) | J33: CEF | K33: A IDEAL
A34: 45693 | B34: BM 10 - Recebimento de Clientes (100,00%); | C34: 31444.71 | E34: 31444.71 | F34: Recebimento de Clientes | G34: =YEAR(A34) | H34: =MONTH(A34) | I34: =INDEX(mês[],Consolidado!H34,2) | J34: CEF | K34: A IDEAL
A35: 45693 | B35: TRANSFERENCIA CEF X ITAÚ - Transferência entre Bancos (100,00%); | D35: 31444.71 | E35: 0 | F35: Transferência Emitida | G35: =YEAR(A35) | H35: =MONTH(A35) | I35: =INDEX(mês[],Consolidado!H35,2) | J35: CEF | K35: A IDEAL
A36: 45694 | B36: TRANSFERÊNCIA ENTRE BANCOS ITAÚ X CEF - Transferência entre Bancos (100,00%); | C36: 370205.08 | E36: 370205.08 | F36: Transferência Recebida | G36: =YEAR(A36) | H36: =MONTH(A36) | I36: =INDEX(mês[],Consolidado!H36,2) | J36: CEF | K36: A IDEAL
A37: 45694 | B37: TRANSFERÊNCIA ENTRE BANCOS ITAÚ X CEF - Transferência entre Bancos (100,00%); | C37: 20000 | E37: 390205.08 | F37: Transferência Recebida | G37: =YEAR(A37) | H37: =MONTH(A37) | I37: =INDEX(mês[],Consolidado!H37,2) | J37: CEF | K37: A IDEAL
A38: 45694 | B38: FOLHA PAGAMENTO REF. 01/2025 - SALARIO (100,00%); | D38: 370205.08 | E38: 20000 | F38: SALARIO | G38: =YEAR(A38) | H38: =MONTH(A38) | I38: =INDEX(mês[],Consolidado!H38,2) | J38: CEF | K38: A IDEAL
A39: 45694 | B39: EMPRESTIMO BANCO CAIXA / PEGO PARA PAGAR MERCANTIL - PAGAMENTOS EMPRESTIMOS (100,00%); | D39: 19925.94 | E39: 74.06 | F39: Pagamento de Empréstimos Bancários | G39: =YEAR(A39) | H39: =MONTH(A39) | I39: =INDEX(mês[],Consolidado!H39,2) | J39: CEF | K39: A IDEAL
A40: 45694 | B40: BLOQUEIO JUDICIAL AÇÃO TRABALHISTA - DESPESAS COM PROCESSOS (100,00%); | D40: 82.39 | E40: -8.33 | F40: Devolução de Pagamento Recebido | G40: =YEAR(A40) | H40: =MONTH(A40) | I40: =INDEX(mês[],Consolidado!H40,2) | J40: CEF | K40: A IDEAL
...

Sheet Apresentação GMP
C2: Jan | D2: Fev | E2: Mar | F2: Abr | G2: Mai | H2: Jun | I2: Jul | J2: Ago | K2: Set | L2: Out | M2: Nov | N2: Dez | O2: Acum
B3: Margem Líquida de Caixa 2025 | C3: ='Fluxo de Caixa '!D168 | D3: ='Fluxo de Caixa '!E168 | E3: ='Fluxo de Caixa '!F168 | F3: ='Fluxo de Caixa '!G168 | G3: ='Fluxo de Caixa '!H168 | H3: ='Fluxo de Caixa '!I168 | I3: ='Fluxo de Caixa '!J168 | J3: ='Fluxo de Caixa '!K168 | ... N3: ='Fluxo de Caixa '!O168 | O3: =SUM(C3:N3)
B4: Margem Líquida de Caixa 2023
B5: % Margem Líquida de Caixa 2025 | C5: ='Fluxo de Caixa '!D169 | D5: ='Fluxo de Caixa '!E169 | E5: ='Fluxo de Caixa '!F169 | F5: ='Fluxo de Caixa '!G169 | G5: ='Fluxo de Caixa '!H169 | H5: ='Fluxo de Caixa '!I169 | I5: ='Fluxo de Caixa '!J169 | J5: ='Fluxo de Caixa '!K169 | ... N5: ='Fluxo de Caixa '!O169 | O5: ='Fluxo de Caixa '!Q169
B6: % Margem Líquida de Caixa 2023
B7: Var. Margem Líquida de Caixa | C7: =IFERROR(C3/N4-1,0) | D7: =IFERROR(D3/C3-1,0) | E7: =IFERROR(E3/D3-1,0) | F7: =IFERROR(F3/E3-1,0) | G7: =IFERROR(G3/F3-1,0) | H7: =IFERROR(H3/G3-1,0) | I7: =IFERROR(I3/H3-1,0) | J7: =IFERROR(J3/I3-1,0) | K7: =IFERROR(K3/J3-1,0) | ... N7: =IFERROR(N3/M3-1,0)
C9: Jan | D9: Fev | E9: Mar | F9: Abr | G9: Mai | H9: Jun | I9: Jul | J9: Ago | K9: Set | L9: Out | M9: Nov | N9: Dez | O9: Acum
B10: Recebimentos Operacionais 2025 | C10: ='Fluxo de Caixa '!D20 | D10: ='Fluxo de Caixa '!E20 | E10: ='Fluxo de Caixa '!F20 | F10: ='Fluxo de Caixa '!G20 | G10: ='Fluxo de Caixa '!H20 | H10: ='Fluxo de Caixa '!I20 | I10: ='Fluxo de Caixa '!J20 | J10: ='Fluxo de Caixa '!K20 | ... N10: ='Fluxo de Caixa '!O20 | O10: =SUM(C10:N10)
B11: Recebimentos Operacionais 2023
B12: Var. Rec. Operacionais | C12: =IFERROR(C10/N11-1,0) | D12: =IFERROR(D10/C10-1,0) | E12: =IFERROR(E10/D10-1,0) | F12: =IFERROR(F10/E10-1,0) | G12: =IFERROR(G10/F10-1,0) | H12: =IFERROR(H10/G10-1,0) | I12: =IFERROR(I10/H10-1,0) | J12: =IFERROR(J10/I10-1,0) | K12: =IFERROR(K10/J10-1,0) | ... N12: =IFERROR(N10/M10-1,0)
C14: Jan | D14: Fev | E14: Mar | F14: Abr | G14: Mai | H14: Jun | I14: Jul | J14: Ago | K14: Set | L14: Out | M14: Nov | N14: Dez | O14: Acum
B15: Pagamentos Operacionais 2025 | C15: ='Fluxo de Caixa '!D28 | D15: ='Fluxo de Caixa '!E28 | E15: ='Fluxo de Caixa '!F28 | F15: ='Fluxo de Caixa '!G28 | G15: ='Fluxo de Caixa '!H28 | H15: ='Fluxo de Caixa '!I28 | I15: ='Fluxo de Caixa '!J28 | J15: ='Fluxo de Caixa '!K28 | ... N15: ='Fluxo de Caixa '!O28 | O15: =SUM(C15:N15)
B16: Pagamentos Operacionais 2023
B17: Var. Pgtos. Operacionais | C17: =IFERROR(C15/N16-1,0) | D17: =IFERROR(D15/C15-1,0) | E17: =IFERROR(E15/D15-1,0) | F17: =IFERROR(F15/E15-1,0) | G17: =IFERROR(G15/F15-1,0) | H17: =IFERROR(H15/G15-1,0) | I17: =IFERROR(I15/H15-1,0) | J17: =IFERROR(J15/I15-1,0) | K17: =IFERROR(K15/J15-1,0) | ... N17: =IFERROR(N15/M15-1,0)
B19: Pagamentos Operacionais | C19: Jan | D19: Fev | E19: Mar | F19: Abr | G19: Mai | H19: Jun | I19: Jul | J19: Ago | K19: Set | L19: Out | M19: Nov | N19: Dez | O19: Acum | P19: 80-20 | Q19: %GF
B20: Pgtos Operacionais | C20: ='Fluxo de Caixa '!D28 | D20: ='Fluxo de Caixa '!E28 | E20: ='Fluxo de Caixa '!F28 | F20: ='Fluxo de Caixa '!G28 | G20: ='Fluxo de Caixa '!H28 | H20: ='Fluxo de Caixa '!I28 | I20: ='Fluxo de Caixa '!J28 | J20: ='Fluxo de Caixa '!K28 | ... N20: ='Fluxo de Caixa '!O28 | O20: ='Fluxo de Caixa '!Q28
B21: G. Pessoal | C21: ='Fluxo de Caixa '!D29 | D21: ='Fluxo de Caixa '!E29 | E21: ='Fluxo de Caixa '!F29 | F21: ='Fluxo de Caixa '!G29 | G21: ='Fluxo de Caixa '!H29 | H21: ='Fluxo de Caixa '!I29 | I21: ='Fluxo de Caixa '!J29 | J21: ='Fluxo de Caixa '!K29 | ... N21: ='Fluxo de Caixa '!O29 | O21: ='Fluxo de Caixa '!Q29 | P21: =IFERROR(P20+O21/$O$20,0) | Q21: =IFERROR(O21/$O$20,0)
B22: G. Impostos e Tributos | C22: ='Fluxo de Caixa '!D74 | D22: ='Fluxo de Caixa '!E74 | E22: ='Fluxo de Caixa '!F74 | F22: ='Fluxo de Caixa '!G74 | G22: ='Fluxo de Caixa '!H74 | H22: ='Fluxo de Caixa '!I74 | I22: ='Fluxo de Caixa '!J74 | J22: ='Fluxo de Caixa '!K74 | ... N22: ='Fluxo de Caixa '!O74 | O22: ='Fluxo de Caixa '!Q74 | P22: =IFERROR(P21+O22/$O$20,0) | Q22: =IFERROR(O22/$O$20,0)
B23: G. Locações | C23: ='Fluxo de Caixa '!D95 | D23: ='Fluxo de Caixa '!E95 | E23: ='Fluxo de Caixa '!F95 | F23: ='Fluxo de Caixa '!G95 | G23: ='Fluxo de Caixa '!H95 | H23: ='Fluxo de Caixa '!I95 | I23: ='Fluxo de Caixa '!J95 | J23: ='Fluxo de Caixa '!K95 | ... N23: ='Fluxo de Caixa '!O95 | O23: ='Fluxo de Caixa '!Q95 | P23: =IFERROR(P22+O23/$O$20,0) | Q23: =IFERROR(O23/$O$20,0)
B24: G. Fornecedores | C24: ='Fluxo de Caixa '!D132 | D24: ='Fluxo de Caixa '!E132 | E24: ='Fluxo de Caixa '!F132 | F24: ='Fluxo de Caixa '!G132 | G24: ='Fluxo de Caixa '!H132 | H24: ='Fluxo de Caixa '!I132 | I24: ='Fluxo de Caixa '!J132 | J24: ='Fluxo de Caixa '!K132 | ... N24: ='Fluxo de Caixa '!O132 | O24: ='Fluxo de Caixa '!Q132 | P24: =IFERROR(P23+O24/$O$20,0) | Q24: =IFERROR(O24/$O$20,0)
B25: G. Instalações | C25: ='Fluxo de Caixa '!D55 | D25: ='Fluxo de Caixa '!E55 | E25: ='Fluxo de Caixa '!F55 | F25: ='Fluxo de Caixa '!G55 | G25: ='Fluxo de Caixa '!H55 | H25: ='Fluxo de Caixa '!I55 | I25: ='Fluxo de Caixa '!J55 | J25: ='Fluxo de Caixa '!K55 | ... N25: ='Fluxo de Caixa '!O55 | O25: ='Fluxo de Caixa '!Q55 | P25: =IFERROR(P23+O25/$O$20,0) | Q25: =IFERROR(O25/$O$20,0)
B26: G. Veículos | C26: ='Fluxo de Caixa '!D83 | D26: ='Fluxo de Caixa '!E83 | E26: ='Fluxo de Caixa '!F83 | F26: ='Fluxo de Caixa '!G83 | G26: ='Fluxo de Caixa '!H83 | H26: ='Fluxo de Caixa '!I83 | I26: ='Fluxo de Caixa '!J83 | J26: ='Fluxo de Caixa '!K83 | ... N26: ='Fluxo de Caixa '!O83 | O26: ='Fluxo de Caixa '!Q83 | P26: =IFERROR(P23+O26/$O$20,0) | Q26: =IFERROR(O26/$O$20,0)
B27: G. Administrativos | C27: ='Fluxo de Caixa '!D144 | D27: ='Fluxo de Caixa '!E144 | E27: ='Fluxo de Caixa '!F144 | F27: ='Fluxo de Caixa '!G144 | G27: ='Fluxo de Caixa '!H144 | H27: ='Fluxo de Caixa '!I144 | I27: ='Fluxo de Caixa '!J144 | J27: ='Fluxo de Caixa '!K144 | ... N27: ='Fluxo de Caixa '!O144 | O27: ='Fluxo de Caixa '!Q144 | P27: =IFERROR(P26+O27/$O$20,0) | Q27: =IFERROR(O27/$O$20,0)
B28: G. com Máquinas e Equipamentos | C28: ='Fluxo de Caixa '!D110 | D28: ='Fluxo de Caixa '!E110 | E28: ='Fluxo de Caixa '!F110 | F28: ='Fluxo de Caixa '!G110 | G28: ='Fluxo de Caixa '!H110 | H28: ='Fluxo de Caixa '!I110 | I28: ='Fluxo de Caixa '!J110 | J28: ='Fluxo de Caixa '!K110 | ... N28: ='Fluxo de Caixa '!O110 | O28: ='Fluxo de Caixa '!Q110 | P28: =IFERROR(P27+O28/$O$20,0) | Q28: =IFERROR(O28/$O$20,0)
B29: G. Fretes | C29: ='Fluxo de Caixa '!D126 | D29: ='Fluxo de Caixa '!E126 | E29: ='Fluxo de Caixa '!F126 | F29: ='Fluxo de Caixa '!G126 | G29: ='Fluxo de Caixa '!H126 | H29: ='Fluxo de Caixa '!I126 | I29: ='Fluxo de Caixa '!J126 | J29: ='Fluxo de Caixa '!K126 | ... N29: ='Fluxo de Caixa '!O126 | O29: ='Fluxo de Caixa '!Q126 | P29: =IFERROR(P27+O29/$O$20,0) | Q29: =IFERROR(O29/$O$20,0)
B30: G. Serviços de Terceiros | C30: ='Fluxo de Caixa '!D68 | D30: ='Fluxo de Caixa '!E68 | E30: ='Fluxo de Caixa '!F68 | F30: ='Fluxo de Caixa '!G68 | G30: ='Fluxo de Caixa '!H68 | H30: ='Fluxo de Caixa '!I68 | I30: ='Fluxo de Caixa '!J68 | J30: ='Fluxo de Caixa '!K68 | ... N30: ='Fluxo de Caixa '!O68 | O30: ='Fluxo de Caixa '!Q68 | P30: =IFERROR(P29+O30/$O$20,0) | Q30: =IFERROR(O30/$O$20,0)
B31: G. com Viagens e Hospedagens | C31: ='Fluxo de Caixa '!D140 | D31: ='Fluxo de Caixa '!E140 | E31: ='Fluxo de Caixa '!F140 | F31: ='Fluxo de Caixa '!G140 | G31: ='Fluxo de Caixa '!H140 | H31: ='Fluxo de Caixa '!I140 | I31: ='Fluxo de Caixa '!J140 | J31: ='Fluxo de Caixa '!K140 | ... N31: ='Fluxo de Caixa '!O140 | O31: ='Fluxo de Caixa '!Q140 | P31: =IFERROR(P30+O31/$O$20,0) | Q31: =IFERROR(O31/$O$20,0)
B32: G. Bancários | C32: ='Fluxo de Caixa '!D137 | D32: ='Fluxo de Caixa '!E137 | E32: ='Fluxo de Caixa '!F137 | F32: ='Fluxo de Caixa '!G137 | G32: ='Fluxo de Caixa '!H137 | H32: ='Fluxo de Caixa '!I137 | I32: ='Fluxo de Caixa '!J137 | J32: ='Fluxo de Caixa '!K137 | ... N32: ='Fluxo de Caixa '!O137 | O32: ='Fluxo de Caixa '!Q137 | P32: =IFERROR(P31+O32/$O$20,0) | Q32: =IFERROR(O32/$O$20,0)
B33: Total | C33: =SUM(C21:C32) | D33: =SUM(D21:D32) | E33: =SUM(E21:E32) | F33: =SUM(F21:F32) | G33: =SUM(G21:G32) | H33: =SUM(H21:H32) | I33: =SUM(I21:I32) | J33: =SUM(J21:J32) | ... O33: =SUM(O21:O32)
B34: % Receb. Operacionais | C34: =IFERROR(C33/C$10,0) | D34: =IFERROR(D33/D$10,0) | E34: =IFERROR(E33/E$10,0) | F34: =IFERROR(F33/F$10,0) | G34: =IFERROR(G33/G$10,0) | H34: =IFERROR(H33/H$10,0) | I34: =IFERROR(I33/I$10,0) | J34: =IFERROR(J33/J$10,0) | ... O34: =IFERROR(O33/O$10,0)
B36: Gastos com Pessoal | C36: Jan | D36: Fev | E36: Mar | F36: Abr | G36: Mai | H36: Jun | I36: Jul | J36: Ago | K36: Set | L36: Out | M36: Nov | N36: Dez | O36: Acum | P36: Var. Julho x Junho | Q36: % Recb. Operacionais
B37: ='Fluxo de Caixa '!C30 | C37: ='Fluxo de Caixa '!D30 | D37: ='Fluxo de Caixa '!E30 | E37: ='Fluxo de Caixa '!F30 | F37: ='Fluxo de Caixa '!G30 | G37: ='Fluxo de Caixa '!H30 | H37: ='Fluxo de Caixa '!I30 | I37: ='Fluxo de Caixa '!J30 | ... N37: ='Fluxo de Caixa '!O30 | O37: =SUM(C37:N37) | P37: =IFERROR(I37/H37-1,IF(I37>0,1,0)) | Q37: =IFERROR(O37/$O$10,0) | R37: =I37-H37
B38: ='Fluxo de Caixa '!C34 | C38: ='Fluxo de Caixa '!D34 | D38: ='Fluxo de Caixa '!E34 | E38: ='Fluxo de Caixa '!F34 | F38: ='Fluxo de Caixa '!G34 | G38: ='Fluxo de Caixa '!H34 | H38: ='Fluxo de Caixa '!I34 | I38: ='Fluxo de Caixa '!J34 | ... N38: ='Fluxo de Caixa '!O34 | O38: =SUM(C38:N38) | P38: =IFERROR(I38/H38-1,IF(I38>0,1,0)) | Q38: =IFERROR(O38/$O$10,0) | R38: =I38-H38
B39: ='Fluxo de Caixa '!C37 | C39: ='Fluxo de Caixa '!D37 | D39: ='Fluxo de Caixa '!E37 | E39: ='Fluxo de Caixa '!F37 | F39: ='Fluxo de Caixa '!G37 | G39: ='Fluxo de Caixa '!H37 | H39: ='Fluxo de Caixa '!I37 | I39: ='Fluxo de Caixa '!J37 | ... N39: ='Fluxo de Caixa '!O37 | O39: =SUM(C39:N39) | P39: =IFERROR(I39/H39-1,IF(I39>0,1,0)) | Q39: =IFERROR(O39/$O$10,0) | R39: =I39-H39
B40: ='Fluxo de Caixa '!C45 | C40: ='Fluxo de Caixa '!D45 | D40: ='Fluxo de Caixa '!E45 | E40: ='Fluxo de Caixa '!F45 | F40: ='Fluxo de Caixa '!G45 | G40: ='Fluxo de Caixa '!H45 | H40: ='Fluxo de Caixa '!I45 | I40: ='Fluxo de Caixa '!J45 | ... N40: ='Fluxo de Caixa '!O45 | O40: =SUM(C40:N40) | P40: =IFERROR(I40/H40-1,IF(I40>0,1,0)) | Q40: =IFERROR(O40/$O$10,0) | R40: =I40-H40
B41: ='Fluxo de Caixa '!C36 | C41: ='Fluxo de Caixa '!D36 | D41: ='Fluxo de Caixa '!E36 | E41: ='Fluxo de Caixa '!F36 | F41: ='Fluxo de Caixa '!G36 | G41: ='Fluxo de Caixa '!H36 | H41: ='Fluxo de Caixa '!I36 | I41: ='Fluxo de Caixa '!J36 | ... N41: ='Fluxo de Caixa '!O36 | O41: =SUM(C41:N41) | P41: =IFERROR(I41/H41-1,IF(I41>0,1,0)) | Q41: =IFERROR(O41/$O$10,0) | R41: =I41-H41
B42: ='Fluxo de Caixa '!C43 | C42: ='Fluxo de Caixa '!D43 | D42: ='Fluxo de Caixa '!E43 | E42: ='Fluxo de Caixa '!F43 | F42: ='Fluxo de Caixa '!G43 | G42: ='Fluxo de Caixa '!H43 | H42: ='Fluxo de Caixa '!I43 | I42: ='Fluxo de Caixa '!J43 | ... N42: ='Fluxo de Caixa '!O43 | O42: =SUM(C42:N42) | P42: =IFERROR(I42/H42-1,IF(I42>0,1,0)) | Q42: =IFERROR(O42/$O$10,0) | R42: =I42-H42
B43: ='Fluxo de Caixa '!C44 | C43: ='Fluxo de Caixa '!D44 | D43: ='Fluxo de Caixa '!E44 | E43: ='Fluxo de Caixa '!F44 | F43: ='Fluxo de Caixa '!G44 | G43: ='Fluxo de Caixa '!H44 | H43: ='Fluxo de Caixa '!I44 | I43: ='Fluxo de Caixa '!J44 | ... N43: ='Fluxo de Caixa '!O44 | O43: =SUM(C43:N43) | P43: =IFERROR(I43/H43-1,IF(I43>0,1,0)) | Q43: =IFERROR(O43/$O$10,0) | R43: =I43-H43
B44: FERIAS | C44: ='Fluxo de Caixa '!D32 | D44: ='Fluxo de Caixa '!E32 | E44: ='Fluxo de Caixa '!F32 | F44: ='Fluxo de Caixa '!G32 | G44: ='Fluxo de Caixa '!H32 | H44: ='Fluxo de Caixa '!I32 | I44: ='Fluxo de Caixa '!J32 | J44: ='Fluxo de Caixa '!K32 | ... N44: ='Fluxo de Caixa '!O32 | O44: =SUM(C44:N44) | P44: =IFERROR(I44/H44-1,IF(I44>0,1,0)) | Q44: =IFERROR(O44/$O$10,0) | R44: =I44-H44
B45: ='Fluxo de Caixa '!C39 | C45: ='Fluxo de Caixa '!D39 | D45: ='Fluxo de Caixa '!E39 | E45: ='Fluxo de Caixa '!F39 | F45: ='Fluxo de Caixa '!G39 | G45: ='Fluxo de Caixa '!H39 | H45: ='Fluxo de Caixa '!I39 | I45: ='Fluxo de Caixa '!J39 | ... N45: ='Fluxo de Caixa '!O39 | O45: =SUM(C45:N45) | P45: =IFERROR(I45/H45-1,IF(I45>0,1,0)) | Q45: =IFERROR(O45/$O$10,0) | R45: =I45-H45
...

Sheet Apoio
B1: Ano | C1: (Tudo)
C3: Rótulos de Coluna
C4: Janeiro | E4: Fevereiro | G4: Março | I4: Abril | K4: Maio | M4: Junho | O4: Julho | Q4: Agosto | S4: Setembro | U4: Outubro | W4: Novembro | Y4: Dezembro | AA4: Total Soma de Crédito | AB4: Total Soma de Débito
B5: Rótulos de Linha | C5: Soma de Crédito | D5: Soma de Débito | E5: Soma de Crédito | F5: Soma de Débito | G5: Soma de Crédito | H5: Soma de Débito | I5: Soma de Crédito | J5: Soma de Débito | K5: Soma de Crédito | L5: Soma de Débito | M5: Soma de Crédito | N5: Soma de Débito | O5: Soma de Crédito | P5: Soma de Débito | Q5: Soma de Crédito | R5: Soma de Débito | S5: Soma de Crédito | T5: Soma de Débito | U5: Soma de Crédito | V5: Soma de Débito | W5: Soma de Crédito | X5: Soma de Débito | Y5: Soma de Crédito | Z5: Soma de Débito
A6: =COUNTIF('Fluxo de Caixa '!C:C,B6) | B6: Consórcio | D6: 3006.4 | AB6: 3006.4
A7: =COUNTIF('Fluxo de Caixa '!C:C,B7) | B7: CSLL | F7: 80807.22 | J7: 30730.21 | AB7: 111537.43
A8: =COUNTIF('Fluxo de Caixa '!C:C,B8) | B8: Devolução / Estorno de Pagamento | E8: 164.78 | G8: 6740.48 | I8: 2050 | L8: 2700 | O8: 645.71 | AA8: 9600.97 | AB8: 2700
A9: =COUNTIF('Fluxo de Caixa '!C:C,B9) | B9: Devolução de Pagamento Recebido | F9: 164.78 | H9: 6740.48 | AB9: 6905.26
A10: =COUNTIF('Fluxo de Caixa '!C:C,B10) | B10: IPTU | D10: 3510.85 | F10: 954.17 | H10: 953.93 | J10: 953.93 | L10: 4536.64 | P10: 3704.6 | AB10: 14614.12
A11: =COUNTIF('Fluxo de Caixa '!C:C,B11) | B11: IRPJ | D11: 148466.82 | J11: 38858.12 | AB11: 187324.94
A12: =COUNTIF('Fluxo de Caixa '!C:C,B12) | B12: PIS | D12: 15499.36 | F12: 4219.23 | H12: 6139.58 | J12: 8297.04 | L12: 21787.88 | N12: 10966.3 | P12: 350.43 | AB12: 67259.82
A13: =COUNTIF('Fluxo de Caixa '!C:C,B13) | B13: Pró-Labore | D13: 2520.95 | F13: 3157.96 | H13: 900 | J13: 4113.36 | L13: 1383.33 | N13: 3659.96 | P13: 32731.01 | AB13: 48466.57
A14: =COUNTIF('Fluxo de Caixa '!C:C,B14) | B14: Transferência Emitida | D14: 2579816.4 | F14: 3879579.6 | H14: 1858648.1 | J14: 2017266.3 | L14: 1848736.2 | N14: 1492353.6 | P14: 968426.05 | AB14: 14644826
A15: =COUNTIF('Fluxo de Caixa '!C:C,B15) | B15: Transferência Recebida | C15: 2579816.4 | E15: 3879579.6 | G15: 1858648.1 | I15: 2017266.3 | K15: 3203452.3 | M15: 1492353.6 | O15: 968426.05 | AA15: 15999542
A16: =COUNTIF('Fluxo de Caixa '!C:C,B16) | B16: Saldo Final CEF | D16: -9962.67 | F16: 2896.27 | H16: -6790.36 | J16: 6291.18 | L16: -9341.64 | N16: -8714.28 | P16: 153067.5 | AB16: 127446
A17: =COUNTIF('Fluxo de Caixa '!C:C,B17) | B17: Saldo Inicial CEF | C17: 435332.04 | AA17: 435332.04
A18: =COUNTIF('Fluxo de Caixa '!C:C,B18) | B18: Empréstimo Sócios x Empresa | G18: 35000 | I18: 45000 | K18: 75000 | AA18: 155000
A19: =COUNTIF('Fluxo de Caixa '!C:C,B19) | B19: Pagamento Empréstimo Sócios x Empresa | J19: 80000 | AB19: 80000
A20: =COUNTIF('Fluxo de Caixa '!C:C,B20) | B20: Juros Recebidos | C20: 346.95 | E20: 5.69 | G20: 2.53 | I20: 0.67 | AA20: 355.84
A21: =COUNTIF('Fluxo de Caixa '!C:C,B21) | B21: Saldo Inicial Safra | C21: 102806.82 | AA21: 102806.82
A22: =COUNTIF('Fluxo de Caixa '!C:C,B22) | B22: Saldo Inicial Itau | C22: 562274.75 | AA22: 562274.75
A23: =COUNTIF('Fluxo de Caixa '!C:C,B23) | B23: Saldo Final Safra | D23: 2395.58 | F23: 70052.84 | H23: 2917.84 | J23: 16674.07 | L23: 74054.33 | N23: 256529.57 | P23: 29814.44 | AB23: 452438.67
A24: =COUNTIF('Fluxo de Caixa '!C:C,B24) | B24: Saldo Final Itau | D24: 64565.25 | F24: 153022.37 | H24: -22295.75 | J24: 46816.91 | L24: 20269.86 | N24: 26636.19 | P24: 12909.32 | AB24: 301924.15
A25: =COUNTIF('Fluxo de Caixa '!C:C,B25) | B25: Parcelamento de Impostos Exercicio Anterior | D25: 143237.64 | F25: 71856.49 | H25: 111292.76 | J25: 207684.95 | L25: 165124.25 | N25: 73927.63 | P25: 113849.05 | AB25: 886972.77
A26: =COUNTIF('Fluxo de Caixa '!C:C,B26) | B26: Venda de Imobilizado | M26: 49000 | AA26: 49000
A27: =COUNTIF('Fluxo de Caixa '!C:C,B27) | B27: Outros Recebimentos Não Operacionais | E27: 1295.56 | I27: 251.13 | M27: 2500 | AA27: 4046.69
A28: =COUNTIF('Fluxo de Caixa '!C:C,B28) | B28: Pagamento de Empréstimos Bancários | D28: 35696.55 | F28: 40730.52 | H28: 43077.28 | J28: 42095.09 | L28: 192115.5 | N28: 42150.54 | P28: 99262.79 | AB28: 495128.27
A29: =COUNTIF('Fluxo de Caixa '!C:C,B29) | B29: Construção da Nova Sede | D29: 58161.73 | F29: 81805.24 | H29: 36185.46 | J29: 75533.31 | L29: 181791.31 | N29: 69101.17 | P29: 29206.35 | AB29: 531784.57
A30: =COUNTIF('Fluxo de Caixa '!C:C,B30) | B30: Juros Bancários | D30: 5043.84 | F30: 5246.45 | H30: 3717.89 | J30: 2857.57 | L30: 3530.54 | N30: 2041.45 | P30: 5727.74 | AB30: 28165.48
A31: =COUNTIF('Fluxo de Caixa '!C:C,B31) | B31: Recebimento de Clientes | C31: 1802062.1 | E31: 1687804.9 | G31: 1558821.9 | I31: 2037244.6 | K31: 3108953.3 | M31: 1459018.7 | O31: 1613066.1 | AA31: 13266972
A32: =COUNTIF('Fluxo de Caixa '!C:C,B32) | B32: SALARIO | D32: 498154.44 | F32: 520467.94 | H32: 525625.75 | J32: 526479.56 | L32: 639195.11 | N32: 548773.44 | P32: 558932.38 | AB32: 3817628.6
